Workbook

Sheet Summary
A1: Notes: the number of enemies of each type in each location is irrelevant from the mathematical point of view.
A2: If locations act as "levels", it may be interesting to have weak enemies in the first location and add other species in the following locations.
A5: Feature | B5: RTP | C5: Freq | D5: Probability | E5: Avg pay
A6: Base game | B6: 0.6
A7: Boss round | B7: 0.25 | C7: 200 | D7: =1/C7 -> 0.005 | E7: =+C7*B7 -> 50 | F7: Prize: 50x to be distributed between players according to damage done to boss
A8: Special weapon (*) | B8: 0.1 | C8: 60 | D8: =1/C8 -> 0.016666667 | E8: =+C8*B8 -> 6
A9: Leaderboard | B9: 0
A10: Total | B10: 0.95
A11: (*) To use in MAIN only. Shots using special weapons are not paid. Each special weapon has a limited number of shots and could be used any time in base game.
A12: When a player gets a GUARANTEE KNOCKOUT he/she can use it only in base game and optimal strategy is to kill a Powerful Pharaoh Mummy with no damage. The prize is x15 (see table below)
A13: If player uses the special weapon in other case (imperfect play) then he/she will get a prize lower than x15. The difference is added to leaderboard prize.
A15: There are different kind of enemies. Each enemy has its own prizes. Stronger enemies grant bigger prizes but are more difficult to kill.
A18: Scarab black | D18: Scarab gold | G18: Scarab gem covered
A19: Prize # | B19: Pays | D19: Prize # | E19: Pays | G19: Prize # | H19: Pays
A20: 1 | B20: 2 | D20: 1 | E20: 3 | G20: 1 | H20: 4
A24: Standard Mummy | D24: Medium Mummy A | G24: Medium Mummy B | J24: Medium Mummy C
A25: Prize | B25: Pays | D25: Prize # | E25: Pays | G25: Prize # | H25: Pays | J25: Prize # | K25: Pays
A26: 1 | B26: 2 | D26: 2 | E26: 2 | G26: 1 | H26: 2 | J26: 1 | K26: 3
A27: 2 | B27: 3 | D27: 3 | E27: 3 | G27: 2 | H27: 2 | J27: 2 | K27: 3
A28: Total | B28: =+SUM(B26:B27) -> 5 | D28: Total | E28: =+SUM(E26:E27) -> 5 | G28: 3 | H28: 4 | J28: 3 | K28: 6
G29: Total | H29: =+SUM(H26:H28) -> 8 | J29: Total | K29: =+SUM(K26:K28) -> 12
A33: Powerful Pharaoh Mummy A | D33: Powerful Pharaoh Mummy B
A34: Prize # | B34: Pays | D34: Prize # | E34: Pays
A35: 1 | B35: 2 | D35: 1 | E35: 2
A36: 2 | B36: 5 | D36: 2 | E36: 5
A37: 3 | B37: 8 | D37: 3 | E37: 8
A38: Total | B38: =+SUM(B35:B37) -> 15 | D38: Total | E38: =+SUM(E35:E37) -> 15

Sheet Special weapon
A1: For each shot in base game with a regular weapon draw if player gets a special weapon or not.
A2: Probability of getting a special weapon = 1/60
A3: If player gets a special weapon then draw which one he gets using the weights in the table below.
A6: Special weapons: | B6: Shots | C6: Avg pay by shot | D6: Total avg pay | E6: Weights
A7: Special weapon 1 | B7: 3 | C7: 1.2 | D7: =+B7*C7 -> 3.6 | E7: 330
A8: Special weapon 2 | B8: 5 | C8: 1.05 | D8: =+B8*C8 -> 5.25 | E8: 180
A9: Special weapon 3 | B9: 10 | C9: 0.9 | D9: =+B9*C9 -> 9 | E9: 309
A10: Guarantee knockout (*) | B10: 0 | C10: 15 | D10: =+B10*C10 -> 0 | E10: 0 | F10: (*) if there is not any Powerful Pharaoh Mummy in location we can discard this one to make it simpler.
F11: Otherwise, the best strategy would be to keep this weapon and use it in another location to kill a Powerful Pharaoh Mummy.
C12: Avg win | D12: =+SUMPRODUCT(D7:D9,E7:E9)/SUM(E7:E9) -> 6
A15: Special weapons can be use anytime in base game only.
A17: Special weapons: | B17: Shots | C17: Avg pay by shot | D17: Total avg pay | E17: Weights
A18: Special weapon 1 | B18: 3 | C18: 1.2 | D18: =+B18*C18 -> 3.6 | E18: 10
A19: Special weapon 2 | B19: 5 | C19: 1.05 | D19: =+B19*C19 -> 5.25 | E19: 8
A20: Special weapon 3 | B20: 10 | C20: 0.9 | D20: =+B20*C20 -> 9 | E20: 7
A21: Guarantee knockout (*) | B21: 1 | C21: 15 | D21: =+B21*C21 -> 15 | E21: 1 | F21: Skill: best strategy is to use it with a Powerful Pharaoh Mummy with no damage
A22: (*) avg pay using best strategy
C23: Avg win | D23: =+SUMPRODUCT(D18:D21,E18:E21)/SUM(E18:E21) -> 6
A25: Each special weapon has its own probabilities of damage for each kind of enemy. Prizes must be multiplied by the stake that triggered the feature.
A26: For instance, if player gets a special weapon betting 100 credits, at the moment he decides to use it the prizes must be multiplied by 100. It doesn’t matter if after getting the special weapon he changed the stake.
A29: Special weapons description
A30: Special weapon 1: holy arrows (3 arrows)
A32: Special weapon 2: 1 bomb hitting 5 times.
A33: When the bomb is thrown hit the nearest enemy (i.e. draw the damage according to tables for special weapon 2), if that enemy is not defeated then hit him one more time, else hit the following nearest enemy. Repeat 3 more times (total: 5 "shots").
A34: Algorithmically is a sequential process but graphically it is shown as everything ocurring at the same moment.
A36: Special weapon 3: every time a player gets special weapon 3 choose at random between a Chain gun or Ricochet.
A37: Chain Gun: 10 shots but each shot can be shown as a burst of several bullets. For example, each shot can be replaced by one burst of 10 bullets and this corresponds to only one draw using the probabilities of the tables.
A38: Ricochet: 5 shots but each shot bounces hitting a second enemy. The second enemy is chosen at random and it is not necessary the same kind of enemy that the player aimed.

Sheet Base game (Mummy A)
A1: Medium Mummy A (golden wrist bands)
A2: For each shot with a regular weapon, draw the damage caused using the table according to prizes already granted by enemy that is being shot.
A4: Table 1 | B4: Prize # | C4: Probability | D4: Cumulative prob. | E4: Award | F4: RTP | G4: Prob. Boss round
A5: (Initial state) | B5: 1 | C5: 0.2 | D5: =+SUM($C$5:C5) -> 0.2 | E5: =+Summary!E26 -> 2 | F5: =+C5*E5 -> 0.4
B6: 2 | C6: 0.05 | D6: =+SUM($C$5:C6) -> 0.25 | E6: =+Summary!E27 -> 3 | F6: =+C6*E6 -> 0.15
B7: 1 and 2 | C7: 0.01 | D7: =+SUM($C$5:C7) -> 0.26 | E7: =+E5+E6 -> 5 | F7: =+C7*E7 -> 0.05 | G7: 0.5 | H7: (*) Enemy killed
B8: Total (*) | C8: =+SUM(C5:C7) -> 0.26 | F8: =+SUM(F5:F7) -> 0.6
B9: (*) Total probability is hit rate
A12: Table 6 | B12: Prize # | C12: Probability | D12: Cumulative prob. | E12: Award | F12: RTP | G12: Prob. Boss round
A13: Awards granted: | B13: 1 | C13: 0.3 | D13: =+SUM(C13:$C$13) -> 0.3 | E13: =+E5 -> 2 | F13: =+E13*C13 -> 0.6 | G13: 0.016666667 | H13: (*) Enemy killed
A14: Prize #2 | B14: Total | C14: =+SUM(C13:C13) -> 0.3 | F14: =+SUM(F13:F13) -> 0.6
A17: Table 7 | B17: Prize # | C17: Probability | D17: Cumulative prob. | E17: Award | F17: RTP | G17: Prob. Boss round
A18: Awards granted: | B18: 2 | C18: 0.2 | D18: =+SUM(C$18:$C18) -> 0.2 | E18: =+E6 -> 3 | F18: =+E18*C18 -> 0.6 | G18: 0.025 | H18: (*) Enemy killed
A19: Prize #1 | B19: Total | C19: =+SUM(C18:C18) -> 0.2 | F19: =+SUM(F18:F18) -> 0.6

Sheet Base game (Mummy B)
A1: Medium Mummy B (golden wrist bands and necklace)
A2: For each shot with a regular weapon, draw the damage caused using the table according to prizes already granted by enemy that is being shot.
A4: Table 1 | B4: Prize # | C4: Probability | D4: Cumulative prob. | E4: Award | F4: RTP | G4: Prob. Boss round
A5: (Initial state) | B5: 1 | C5: 0.09 | D5: =+SUM($C$5:C5) -> 0.09 | E5: =+Summary!H26 -> 2 | F5: =+C5*E5 -> 0.18
B6: 2 | C6: 0.09 | D6: =+SUM($C$5:C6) -> 0.18 | E6: =+Summary!H27 -> 2 | F6: =+C6*E6 -> 0.18
B7: 3 | C7: 0.03 | D7: =+SUM($C$5:C7) -> 0.21 | E7: =+Summary!H28 -> 4 | F7: =+C7*E7 -> 0.12
B8: 1 and 2 | C8: 0.008 | D8: =+SUM($C$5:C8) -> 0.218 | E8: =+E5+E6 -> 4 | F8: =+C8*E8 -> 0.032
B9: 1 and 3 | C9: 0.004 | D9: =+SUM($C$5:C9) -> 0.222 | E9: =+E5+E7 -> 6 | F9: =+C9*E9 -> 0.024
B10: 2 and 3 | C10: 0.004 | D10: =+SUM($C$5:C10) -> 0.226 | E10: =+E6+E7 -> 6 | F10: =+C10*E10 -> 0.024
B11: 1, 2 and 3 (*) | C11: 0.005 | D11: =+SUM($C$5:C11) -> 0.231 | E11: =+E5+E6+E7 -> 8 | F11: =+C11*E11 -> 0.04 | G11: 1 | H11: (*) Enemy killed
B12: Total (*) | C12: =+SUM(C5:C11) -> 0.231 | F12: =+SUM(F5:F11) -> 0.6
B13: (*) Total probability is hit rate
A15: Table 2 | B15: Prize # | C15: Probability | D15: Cumulative prob. | E15: Award | F15: RTP | G15: Prob. Boss round
A16: Awards granted: | B16: 2 | C16: 0.25 | D16: =+SUM(C16:$C$16) -> 0.25 | E16: =+E6 -> 2 | F16: =+C16*E16 -> 0.5
A17: Prize #1 | B17: 3 | C17: 0.013 | D17: =+SUM(C$16:$C17) -> 0.263 | E17: =+E7 -> 4 | F17: =+C17*E17 -> 0.052
B18: 2 and 3 | C18: 0.008 | D18: =+SUM(C$16:$C18) -> 0.271 | E18: =+E16+E17 -> 6 | F18: =+C18*E18 -> 0.048 | G18: 0.625 | H18: (*) Enemy killed
B19: Total | C19: =+SUM(C16:C18) -> 0.271 | F19: =+SUM(F16:F18) -> 0.6
A22: Table 3 | B22: Prize # | C22: Probability | D22: Cumulative prob. | E22: Award | F22: RTP | G22: Prob. Boss round
A23: Awards granted: | B23: 1 | C23: 0.25 | D23: =+SUM(C23:$C$23) -> 0.25 | E23: =+E5 -> 2 | F23: =+C23*E23 -> 0.5
A24: Prize #2 | B24: 3 | C24: 0.013 | D24: =+SUM(C$23:$C24) -> 0.263 | E24: =+E7 -> 4 | F24: =+C24*E24 -> 0.052
B25: 1 and 3 | C25: 0.008 | D25: =+SUM(C$23:$C25) -> 0.271 | E25: =+E23+E24 -> 6 | F25: =+C25*E25 -> 0.048 | G25: 0.625 | H25: (*) Enemy killed
B26: Total | C26: =+SUM(C23:C25) -> 0.271 | F26: =+SUM(F23:F25) -> 0.6
A29: Table 4 | B29: Prize # | C29: Probability | D29: Cumulative prob. | E29: Award | F29: RTP | G29: Prob. Boss round
A30: Awards granted: | B30: 3 | C30: 0.15 | D30: =+SUM(C30:$C$30) -> 0.15 | E30: =+E7 -> 4 | F30: =+C30*E30 -> 0.6 | G30: 0.033333333 | H30: (*) Enemy killed
A31: Prize #1 | B31: Total | C31: =+SUM(C30:C30) -> 0.15 | F31: =+SUM(F30:F30) -> 0.6
A32: Prize #2
A34: Table 5 | B34: Prize # | C34: Probability | D34: Cumulative prob. | E34: Award | F34: RTP | G34: Prob. Boss round
A35: Awards granted: | B35: 1 | C35: 0.14 | D35: =+SUM(C35:$C$35) -> 0.14 | E35: =+E5 -> 2 | F35: =+C35*E35 -> 0.28
A36: Prize #3 | B36: 2 | C36: 0.14 | D36: =+SUM(C$35:$C36) -> 0.28 | E36: =+E6 -> 2 | F36: =+C36*E36 -> 0.28
B37: 1 and 2 | C37: 0.01 | D37: =+SUM(C$35:$C37) -> 0.29 | E37: =+E35+E36 -> 4 | F37: =+C37*E37 -> 0.04 | G37: 0.5 | H37: (*) Enemy killed
B38: Total | C38: =+SUM(C35:C37) -> 0.29 | F38: =+SUM(F35:F37) -> 0.6
A41: Table 6 | B41: Prize # | C41: Probability | D41: Cumulative prob. | E41: Award | F41: RTP | G41: Prob. Boss round
A42: Awards granted: | B42: 1 | C42: 0.3 | D42: =+SUM(C42:$C$42) -> 0.3 | E42: =+E5 -> 2 | F42: =+E42*C42 -> 0.6 | G42: 0.016666667 | H42: (*) Enemy killed
A43: Prize #2 | B43: Total | C43: =+SUM(C42:C42) -> 0.3 | F43: =+SUM(F42:F42) -> 0.6
A44: Prize #3
A46: Table 7 | B46: Prize # | C46: Probability | D46: Cumulative prob. | E46: Award | F46: RTP | G46: Prob. Boss round
A47: Awards granted: | B47: 2 | C47: 0.3 | D47: =+SUM(C$47:$C47) -> 0.3 | E47: =+E6 -> 2 | F47: =+E47*C47 -> 0.6 | G47: 0.016666667 | H47: (*) Enemy killed
A48: Prize #1 | B48: Total | C48: =+SUM(C47:C47) -> 0.3 | F48: =+SUM(F47:F47) -> 0.6
A49: Prize #3

Sheet Base game (Mummy C)
A1: Medium Mummy C (golden boots and wrist bands)
A2: For each shot with a regular weapon, draw the damage caused using the table according to prizes already granted by enemy that is being shot.
A4: Table 1 | B4: Prize # | C4: Probability | D4: Cumulative prob. | E4: Award | F4: RTP | G4: Prob. Boss round
A5: (Initial state) | B5: 1 | C5: 0.07 | D5: =+SUM($C$5:C5) -> 0.07 | E5: =+Summary!K26 -> 3 | F5: =+C5*E5 -> 0.21
B6: 2 | C6: 0.07 | D6: =+SUM($C$5:C6) -> 0.14 | E6: =+Summary!K27 -> 3 | F6: =+C6*E6 -> 0.21
B7: 3 | C7: 0.01 | D7: =+SUM($C$5:C7) -> 0.15 | E7: =+Summary!K28 -> 6 | F7: =+C7*E7 -> 0.06
B8: 1 and 2 | C8: 0.0055 | D8: =+SUM($C$5:C8) -> 0.1555 | E8: =+E5+E6 -> 6 | F8: =+C8*E8 -> 0.033
B9: 1 and 3 | C9: 0.0015 | D9: =+SUM($C$5:C9) -> 0.157 | E9: =+E5+E7 -> 9 | F9: =+C9*E9 -> 0.0135
B10: 2 and 3 | C10: 0.0015 | D10: =+SUM($C$5:C10) -> 0.1585 | E10: =+E6+E7 -> 9 | F10: =+C10*E10 -> 0.0135
B11: 1, 2 and 3 (*) | C11: 0.005 | D11: =+SUM($C$5:C11) -> 0.1635 | E11: =+E5+E6+E7 -> 12 | F11: =+C11*E11 -> 0.06 | G11: 1 | H11: (*) Enemy killed
B12: Total (*) | C12: =+SUM(C5:C11) -> 0.1635 | F12: =+SUM(F5:F11) -> 0.6
B13: (*) Total probability is hit rate
A15: Table 2 | B15: Prize # | C15: Probability | D15: Cumulative prob. | E15: Award | F15: RTP | G15: Prob. Boss round
A16: Awards granted: | B16: 2 | C16: 0.11 | D16: =+SUM(C16:$C$16) -> 0.11 | E16: =+E6 -> 3 | F16: =+C16*E16 -> 0.33
A17: Prize #1 | B17: 3 | C17: 0.03 | D17: =+SUM(C$16:$C17) -> 0.14 | E17: =+E7 -> 6 | F17: =+C17*E17 -> 0.18
B18: 2 and 3 | C18: 0.01 | D18: =+SUM(C$16:$C18) -> 0.15 | E18: =+E16+E17 -> 9 | F18: =+C18*E18 -> 0.09 | G18: 0.5 | H18: (*) Enemy killed
B19: Total | C19: =+SUM(C16:C18) -> 0.15 | F19: =+SUM(F16:F18) -> 0.6
A22: Table 3 | B22: Prize # | C22: Probability | D22: Cumulative prob. | E22: Award | F22: RTP | G22: Prob. Boss round
A23: Awards granted: | B23: 1 | C23: 0.11 | D23: =+SUM(C23:$C$23) -> 0.11 | E23: =+E5 -> 3 | F23: =+C23*E23 -> 0.33
A24: Prize #2 | B24: 3 | C24: 0.03 | D24: =+SUM(C$23:$C24) -> 0.14 | E24: =+E7 -> 6 | F24: =+C24*E24 -> 0.18
B25: 1 and 3 | C25: 0.01 | D25: =+SUM(C$23:$C25) -> 0.15 | E25: =+E23+E24 -> 9 | F25: =+C25*E25 -> 0.09 | G25: 0.5 | H25: (*) Enemy killed
B26: Total | C26: =+SUM(C23:C25) -> 0.15 | F26: =+SUM(F23:F25) -> 0.6
A29: Table 4 | B29: Prize # | C29: Probability | D29: Cumulative prob. | E29: Award | F29: RTP | G29: Prob. Boss round
A30: Awards granted: | B30: 3 | C30: 0.1 | D30: =+SUM(C30:$C$30) -> 0.1 | E30: =+E7 -> 6 | F30: =+C30*E30 -> 0.6 | G30: 0.05 | H30: (*) Enemy killed
A31: Prize #1 | B31: Total | C31: =+SUM(C30:C30) -> 0.1 | F31: =+SUM(F30:F30) -> 0.6
A32: Prize #2
A34: Table 5 | B34: Prize # | C34: Probability | D34: Cumulative prob. | E34: Award | F34: RTP | G34: Prob. Boss round
A35: Awards granted: | B35: 1 | C35: 0.09 | D35: =+SUM(C35:$C$35) -> 0.09 | E35: =+E5 -> 3 | F35: =+C35*E35 -> 0.27
A36: Prize #3 | B36: 2 | C36: 0.083333333 | D36: =+SUM(C$35:$C36) -> 0.17333333 | E36: =+E6 -> 3 | F36: =+C36*E36 -> 0.25
B37: 1 and 2 | C37: 0.013333333 | D37: =+SUM(C$35:$C37) -> 0.18666667 | E37: =+E35+E36 -> 6 | F37: =+C37*E37 -> 0.08 | G37: 0.375 | H37: (*) Enemy killed
B38: Total | C38: =+SUM(C35:C37) -> 0.18666667 | F38: =+SUM(F35:F37) -> 0.6
A41: Table 6 | B41: Prize # | C41: Probability | D41: Cumulative prob. | E41: Award | F41: RTP | G41: Prob. Boss round
A42: Awards granted: | B42: 1 | C42: 0.2 | D42: =+SUM(C42:$C$42) -> 0.2 | E42: =+E5 -> 3 | F42: =+E42*C42 -> 0.6 | G42: 0.025 | H42: (*) Enemy killed
A43: Prize #2 | B43: Total | C43: =+SUM(C42:C42) -> 0.2 | F43: =+SUM(F42:F42) -> 0.6
A44: Prize #3
A46: Table 7 | B46: Prize # | C46: Probability | D46: Cumulative prob. | E46: Award | F46: RTP | G46: Prob. Boss round
A47: Awards granted: | B47: 2 | C47: 0.2 | D47: =+SUM(C$47:$C47) -> 0.2 | E47: =+E6 -> 3 | F47: =+E47*C47 -> 0.6 | G47: 0.025 | H47: (*) Enemy killed
A48: Prize #1 | B48: Total | C48: =+SUM(C47:C47) -> 0.2 | F48: =+SUM(F47:F47) -> 0.6
A49: Prize #3

Sheet Base game (Standard Mummy)
A1: Standard Mummy
A2: For each shot with a regular weapon, draw the damage caused using the table according to prizes already granted by enemy that is being shot.
A4: Table 1 | B4: Prize # | C4: Probability | D4: Cumulative prob. | E4: Award | F4: RTP | G4: Prob. Boss round
A5: (Initial state) | B5: 1 | C5: 0.125 | D5: =+SUM($C$5:C5) -> 0.125 | E5: =+Summary!B26 -> 2 | F5: =+C5*E5 -> 0.25
B6: 2 | C6: 0.1 | D6: =+SUM($C$5:C6) -> 0.225 | E6: =+Summary!B27 -> 3 | F6: =+C6*E6 -> 0.3
B7: 1 and 2 | C7: 0.01 | D7: =+SUM($C$5:C7) -> 0.235 | E7: =+E5+E6 -> 5 | F7: =+C7*E7 -> 0.05 | G7: 0.5 | H7: (*) Enemy killed
B8: Total (*) | C8: =+SUM(C5:C7) -> 0.235 | F8: =+SUM(F5:F7) -> 0.6
B9: (*) Total probability is hit rate
A12: Table 6 | B12: Prize # | C12: Probability | D12: Cumulative prob. | E12: Award | F12: RTP | G12: Prob. Boss round
A13: Awards granted: | B13: 1 | C13: 0.3 | D13: =+SUM(C13:$C$13) -> 0.3 | E13: =+E5 -> 2 | F13: =+E13*C13 -> 0.6 | G13: 0.016666667 | H13: (*) Enemy killed
A14: Prize #2 | B14: Total | C14: =+SUM(C13:C13) -> 0.3 | F14: =+SUM(F13:F13) -> 0.6
A17: Table 7 | B17: Prize # | C17: Probability | D17: Cumulative prob. | E17: Award | F17: RTP | G17: Prob. Boss round
A18: Awards granted: | B18: 2 | C18: 0.2 | D18: =+SUM(C$18:$C18) -> 0.2 | E18: =+E6 -> 3 | F18: =+E18*C18 -> 0.6 | G18: 0.025 | H18: (*) Enemy killed
A19: Prize #1 | B19: Total | C19: =+SUM(C18:C18) -> 0.2 | F19: =+SUM(F18:F18) -> 0.6

Sheet Base game (Scarabs)
A1: Scarabs
A4: Scarab black | B4: Prize # | C4: Probability | D4: Cumulative prob. | E4: Award | F4: RTP | G4: Prob. Boss round
B5: 1 | C5: 0.3 | D5: =+SUM(C5:$C$5) -> 0.3 | E5: =+Summary!B20 -> 2 | F5: =+E5*C5 -> 0.6 | G5: 0.016666667 | H5: (*) Enemy killed
B6: Total | C6: =+SUM(C5:C5) -> 0.3 | F6: =+SUM(F5:F5) -> 0.6
A9: Scarab gold | B9: Prize # | C9: Probability | D9: Cumulative prob. | E9: Award | F9: RTP | G9: Prob. Boss round
B10: 1 | C10: 0.2 | D10: =1/6 -> 0.16666667 | E10: =+Summary!E20 -> 3 | F10: =+E10*C10 -> 0.6 | G10: 0.025 | H10: (*) Enemy killed
B11: Total | C11: =+SUM(C10:C10) -> 0.2 | F11: =+SUM(F10:F10) -> 0.6
A14: Scarab gem covered | B14: Prize # | C14: Probability | D14: Cumulative prob. | E14: Award | F14: RTP | G14: Prob. Boss round
B15: 1 | C15: 0.15 | D15: =+SUM(C$15:$C15) -> 0.15 | E15: =+Summary!H20 -> 4 | F15: =+E15*C15 -> 0.6 | G15: 0.033333333 | H15: (*) Enemy killed
B16: Total | C16: =+SUM(C15:C15) -> 0.15 | F16: =+SUM(F15:F15) -> 0.6

Sheet Base game (Pharaoh A & B)
A1: Powerful Pharaoh Mummy A & B
A2: For each shot with a regular weapon, draw the damage caused using the table according to prizes already granted by enemy that is being shot.
A4: Table 1 | B4: Prize # | C4: Probability | D4: Cumulative prob. | E4: Award | F4: RTP | G4: Prob. Boss round
A5: (Initial state) | B5: 1 | C5: 0.08 | D5: =+SUM($C$5:C5) -> 0.08 | E5: =+Summary!B35 -> 2 | F5: =+C5*E5 -> 0.16
B6: 2 | C6: 0.025 | D6: =+SUM($C$5:C6) -> 0.105 | E6: =+Summary!B36 -> 5 | F6: =+C6*E6 -> 0.125
B7: 3 | C7: 0.01 | D7: =+SUM($C$5:C7) -> 0.115 | E7: =+Summary!B37 -> 8 | F7: =+C7*E7 -> 0.08
B8: 1 and 2 | C8: 0.005 | D8: =+SUM($C$5:C8) -> 0.12 | E8: =+E5+E6 -> 7 | F8: =+C8*E8 -> 0.035
B9: 1 and 3 | C9: 0.006 | D9: =+SUM($C$5:C9) -> 0.126 | E9: =+E5+E7 -> 10 | F9: =+C9*E9 -> 0.06
B10: 2 and 3 | C10: 0.005 | D10: =+SUM($C$5:C10) -> 0.131 | E10: =+E6+E7 -> 13 | F10: =+C10*E10 -> 0.065
B11: 1, 2 and 3 (*) | C11: 0.005 | D11: =+SUM($C$5:C11) -> 0.136 | E11: =+E5+E6+E7 -> 15 | F11: =+C11*E11 -> 0.075 | G11: 1 | H11: (*) Enemy killed
B12: Total (*) | C12: =+SUM(C5:C11) -> 0.136 | F12: =+SUM(F5:F11) -> 0.6
B13: (*) Total probability is hit rate
A15: Table 2 | B15: Prize # | C15: Probability | D15: Cumulative prob. | E15: Award | F15: RTP | G15: Prob. Boss round
A16: Awards granted: | B16: 2 | C16: 0.08 | D16: =+SUM(C16:$C$16) -> 0.08 | E16: =+E6 -> 5 | F16: =+C16*E16 -> 0.4
A17: Prize #1 | B17: 3 | C17: 0.016875 | D17: =+SUM(C$16:$C17) -> 0.096875 | E17: =+E7 -> 8 | F17: =+C17*E17 -> 0.135
B18: 2 and 3 | C18: 0.005 | D18: =+SUM(C$16:$C18) -> 0.101875 | E18: =+E16+E17 -> 13 | F18: =+C18*E18 -> 0.065 | G18: 1 | H18: (*) Enemy killed
B19: Total | C19: =+SUM(C16:C18) -> 0.101875 | F19: =+SUM(F16:F18) -> 0.6
A22: Table 3 | B22: Prize # | C22: Probability | D22: Cumulative prob. | E22: Award | F22: RTP | G22: Prob. Boss round
A23: Awards granted: | B23: 1 | C23: 0.12 | D23: =+SUM(C23:$C$23) -> 0.12 | E23: =+E5 -> 2 | F23: =+C23*E23 -> 0.24
A24: Prize #2 | B24: 3 | C24: 0.0325 | D24: =+SUM(C$23:$C24) -> 0.1525 | E24: =+E7 -> 8 | F24: =+C24*E24 -> 0.26
B25: 1 and 3 | C25: 0.01 | D25: =+SUM(C$23:$C25) -> 0.1625 | E25: =+E23+E24 -> 10 | F25: =+C25*E25 -> 0.1 | G25: 0.5 | H25: (*) Enemy killed
B26: Total | C26: =+SUM(C23:C25) -> 0.1625 | F26: =+SUM(F23:F25) -> 0.6
A29: Table 4 | B29: Prize # | C29: Probability | D29: Cumulative prob. | E29: Award | F29: RTP | G29: Prob. Boss round
A30: Awards granted: | B30: 3 | C30: 0.075 | D30: =+SUM(C30:$C$30) -> 0.075 | E30: =+E7 -> 8 | F30: =+C30*E30 -> 0.6 | G30: 0.066666667 | H30: (*) Enemy killed
A31: Prize #1 | B31: Total | C31: =+SUM(C30:C30) -> 0.075 | F31: =+SUM(F30:F30) -> 0.6
A32: Prize #2
A34: Table 5 | B34: Prize # | C34: Probability | D34: Cumulative prob. | E34: Award | F34: RTP | G34: Prob. Boss round
A35: Awards granted: | B35: 1 | C35: 0.14 | D35: =+SUM(C35:$C$35) -> 0.14 | E35: =+E5 -> 2 | F35: =+C35*E35 -> 0.28
A36: Prize #3 | B36: 2 | C36: 0.05 | D36: =+SUM(C$35:$C36) -> 0.19 | E36: =+E6 -> 5 | F36: =+C36*E36 -> 0.25
B37: 1 and 2 | C37: 0.01 | D37: =+SUM(C$35:$C37) -> 0.2 | E37: =+E35+E36 -> 7 | F37: =+C37*E37 -> 0.07 | G37: 0.5 | H37: (*) Enemy killed
B38: Total | C38: =+SUM(C35:C37) -> 0.2 | F38: =+SUM(F35:F37) -> 0.6
A41: Table 6 | B41: Prize # | C41: Probability | D41: Cumulative prob. | E41: Award | F41: RTP | G41: Prob. Boss round
A42: Awards granted: | B42: 1 | C42: 0.3 | D42: =+SUM(C42:$C$42) -> 0.3 | E42: =+E5 -> 2 | F42: =+E42*C42 -> 0.6 | G42: 0.016666667 | H42: (*) Enemy killed
A43: Prize #2 | B43: Total | C43: =+SUM(C42:C42) -> 0.3 | F43: =+SUM(F42:F42) -> 0.6
A44: Prize #3
A46: Table 7 | B46: Prize # | C46: Probability | D46: Cumulative prob. | E46: Award | F46: RTP | G46: Prob. Boss round
A47: Awards granted: | B47: 2 | C47: 0.12 | D47: =+SUM(C$47:$C47) -> 0.12 | E47: =+E6 -> 5 | F47: =+E47*C47 -> 0.6 | G47: 0.041666667 | H47: (*) Enemy killed
A48: Prize #1 | B48: Total | C48: =+SUM(C47:C47) -> 0.12 | F48: =+SUM(F47:F47) -> 0.6
A49: Prize #3

Sheet Special weapon 1 (Mummy A)
A1: SPECIAL WEAPON 1 - Medium Mummy A (golden wrist bands)
A2: For each shot with a special weapon, draw the damage caused using the table according to prizes already granted by enemy that is being shot.
A4: Table 1 | B4: Prize # | C4: Probability | D4: Cumulative prob. | E4: Award | F4: RTP | G4: Prob. Boss round
A5: (Initial state) | B5: 1 | C5: 0.375 | D5: =+SUM($C$5:C5) -> 0.375 | E5: =+Summary!E26 -> 2 | F5: =+C5*E5 -> 0.75
B6: 2 | C6: 0.075 | D6: =+SUM($C$5:C6) -> 0.45 | E6: =+Summary!E27 -> 3 | F6: =+C6*E6 -> 0.225
B7: 1 and 2 | C7: 0.045 | D7: =+SUM($C$5:C7) -> 0.495 | E7: =+E5+E6 -> 5 | F7: =+C7*E7 -> 0.225 | G7: 0 | H7: (*) Enemy killed
B8: Total (*) | C8: =+SUM(C5:C7) -> 0.495 | F8: =+SUM(F5:F7) -> 1.2
B9: (*) Total probability is hit rate
A12: Table 6 | B12: Prize # | C12: Probability | D12: Cumulative prob. | E12: Award | F12: RTP | G12: Prob. Boss round
A13: Awards granted: | B13: 1 | C13: 0.6 | D13: =+SUM(C13:$C$13) -> 0.6 | E13: =+E5 -> 2 | F13: =+E13*C13 -> 1.2 | G13: 0 | H13: (*) Enemy killed
A14: Prize #2 | B14: Total | C14: =+SUM(C13:C13) -> 0.6 | F14: =+SUM(F13:F13) -> 1.2
A17: Table 7 | B17: Prize # | C17: Probability | D17: Cumulative prob. | E17: Award | F17: RTP | G17: Prob. Boss round
A18: Awards granted: | B18: 2 | C18: 0.4 | D18: =+SUM(C$18:$C18) -> 0.4 | E18: =+E6 -> 3 | F18: =+E18*C18 -> 1.2 | G18: 0 | H18: (*) Enemy killed
A19: Prize #1 | B19: Total | C19: =+SUM(C18:C18) -> 0.4 | F19: =+SUM(F18:F18) -> 1.2

Sheet Special weapon 1 (Mummy B)
A1: SPECIAL WEAPON 1 - Medium Mummy B (golden wrist bands and necklace)
A2: For each shot with a special weapon, draw the damage caused using the table according to prizes already granted by enemy that is being shot.
A4: Table 1 | B4: Prize # | C4: Probability | D4: Cumulative prob. | E4: Award | F4: RTP | G4: Prob. Boss round
A5: (Initial state) | B5: 1 | C5: 0.2 | D5: =+SUM($C$5:C5) -> 0.2 | E5: =+Summary!H26 -> 2 | F5: =+C5*E5 -> 0.4
B6: 2 | C6: 0.2 | D6: =+SUM($C$5:C6) -> 0.4 | E6: =+Summary!H27 -> 2 | F6: =+C6*E6 -> 0.4
B7: 3 | C7: 0.01 | D7: =+SUM($C$5:C7) -> 0.41 | E7: =+Summary!H28 -> 4 | F7: =+C7*E7 -> 0.04
B8: 1 and 2 | C8: 0.05 | D8: =+SUM($C$5:C8) -> 0.46 | E8: =+E5+E6 -> 4 | F8: =+C8*E8 -> 0.2
B9: 1 and 3 | C9: 0.01 | D9: =+SUM($C$5:C9) -> 0.47 | E9: =+E5+E7 -> 6 | F9: =+C9*E9 -> 0.06
B10: 2 and 3 | C10: 0.01 | D10: =+SUM($C$5:C10) -> 0.48 | E10: =+E6+E7 -> 6 | F10: =+C10*E10 -> 0.06
B11: 1, 2 and 3 (*) | C11: 0.005 | D11: =+SUM($C$5:C11) -> 0.485 | E11: =+E5+E6+E7 -> 8 | F11: =+C11*E11 -> 0.04 | G11: 0 | H11: (*) Enemy killed
B12: Total (*) | C12: =+SUM(C5:C11) -> 0.485 | F12: =+SUM(F5:F11) -> 1.2
B13: (*) Total probability is hit rate
A15: Table 2 | B15: Prize # | C15: Probability | D15: Cumulative prob. | E15: Award | F15: RTP | G15: Prob. Boss round
A16: Awards granted: | B16: 2 | C16: 0.5 | D16: =+SUM(C16:$C$16) -> 0.5 | E16: =+E6 -> 2 | F16: =+C16*E16 -> 1
A17: Prize #1 | B17: 3 | C17: 0.02 | D17: =+SUM(C$16:$C17) -> 0.52 | E17: =+E7 -> 4 | F17: =+C17*E17 -> 0.08
B18: 2 and 3 | C18: 0.02 | D18: =+SUM(C$16:$C18) -> 0.54 | E18: =+E16+E17 -> 6 | F18: =+C18*E18 -> 0.12 | G18: 0 | H18: (*) Enemy killed
B19: Total | C19: =+SUM(C16:C18) -> 0.54 | F19: =+SUM(F16:F18) -> 1.2
A22: Table 3 | B22: Prize # | C22: Probability | D22: Cumulative prob. | E22: Award | F22: RTP | G22: Prob. Boss round
A23: Awards granted: | B23: 1 | C23: 0.5 | D23: =+SUM(C23:$C$23) -> 0.5 | E23: =+E5 -> 2 | F23: =+C23*E23 -> 1
A24: Prize #2 | B24: 3 | C24: 0.02 | D24: =+SUM(C$23:$C24) -> 0.52 | E24: =+E7 -> 4 | F24: =+C24*E24 -> 0.08
B25: 1 and 3 | C25: 0.02 | D25: =+SUM(C$23:$C25) -> 0.54 | E25: =+E23+E24 -> 6 | F25: =+C25*E25 -> 0.12 | G25: 0 | H25: (*) Enemy killed
B26: Total | C26: =+SUM(C23:C25) -> 0.54 | F26: =+SUM(F23:F25) -> 1.2
A29: Table 4 | B29: Prize # | C29: Probability | D29: Cumulative prob. | E29: Award | F29: RTP | G29: Prob. Boss round
A30: Awards granted: | B30: 3 | C30: 0.3 | D30: =+SUM(C30:$C$30) -> 0.3 | E30: =+E7 -> 4 | F30: =+C30*E30 -> 1.2 | G30: 0 | H30: (*) Enemy killed
A31: Prize #1 | B31: Total | C31: =+SUM(C30:C30) -> 0.3 | F31: =+SUM(F30:F30) -> 1.2
A32: Prize #2
A34: Table 5 | B34: Prize # | C34: Probability | D34: Cumulative prob. | E34: Award | F34: RTP | G34: Prob. Boss round
A35: Awards granted: | B35: 1 | C35: 0.28 | D35: =+SUM(C35:$C$35) -> 0.28 | E35: =+E5 -> 2 | F35: =+C35*E35 -> 0.56
A36: Prize #3 | B36: 2 | C36: 0.28 | D36: =+SUM(C$35:$C36) -> 0.56 | E36: =+E6 -> 2 | F36: =+C36*E36 -> 0.56
B37: 1 and 2 | C37: 0.02 | D37: =+SUM(C$35:$C37) -> 0.58 | E37: =+E35+E36 -> 4 | F37: =+C37*E37 -> 0.08 | G37: 0 | H37: (*) Enemy killed
B38: Total | C38: =+SUM(C35:C37) -> 0.58 | F38: =+SUM(F35:F37) -> 1.2
A41: Table 6 | B41: Prize # | C41: Probability | D41: Cumulative prob. | E41: Award | F41: RTP
A42: Awards granted: | B42: 1 | C42: 0.6 | D42: =+SUM(C42:$C$42) -> 0.6 | E42: =+E5 -> 2 | F42: =+E42*C42 -> 1.2 | G42: 0 | H42: (*) Enemy killed
A43: Prize #2 | B43: Total | C43: =+SUM(C42:C42) -> 0.6 | F43: =+SUM(F42:F42) -> 1.2
A44: Prize #3
A46: Table 7 | B46: Prize # | C46: Probability | D46: Cumulative prob. | E46: Award | F46: RTP
A47: Awards granted: | B47: 2 | C47: 0.6 | D47: =+SUM(C$47:$C47) -> 0.6 | E47: =+E6 -> 2 | F47: =+E47*C47 -> 1.2 | G47: 0 | H47: (*) Enemy killed
A48: Prize #1 | B48: Total | C48: =+SUM(C47:C47) -> 0.6 | F48: =+SUM(F47:F47) -> 1.2
A49: Prize #3

Sheet Special weapon 1 (Mummy C)
A1: SPECIAL WEAPON 1 - Medium Mummy C (golden boots and wrist bands)
A2: For each shot with a special weapon, draw the damage caused using the table according to prizes already granted by enemy that is being shot.
A4: Table 1 | B4: Prize # | C4: Probability | D4: Cumulative prob. | E4: Award | F4: RTP | G4: Prob. Boss round
A5: (Initial state) | B5: 1 | C5: 0.12 | D5: =+SUM($C$5:C5) -> 0.12 | E5: =Summary!K26 -> 3 | F5: =+C5*E5 -> 0.36
B6: 2 | C6: 0.12 | D6: =+SUM($C$5:C6) -> 0.24 | E6: =Summary!K27 -> 3 | F6: =+C6*E6 -> 0.36
B7: 3 | C7: 0.02 | D7: =+SUM($C$5:C7) -> 0.26 | E7: =Summary!K28 -> 6 | F7: =+C7*E7 -> 0.12
B8: 1 and 2 | C8: 0.02 | D8: =+SUM($C$5:C8) -> 0.28 | E8: =+E5+E6 -> 6 | F8: =+C8*E8 -> 0.12
B9: 1 and 3 | C9: 0.01 | D9: =+SUM($C$5:C9) -> 0.29 | E9: =+E5+E7 -> 9 | F9: =+C9*E9 -> 0.09
B10: 2 and 3 | C10: 0.01 | D10: =+SUM($C$5:C10) -> 0.3 | E10: =+E6+E7 -> 9 | F10: =+C10*E10 -> 0.09
B11: 1, 2 and 3 (*) | C11: 0.005 | D11: =+SUM($C$5:C11) -> 0.305 | E11: =+E5+E6+E7 -> 12 | F11: =+C11*E11 -> 0.06 | G11: 0 | H11: (*) Enemy killed
B12: Total (*) | C12: =+SUM(C5:C11) -> 0.305 | F12: =+SUM(F5:F11) -> 1.2
B13: (*) Total probability is hit rate
A15: Table 2 | B15: Prize # | C15: Probability | D15: Cumulative prob. | E15: Award | F15: RTP | G15: Prob. Boss round
A16: Awards granted: | B16: 2 | C16: 0.3 | D16: =+SUM(C16:$C$16) -> 0.3 | E16: =+E6 -> 3 | F16: =+C16*E16 -> 0.9
A17: Prize #1 | B17: 3 | C17: 0.02 | D17: =+SUM(C$16:$C17) -> 0.32 | E17: =+E7 -> 6 | F17: =+C17*E17 -> 0.12
B18: 2 and 3 | C18: 0.02 | D18: =+SUM(C$16:$C18) -> 0.34 | E18: =+E16+E17 -> 9 | F18: =+C18*E18 -> 0.18 | G18: 0 | H18: (*) Enemy killed
B19: Total | C19: =+SUM(C16:C18) -> 0.34 | F19: =+SUM(F16:F18) -> 1.2
A22: Table 3 | B22: Prize # | C22: Probability | D22: Cumulative prob. | E22: Award | F22: RTP | G22: Prob. Boss round
A23: Awards granted: | B23: 1 | C23: 0.3 | D23: =+SUM(C23:$C$23) -> 0.3 | E23: =+E5 -> 3 | F23: =+C23*E23 -> 0.9
A24: Prize #2 | B24: 3 | C24: 0.02 | D24: =+SUM(C$23:$C24) -> 0.32 | E24: =+E7 -> 6 | F24: =+C24*E24 -> 0.12
B25: 1 and 3 | C25: 0.02 | D25: =+SUM(C$23:$C25) -> 0.34 | E25: =+E23+E24 -> 9 | F25: =+C25*E25 -> 0.18 | G25: 0 | H25: (*) Enemy killed
B26: Total | C26: =+SUM(C23:C25) -> 0.34 | F26: =+SUM(F23:F25) -> 1.2
A29: Table 4 | B29: Prize # | C29: Probability | D29: Cumulative prob. | E29: Award | F29: RTP | G29: Prob. Boss round
A30: Awards granted: | B30: 3 | C30: 0.2 | D30: =+SUM(C30:$C$30) -> 0.2 | E30: =+E7 -> 6 | F30: =+C30*E30 -> 1.2 | G30: 0 | H30: (*) Enemy killed
A31: Prize #1 | B31: Total | C31: =+SUM(C30:C30) -> 0.2 | F31: =+SUM(F30:F30) -> 1.2
A32: Prize #2
A34: Table 5 | B34: Prize # | C34: Probability | D34: Cumulative prob. | E34: Award | F34: RTP | G34: Prob. Boss round
A35: Awards granted: | B35: 1 | C35: 0.16 | D35: =+SUM(C35:$C$35) -> 0.16 | E35: =+E5 -> 3 | F35: =+C35*E35 -> 0.48
A36: Prize #3 | B36: 2 | C36: 0.16 | D36: =+SUM(C$35:$C36) -> 0.32 | E36: =+E6 -> 3 | F36: =+C36*E36 -> 0.48
B37: 1 and 2 | C37: 0.04 | D37: =+SUM(C$35:$C37) -> 0.36 | E37: =+E35+E36 -> 6 | F37: =+C37*E37 -> 0.24 | G37: 0 | H37: (*) Enemy killed
B38: Total | C38: =+SUM(C35:C37) -> 0.36 | F38: =+SUM(F35:F37) -> 1.2
A41: Table 6 | B41: Prize # | C41: Probability | D41: Cumulative prob. | E41: Award | F41: RTP
A42: Awards granted: | B42: 1 | C42: 0.4 | D42: =+SUM(C42:$C$42) -> 0.4 | E42: =+E5 -> 3 | F42: =+E42*C42 -> 1.2 | G42: 0 | H42: (*) Enemy killed
A43: Prize #2 | B43: Total | C43: =+SUM(C42:C42) -> 0.4 | F43: =+SUM(F42:F42) -> 1.2
A44: Prize #3
A46: Table 7 | B46: Prize # | C46: Probability | D46: Cumulative prob. | E46: Award | F46: RTP
A47: Awards granted: | B47: 2 | C47: 0.4 | D47: =+SUM(C$47:$C47) -> 0.4 | E47: =+E6 -> 3 | F47: =+E47*C47 -> 1.2 | G47: 0 | H47: (*) Enemy killed
A48: Prize #1 | B48: Total | C48: =+SUM(C47:C47) -> 0.4 | F48: =+SUM(F47:F47) -> 1.2
A49: Prize #3

Sheet Special weapon 1 (Std Mummy)
A1: SPECIAL WEAPON 1 - Standard Mummy
A2: For each shot with a special weapon, draw the damage caused using the table according to prizes already granted by enemy that is being shot.
A4: Table 1 | B4: Prize # | C4: Probability | D4: Cumulative prob. | E4: Award | F4: RTP | G4: Prob. Boss round
A5: (Initial state) | B5: 1 | C5: 0.26 | D5: =+SUM($C$5:C5) -> 0.26 | E5: =+Summary!B26 -> 2 | F5: =+C5*E5 -> 0.52
B6: 2 | C6: 0.16 | D6: =+SUM($C$5:C6) -> 0.42 | E6: =+Summary!B27 -> 3 | F6: =+C6*E6 -> 0.48
B7: 1 and 2 | C7: 0.04 | D7: =+SUM($C$5:C7) -> 0.46 | E7: =+E5+E6 -> 5 | F7: =+C7*E7 -> 0.2 | G7: 0 | H7: (*) Enemy killed
B8: Total (*) | C8: =+SUM(C5:C7) -> 0.46 | F8: =+SUM(F5:F7) -> 1.2
B9: (*) Total probability is hit rate
A12: Table 6 | B12: Prize # | C12: Probability | D12: Cumulative prob. | E12: Award | F12: RTP | G12: Prob. Boss round
A13: Awards granted: | B13: 1 | C13: 0.6 | D13: =+SUM(C13:$C$13) -> 0.6 | E13: =+E5 -> 2 | F13: =+E13*C13 -> 1.2 | G13: 0 | H13: (*) Enemy killed
A14: Prize #2 | B14: Total | C14: =+SUM(C13:C13) -> 0.6 | F14: =+SUM(F13:F13) -> 1.2
A17: Table 7 | B17: Prize # | C17: Probability | D17: Cumulative prob. | E17: Award | F17: RTP | G17: Prob. Boss round
A18: Awards granted: | B18: 2 | C18: 0.4 | D18: =+SUM(C$18:$C18) -> 0.4 | E18: =+E6 -> 3 | F18: =+E18*C18 -> 1.2 | G18: 0 | H18: (*) Enemy killed
A19: Prize #1 | B19: Total | C19: =+SUM(C18:C18) -> 0.4 | F19: =+SUM(F18:F18) -> 1.2

Sheet Special weapon 1 (Scarabs)
A1: SPECIAL WEAPON 1 - Scarabs
A2: For each shot with a special weapon, draw the damage caused using the table according to prizes already granted by enemy that is being shot.
A4: Scarab black | B4: Prize # | C4: Probability | D4: Cumulative prob. | E4: Award | F4: RTP | G4: Prob. Boss round
B5: 1 | C5: 0.6 | D5: =+SUM(C5:$C$5) -> 0.6 | E5: =+Summary!B20 -> 2 | F5: =+E5*C5 -> 1.2 | G5: 0 | H5: (*) Enemy killed
B6: Total | C6: =+SUM(C5:C5) -> 0.6 | F6: =+SUM(F5:F5) -> 1.2
A9: Scarab gold | B9: Prize # | C9: Probability | D9: Cumulative prob. | E9: Award | F9: RTP | G9: Prob. Boss round
B10: 1 | C10: 0.4 | D10: =1/6 -> 0.16666667 | E10: =+Summary!E20 -> 3 | F10: =+E10*C10 -> 1.2 | G10: 0 | H10: (*) Enemy killed
B11: Total | C11: =+SUM(C10:C10) -> 0.4 | F11: =+SUM(F10:F10) -> 1.2
A14: Scarab gem covered | B14: Prize # | C14: Probability | D14: Cumulative prob. | E14: Award | F14: RTP | G14: Prob. Boss round
B15: 1 | C15: 0.3 | D15: =+SUM(C$15:$C15) -> 0.3 | E15: =+Summary!H20 -> 4 | F15: =+E15*C15 -> 1.2 | G15: 0 | H15: (*) Enemy killed
B16: Total | C16: =+SUM(C15:C15) -> 0.3 | F16: =+SUM(F15:F15) -> 1.2

Sheet Special weapon 1 (Pharaoh A&B)
A1: SPECIAL WEAPON 1 - Powerful Pharaoh Mummy A & B
A2: For each shot with a special weapon, draw the damage caused using the table according to prizes already granted by enemy that is being shot.
A4: Table 1 | B4: Prize # | C4: Probability | D4: Cumulative prob. | E4: Award | F4: RTP | G4: Prob. Boss round
A5: (Initial state) | B5: 1 | C5: 0.12 | D5: =+SUM($C$5:C5) -> 0.12 | E5: =+Summary!B35 -> 2 | F5: =+C5*E5 -> 0.24
B6: 2 | C6: 0.01 | D6: =+SUM($C$5:C6) -> 0.13 | E6: =+Summary!B36 -> 5 | F6: =+C6*E6 -> 0.05
B7: 3 | C7: 0.01 | D7: =+SUM($C$5:C7) -> 0.14 | E7: =+Summary!B37 -> 8 | F7: =+C7*E7 -> 0.08
B8: 1 and 2 | C8: 0.01 | D8: =+SUM($C$5:C8) -> 0.15 | E8: =+E5+E6 -> 7 | F8: =+C8*E8 -> 0.07
B9: 1 and 3 | C9: 0.02 | D9: =+SUM($C$5:C9) -> 0.17 | E9: =+E5+E7 -> 10 | F9: =+C9*E9 -> 0.2
B10: 2 and 3 | C10: 0.02 | D10: =+SUM($C$5:C10) -> 0.19 | E10: =+E6+E7 -> 13 | F10: =+C10*E10 -> 0.26
B11: 1, 2 and 3 (*) | C11: 0.02 | D11: =+SUM($C$5:C11) -> 0.21 | E11: =+E5+E6+E7 -> 15 | F11: =+C11*E11 -> 0.3 | G11: 0 | H11: (*) Enemy killed
B12: Total (*) | C12: =+SUM(C5:C11) -> 0.21 | F12: =+SUM(F5:F11) -> 1.2
B13: (*) Total probability is hit rate
A15: Table 2 | B15: Prize # | C15: Probability | D15: Cumulative prob. | E15: Award | F15: RTP | G15: Prob. Boss round
A16: Awards granted: | B16: 2 | C16: 0.12 | D16: =+SUM(C16:$C$16) -> 0.12 | E16: =+E6 -> 5 | F16: =+C16*E16 -> 0.6
A17: Prize #1 | B17: 3 | C17: 0.01 | D17: =+SUM(C$16:$C17) -> 0.13 | E17: =+E7 -> 8 | F17: =+C17*E17 -> 0.08
B18: 2 and 3 | C18: 0.04 | D18: =+SUM(C$16:$C18) -> 0.17 | E18: =+E16+E17 -> 13 | F18: =+C18*E18 -> 0.52 | G18: 0 | H18: (*) Enemy killed
B19: Total | C19: =+SUM(C16:C18) -> 0.17 | F19: =+SUM(F16:F18) -> 1.2
A22: Table 3 | B22: Prize # | C22: Probability | D22: Cumulative prob. | E22: Award | F22: RTP | G22: Prob. Boss round
A23: Awards granted: | B23: 1 | C23: 0.15 | D23: =+SUM(C23:$C$23) -> 0.15 | E23: =+E5 -> 2 | F23: =+C23*E23 -> 0.3
A24: Prize #2 | B24: 3 | C24: 0.05 | D24: =+SUM(C$23:$C24) -> 0.2 | E24: =+E7 -> 8 | F24: =+C24*E24 -> 0.4
B25: 1 and 3 | C25: 0.05 | D25: =+SUM(C$23:$C25) -> 0.25 | E25: =+E23+E24 -> 10 | F25: =+C25*E25 -> 0.5 | G25: 0 | H25: (*) Enemy killed
B26: Total | C26: =+SUM(C23:C25) -> 0.25 | F26: =+SUM(F23:F25) -> 1.2
A29: Table 4 | B29: Prize # | C29: Probability | D29: Cumulative prob. | E29: Award | F29: RTP | G29: Prob. Boss round
A30: Awards granted: | B30: 3 | C30: 0.15 | D30: =+SUM(C30:$C$30) -> 0.15 | E30: =+E7 -> 8 | F30: =+C30*E30 -> 1.2 | G30: 0 | H30: (*) Enemy killed
A31: Prize #1 | B31: Total | C31: =+SUM(C30:C30) -> 0.15 | F31: =+SUM(F30:F30) -> 1.2
A32: Prize #2
A34: Table 5 | B34: Prize # | C34: Probability | D34: Cumulative prob. | E34: Award | F34: RTP | G34: Prob. Boss round
A35: Awards granted: | B35: 1 | C35: 0.14 | D35: =+SUM(C35:$C$35) -> 0.14 | E35: =+E5 -> 2 | F35: =+C35*E35 -> 0.28
A36: Prize #3 | B36: 2 | C36: 0.1 | D36: =+SUM(C$35:$C36) -> 0.24 | E36: =+E6 -> 5 | F36: =+C36*E36 -> 0.5
B37: 1 and 2 | C37: 0.06 | D37: =+SUM(C$35:$C37) -> 0.3 | E37: =+E35+E36 -> 7 | F37: =+C37*E37 -> 0.42 | G37: 0 | H37: (*) Enemy killed
B38: Total | C38: =+SUM(C35:C37) -> 0.3 | F38: =+SUM(F35:F37) -> 1.2
A41: Table 6 | B41: Prize # | C41: Probability | D41: Cumulative prob. | E41: Award | F41: RTP | G41: Prob. Boss round
A42: Awards granted: | B42: 1 | C42: 0.6 | D42: =+SUM(C42:$C$42) -> 0.6 | E42: =+E5 -> 2 | F42: =+E42*C42 -> 1.2 | G42: 0 | H42: (*) Enemy killed
A43: Prize #2 | B43: Total | C43: =+SUM(C42:C42) -> 0.6 | F43: =+SUM(F42:F42) -> 1.2
A44: Prize #3
A46: Table 7 | B46: Prize # | C46: Probability | D46: Cumulative prob. | E46: Award | F46: RTP | G46: Prob. Boss round
A47: Awards granted: | B47: 2 | C47: 0.24 | D47: =+SUM(C$47:$C47) -> 0.24 | E47: =+E6 -> 5 | F47: =+E47*C47 -> 1.2 | G47: 0 | H47: (*) Enemy killed
A48: Prize #1 | B48: Total | C48: =+SUM(C47:C47) -> 0.24 | F48: =+SUM(F47:F47) -> 1.2
A49: Prize #3

Sheet Special weapon 2 (Mummy A)
A1: SPECIAL WEAPON 2 - Medium Mummy A (golden wrist bands)
A2: For each shot with a special weapon, draw the damage caused using the table according to prizes already granted by enemy that is being shot.
A4: Table 1 | B4: Prize # | C4: Probability | D4: Cumulative prob. | E4: Award | F4: RTP | G4: Prob. Boss round
A5: (Initial state) | B5: 1 | C5: 0.405 | D5: =+SUM($C$5:C5) -> 0.405 | E5: =+Summary!E26 -> 2 | F5: =+C5*E5 -> 0.81
B6: 2 | C6: 0.055 | D6: =+SUM($C$5:C6) -> 0.46 | E6: =+Summary!E27 -> 3 | F6: =+C6*E6 -> 0.165
B7: 1 and 2 | C7: 0.015 | D7: =+SUM($C$5:C7) -> 0.475 | E7: =+E5+E6 -> 5 | F7: =+C7*E7 -> 0.075 | G7: 0 | H7: (*) Enemy killed
B8: Total (*) | C8: =+SUM(C5:C7) -> 0.475 | F8: =+SUM(F5:F7) -> 1.05
B9: (*) Total probability is hit rate
A12: Table 6 | B12: Prize # | C12: Probability | D12: Cumulative prob. | E12: Award | F12: RTP | G12: Prob. Boss round
A13: Awards granted: | B13: 1 | C13: 0.525 | D13: =+SUM(C13:$C$13) -> 0.525 | E13: =+E5 -> 2 | F13: =+E13*C13 -> 1.05 | G13: 0 | H13: (*) Enemy killed
A14: Prize #2 | B14: Total | C14: =+SUM(C13:C13) -> 0.525 | F14: =+SUM(F13:F13) -> 1.05
A17: Table 7 | B17: Prize # | C17: Probability | D17: Cumulative prob. | E17: Award | F17: RTP | G17: Prob. Boss round
A18: Awards granted: | B18: 2 | C18: 0.35 | D18: =+SUM(C$18:$C18) -> 0.35 | E18: =+E6 -> 3 | F18: =+E18*C18 -> 1.05 | G18: 0 | H18: (*) Enemy killed
A19: Prize #1 | B19: Total | C19: =+SUM(C18:C18) -> 0.35 | F19: =+SUM(F18:F18) -> 1.05

Sheet Special weapon 2 (Mummy B)
A1: SPECIAL WEAPON 2 -Medium Mummy B (golden wrist bands and necklace)
A2: For each shot with a special weapon, draw the damage caused using the table according to prizes already granted by enemy that is being shot.
A4: Table 1 | B4: Prize # | C4: Probability | D4: Cumulative prob. | E4: Award | F4: RTP | G4: Prob. Boss round
A5: (Initial state) | B5: 1 | C5: 0.15 | D5: =+SUM($C$5:C5) -> 0.15 | E5: =+Summary!H26 -> 2 | F5: =+C5*E5 -> 0.3
B6: 2 | C6: 0.15 | D6: =+SUM($C$5:C6) -> 0.3 | E6: =+Summary!H27 -> 2 | F6: =+C6*E6 -> 0.3
B7: 3 | C7: 0.0225 | D7: =+SUM($C$5:C7) -> 0.3225 | E7: =+Summary!H28 -> 4 | F7: =+C7*E7 -> 0.09
B8: 1 and 2 | C8: 0.05 | D8: =+SUM($C$5:C8) -> 0.3725 | E8: =+E5+E6 -> 4 | F8: =+C8*E8 -> 0.2
B9: 1 and 3 | C9: 0.01 | D9: =+SUM($C$5:C9) -> 0.3825 | E9: =+E5+E7 -> 6 | F9: =+C9*E9 -> 0.06
B10: 2 and 3 | C10: 0.01 | D10: =+SUM($C$5:C10) -> 0.3925 | E10: =+E6+E7 -> 6 | F10: =+C10*E10 -> 0.06
B11: 1, 2 and 3 (*) | C11: 0.005 | D11: =+SUM($C$5:C11) -> 0.3975 | E11: =+E5+E6+E7 -> 8 | F11: =+C11*E11 -> 0.04 | G11: 0 | H11: (*) Enemy killed
B12: Total (*) | C12: =+SUM(C5:C11) -> 0.3975 | F12: =+SUM(F5:F11) -> 1.05
B13: (*) Total probability is hit rate
A15: Table 2 | B15: Prize # | C15: Probability | D15: Cumulative prob. | E15: Award | F15: RTP | G15: Prob. Boss round
A16: Awards granted: | B16: 2 | C16: 0.4 | D16: =+SUM(C16:$C$16) -> 0.4 | E16: =+E6 -> 2 | F16: =+C16*E16 -> 0.8
A17: Prize #1 | B17: 3 | C17: 0.0325 | D17: =+SUM(C$16:$C17) -> 0.4325 | E17: =+E7 -> 4 | F17: =+C17*E17 -> 0.13
B18: 2 and 3 | C18: 0.02 | D18: =+SUM(C$16:$C18) -> 0.4525 | E18: =+E16+E17 -> 6 | F18: =+C18*E18 -> 0.12 | G18: 0 | H18: (*) Enemy killed
B19: Total | C19: =+SUM(C16:C18) -> 0.4525 | F19: =+SUM(F16:F18) -> 1.05
A22: Table 3 | B22: Prize # | C22: Probability | D22: Cumulative prob. | E22: Award | F22: RTP | G22: Prob. Boss round
A23: Awards granted: | B23: 1 | C23: 0.4 | D23: =+SUM(C23:$C$23) -> 0.4 | E23: =+E5 -> 2 | F23: =+C23*E23 -> 0.8
A24: Prize #2 | B24: 3 | C24: 0.0325 | D24: =+SUM(C$23:$C24) -> 0.4325 | E24: =+E7 -> 4 | F24: =+C24*E24 -> 0.13
B25: 1 and 3 | C25: 0.02 | D25: =+SUM(C$23:$C25) -> 0.4525 | E25: =+E23+E24 -> 6 | F25: =+C25*E25 -> 0.12 | G25: 0 | H25: (*) Enemy killed
B26: Total | C26: =+SUM(C23:C25) -> 0.4525 | F26: =+SUM(F23:F25) -> 1.05
A29: Table 4 | B29: Prize # | C29: Probability | D29: Cumulative prob. | E29: Award | F29: RTP | G29: Prob. Boss round
A30: Awards granted: | B30: 3 | C30: 0.2625 | D30: =+SUM(C30:$C$30) -> 0.2625 | E30: =+E7 -> 4 | F30: =+C30*E30 -> 1.05 | G30: 0 | H30: (*) Enemy killed
A31: Prize #1 | B31: Total | C31: =+SUM(C30:C30) -> 0.2625 | F31: =+SUM(F30:F30) -> 1.05
A32: Prize #2
A34: Table 5 | B34: Prize # | C34: Probability | D34: Cumulative prob. | E34: Award | F34: RTP | G34: Prob. Boss round
A35: Awards granted: | B35: 1 | C35: 0.24 | D35: =+SUM(C35:$C$35) -> 0.24 | E35: =+E5 -> 2 | F35: =+C35*E35 -> 0.48
A36: Prize #3 | B36: 2 | C36: 0.24 | D36: =+SUM(C$35:$C36) -> 0.48 | E36: =+E6 -> 2 | F36: =+C36*E36 -> 0.48
B37: 1 and 2 | C37: 0.0225 | D37: =+SUM(C$35:$C37) -> 0.5025 | E37: =+E35+E36 -> 4 | F37: =+C37*E37 -> 0.09 | G37: 0 | H37: (*) Enemy killed
B38: Total | C38: =+SUM(C35:C37) -> 0.5025 | F38: =+SUM(F35:F37) -> 1.05
A41: Table 6 | B41: Prize # | C41: Probability | D41: Cumulative prob. | E41: Award | F41: RTP
A42: Awards granted: | B42: 1 | C42: 0.525 | D42: =+SUM(C42:$C$42) -> 0.525 | E42: =+E5 -> 2 | F42: =+E42*C42 -> 1.05 | G42: 0 | H42: (*) Enemy killed
A43: Prize #2 | B43: Total | C43: =+SUM(C42:C42) -> 0.525 | F43: =+SUM(F42:F42) -> 1.05
A44: Prize #3
A46: Table 7 | B46: Prize # | C46: Probability | D46: Cumulative prob. | E46: Award | F46: RTP
A47: Awards granted: | B47: 2 | C47: 0.525 | D47: =+SUM(C$47:$C47) -> 0.525 | E47: =+E6 -> 2 | F47: =+E47*C47 -> 1.05 | G47: 0 | H47: (*) Enemy killed
A48: Prize #1 | B48: Total | C48: =+SUM(C47:C47) -> 0.525 | F48: =+SUM(F47:F47) -> 1.05
A49: Prize #3

Sheet Special weapon 2 (Mummy C)
A1: SPECIAL WEAPON 2 - Medium Mummy C (golden boots and wrist bands)
A2: For each shot with a special weapon, draw the damage caused using the table according to prizes already granted by enemy that is being shot.
A4: Table 1 | B4: Prize # | C4: Probability | D4: Cumulative prob. | E4: Award | F4: RTP | G4: Prob. Boss round
A5: (Initial state) | B5: 1 | C5: 0.1 | D5: =+SUM($C$5:C5) -> 0.1 | E5: =Summary!K26 -> 3 | F5: =+C5*E5 -> 0.3
B6: 2 | C6: 0.1 | D6: =+SUM($C$5:C6) -> 0.2 | E6: =Summary!K27 -> 3 | F6: =+C6*E6 -> 0.3
B7: 3 | C7: 0.015 | D7: =+SUM($C$5:C7) -> 0.215 | E7: =Summary!K28 -> 6 | F7: =+C7*E7 -> 0.09
B8: 1 and 2 | C8: 0.02 | D8: =+SUM($C$5:C8) -> 0.235 | E8: =+E5+E6 -> 6 | F8: =+C8*E8 -> 0.12
B9: 1 and 3 | C9: 0.01 | D9: =+SUM($C$5:C9) -> 0.245 | E9: =+E5+E7 -> 9 | F9: =+C9*E9 -> 0.09
B10: 2 and 3 | C10: 0.01 | D10: =+SUM($C$5:C10) -> 0.255 | E10: =+E6+E7 -> 9 | F10: =+C10*E10 -> 0.09
B11: 1, 2 and 3 (*) | C11: 0.005 | D11: =+SUM($C$5:C11) -> 0.26 | E11: =+E5+E6+E7 -> 12 | F11: =+C11*E11 -> 0.06 | G11: 0 | H11: (*) Enemy killed
B12: Total (*) | C12: =+SUM(C5:C11) -> 0.26 | F12: =+SUM(F5:F11) -> 1.05
B13: (*) Total probability is hit rate
A15: Table 2 | B15: Prize # | C15: Probability | D15: Cumulative prob. | E15: Award | F15: RTP | G15: Prob. Boss round
A16: Awards granted: | B16: 2 | C16: 0.25 | D16: =+SUM(C16:$C$16) -> 0.25 | E16: =+E6 -> 3 | F16: =+C16*E16 -> 0.75
A17: Prize #1 | B17: 3 | C17: 0.02 | D17: =+SUM(C$16:$C17) -> 0.27 | E17: =+E7 -> 6 | F17: =+C17*E17 -> 0.12
B18: 2 and 3 | C18: 0.02 | D18: =+SUM(C$16:$C18) -> 0.29 | E18: =+E16+E17 -> 9 | F18: =+C18*E18 -> 0.18 | G18: 0 | H18: (*) Enemy killed
B19: Total | C19: =+SUM(C16:C18) -> 0.29 | F19: =+SUM(F16:F18) -> 1.05
A22: Table 3 | B22: Prize # | C22: Probability | D22: Cumulative prob. | E22: Award | F22: RTP | G22: Prob. Boss round
A23: Awards granted: | B23: 1 | C23: 0.25 | D23: =+SUM(C23:$C$23) -> 0.25 | E23: =+E5 -> 3 | F23: =+C23*E23 -> 0.75
A24: Prize #2 | B24: 3 | C24: 0.02 | D24: =+SUM(C$23:$C24) -> 0.27 | E24: =+E7 -> 6 | F24: =+C24*E24 -> 0.12
B25: 1 and 3 | C25: 0.02 | D25: =+SUM(C$23:$C25) -> 0.29 | E25: =+E23+E24 -> 9 | F25: =+C25*E25 -> 0.18 | G25: 0 | H25: (*) Enemy killed
B26: Total | C26: =+SUM(C23:C25) -> 0.29 | F26: =+SUM(F23:F25) -> 1.05
A29: Table 4 | B29: Prize # | C29: Probability | D29: Cumulative prob. | E29: Award | F29: RTP | G29: Prob. Boss round
A30: Awards granted: | B30: 3 | C30: 0.175 | D30: =+SUM(C30:$C$30) -> 0.175 | E30: =+E7 -> 6 | F30: =+C30*E30 -> 1.05 | G30: 0 | H30: (*) Enemy killed
A31: Prize #1 | B31: Total | C31: =+SUM(C30:C30) -> 0.175 | F31: =+SUM(F30:F30) -> 1.05
A32: Prize #2
A34: Table 5 | B34: Prize # | C34: Probability | D34: Cumulative prob. | E34: Award | F34: RTP | G34: Prob. Boss round
A35: Awards granted: | B35: 1 | C35: 0.15 | D35: =+SUM(C35:$C$35) -> 0.15 | E35: =+E5 -> 3 | F35: =+C35*E35 -> 0.45
A36: Prize #3 | B36: 2 | C36: 0.15 | D36: =+SUM(C$35:$C36) -> 0.3 | E36: =+E6 -> 3 | F36: =+C36*E36 -> 0.45
B37: 1 and 2 | C37: 0.025 | D37: =+SUM(C$35:$C37) -> 0.325 | E37: =+E35+E36 -> 6 | F37: =+C37*E37 -> 0.15 | G37: 0 | H37: (*) Enemy killed
B38: Total | C38: =+SUM(C35:C37) -> 0.325 | F38: =+SUM(F35:F37) -> 1.05
A41: Table 6 | B41: Prize # | C41: Probability | D41: Cumulative prob. | E41: Award | F41: RTP
A42: Awards granted: | B42: 1 | C42: 0.35 | D42: =+SUM(C42:$C$42) -> 0.35 | E42: =+E5 -> 3 | F42: =+E42*C42 -> 1.05 | G42: 0 | H42: (*) Enemy killed
A43: Prize #2 | B43: Total | C43: =+SUM(C42:C42) -> 0.35 | F43: =+SUM(F42:F42) -> 1.05
A44: Prize #3
A46: Table 7 | B46: Prize # | C46: Probability | D46: Cumulative prob. | E46: Award | F46: RTP
A47: Awards granted: | B47: 2 | C47: 0.35 | D47: =+SUM(C$47:$C47) -> 0.35 | E47: =+E6 -> 3 | F47: =+E47*C47 -> 1.05 | G47: 0 | H47: (*) Enemy killed
A48: Prize #1 | B48: Total | C48: =+SUM(C47:C47) -> 0.35 | F48: =+SUM(F47:F47) -> 1.05
A49: Prize #3

Sheet Special weapon 2 (Std Mummy)
A1: SPECIAL WEAPON 2 - Standard Mummy
A2: For each shot with a special weapon, draw the damage caused using the table according to prizes already granted by enemy that is being shot.
A4: Table 1 | B4: Prize # | C4: Probability | D4: Cumulative prob. | E4: Award | F4: RTP | G4: Prob. Boss round
A5: (Initial state) | B5: 1 | C5: 0.25 | D5: =+SUM($C$5:C5) -> 0.25 | E5: =+Summary!B26 -> 2 | F5: =+C5*E5 -> 0.5
B6: 2 | C6: 0.1 | D6: =+SUM($C$5:C6) -> 0.35 | E6: =+Summary!B27 -> 3 | F6: =+C6*E6 -> 0.3
B7: 1 and 2 | C7: 0.05 | D7: =+SUM($C$5:C7) -> 0.4 | E7: =+E5+E6 -> 5 | F7: =+C7*E7 -> 0.25 | G7: 0 | H7: (*) Enemy killed
B8: Total (*) | C8: =+SUM(C5:C7) -> 0.4 | F8: =+SUM(F5:F7) -> 1.05
B9: (*) Total probability is hit rate
A12: Table 6 | B12: Prize # | C12: Probability | D12: Cumulative prob. | E12: Award | F12: RTP | G12: Prob. Boss round
A13: Awards granted: | B13: 1 | C13: 0.525 | D13: =+SUM(C13:$C$13) -> 0.525 | E13: =+E5 -> 2 | F13: =+E13*C13 -> 1.05 | G13: 0 | H13: (*) Enemy killed
A14: Prize #2 | B14: Total | C14: =+SUM(C13:C13) -> 0.525 | F14: =+SUM(F13:F13) -> 1.05
A17: Table 7 | B17: Prize # | C17: Probability | D17: Cumulative prob. | E17: Award | F17: RTP | G17: Prob. Boss round
A18: Awards granted: | B18: 2 | C18: 0.35 | D18: =+SUM(C$18:$C18) -> 0.35 | E18: =+E6 -> 3 | F18: =+E18*C18 -> 1.05 | G18: 0 | H18: (*) Enemy killed
A19: Prize #1 | B19: Total | C19: =+SUM(C18:C18) -> 0.35 | F19: =+SUM(F18:F18) -> 1.05

Sheet Special weapon 2 (Scarabs)
A1: SPECIAL WEAPON 2 - Scarabs
A2: For each shot with a special weapon, draw the damage caused using the table according to prizes already granted by enemy that is being shot.
A4: Scarab black | B4: Prize # | C4: Probability | D4: Cumulative prob. | E4: Award | F4: RTP | G4: Prob. Boss round
B5: 1 | C5: 0.525 | D5: =+SUM(C5:$C$5) -> 0.525 | E5: =+Summary!B20 -> 2 | F5: =+E5*C5 -> 1.05 | G5: 0 | H5: (*) Enemy killed
B6: Total | C6: =+SUM(C5:C5) -> 0.525 | F6: =+SUM(F5:F5) -> 1.05
A9: Scarab gold | B9: Prize # | C9: Probability | D9: Cumulative prob. | E9: Award | F9: RTP | G9: Prob. Boss round
B10: 1 | C10: 0.35 | D10: =1/6 -> 0.16666667 | E10: =+Summary!E20 -> 3 | F10: =+E10*C10 -> 1.05 | G10: 0 | H10: (*) Enemy killed
B11: Total | C11: =+SUM(C10:C10) -> 0.35 | F11: =+SUM(F10:F10) -> 1.05
A14: Scarab gem covered | B14: Prize # | C14: Probability | D14: Cumulative prob. | E14: Award | F14: RTP | G14: Prob. Boss round
B15: 1 | C15: 0.2625 | D15: =+SUM(C$15:$C15) -> 0.2625 | E15: =+Summary!H20 -> 4 | F15: =+E15*C15 -> 1.05 | G15: 0 | H15: (*) Enemy killed
B16: Total | C16: =+SUM(C15:C15) -> 0.2625 | F16: =+SUM(F15:F15) -> 1.05

Sheet Special weapon 2 (Pharaoh A&B)
A1: SPECIAL WEAPON 2 - Powerful Pharaoh Mummy A & B
A2: For each shot with a special weapon, draw the damage caused using the table according to prizes already granted by enemy that is being shot.
A4: Table 1 | B4: Prize # | C4: Probability | D4: Cumulative prob. | E4: Award | F4: RTP | G4: Prob. Boss round
A5: (Initial state) | B5: 1 | C5: 0.12 | D5: =+SUM($C$5:C5) -> 0.12 | E5: =+Summary!B35 -> 2 | F5: =+C5*E5 -> 0.24
B6: 2 | C6: 0.01 | D6: =+SUM($C$5:C6) -> 0.13 | E6: =+Summary!B36 -> 5 | F6: =+C6*E6 -> 0.05
B7: 3 | C7: 0.01 | D7: =+SUM($C$5:C7) -> 0.14 | E7: =+Summary!B37 -> 8 | F7: =+C7*E7 -> 0.08
B8: 1 and 2 | C8: 0.01 | D8: =+SUM($C$5:C8) -> 0.15 | E8: =+E5+E6 -> 7 | F8: =+C8*E8 -> 0.07
B9: 1 and 3 | C9: 0.02 | D9: =+SUM($C$5:C9) -> 0.17 | E9: =+E5+E7 -> 10 | F9: =+C9*E9 -> 0.2
B10: 2 and 3 | C10: 0.02 | D10: =+SUM($C$5:C10) -> 0.19 | E10: =+E6+E7 -> 13 | F10: =+C10*E10 -> 0.26
B11: 1, 2 and 3 (*) | C11: 0.01 | D11: =+SUM($C$5:C11) -> 0.2 | E11: =+E5+E6+E7 -> 15 | F11: =+C11*E11 -> 0.15 | G11: 0 | H11: (*) Enemy killed
B12: Total (*) | C12: =+SUM(C5:C11) -> 0.2 | F12: =+SUM(F5:F11) -> 1.05
B13: (*) Total probability is hit rate
A15: Table 2 | B15: Prize # | C15: Probability | D15: Cumulative prob. | E15: Award | F15: RTP | G15: Prob. Boss round
A16: Awards granted: | B16: 2 | C16: 0.09 | D16: =+SUM(C16:$C$16) -> 0.09 | E16: =+E6 -> 5 | F16: =+C16*E16 -> 0.45
A17: Prize #1 | B17: 3 | C17: 0.01 | D17: =+SUM(C$16:$C17) -> 0.1 | E17: =+E7 -> 8 | F17: =+C17*E17 -> 0.08
B18: 2 and 3 | C18: 0.04 | D18: =+SUM(C$16:$C18) -> 0.14 | E18: =+E16+E17 -> 13 | F18: =+C18*E18 -> 0.52 | G18: 0 | H18: (*) Enemy killed
B19: Total | C19: =+SUM(C16:C18) -> 0.14 | F19: =+SUM(F16:F18) -> 1.05
A22: Table 3 | B22: Prize # | C22: Probability | D22: Cumulative prob. | E22: Award | F22: RTP | G22: Prob. Boss round
A23: Awards granted: | B23: 1 | C23: 0.12 | D23: =+SUM(C23:$C$23) -> 0.12 | E23: =+E5 -> 2 | F23: =+C23*E23 -> 0.24
A24: Prize #2 | B24: 3 | C24: 0.04 | D24: =+SUM(C$23:$C24) -> 0.16 | E24: =+E7 -> 8 | F24: =+C24*E24 -> 0.32
B25: 1 and 3 | C25: 0.049 | D25: =+SUM(C$23:$C25) -> 0.209 | E25: =+E23+E24 -> 10 | F25: =+C25*E25 -> 0.49 | G25: 0 | H25: (*) Enemy killed
B26: Total | C26: =+SUM(C23:C25) -> 0.209 | F26: =+SUM(F23:F25) -> 1.05
A29: Table 4 | B29: Prize # | C29: Probability | D29: Cumulative prob. | E29: Award | F29: RTP | G29: Prob. Boss round
A30: Awards granted: | B30: 3 | C30: 0.13125 | D30: =+SUM(C30:$C$30) -> 0.13125 | E30: =+E7 -> 8 | F30: =+C30*E30 -> 1.05 | G30: 0 | H30: (*) Enemy killed
A31: Prize #1 | B31: Total | C31: =+SUM(C30:C30) -> 0.13125 | F31: =+SUM(F30:F30) -> 1.05
A32: Prize #2
A34: Table 5 | B34: Prize # | C34: Probability | D34: Cumulative prob. | E34: Award | F34: RTP | G34: Prob. Boss round
A35: Awards granted: | B35: 1 | C35: 0.12 | D35: =+SUM(C35:$C$35) -> 0.12 | E35: =+E5 -> 2 | F35: =+C35*E35 -> 0.24
A36: Prize #3 | B36: 2 | C36: 0.078 | D36: =+SUM(C$35:$C36) -> 0.198 | E36: =+E6 -> 5 | F36: =+C36*E36 -> 0.39
B37: 1 and 2 | C37: 0.06 | D37: =+SUM(C$35:$C37) -> 0.258 | E37: =+E35+E36 -> 7 | F37: =+C37*E37 -> 0.42 | G37: 0 | H37: (*) Enemy killed
B38: Total | C38: =+SUM(C35:C37) -> 0.258 | F38: =+SUM(F35:F37) -> 1.05
A41: Table 6 | B41: Prize # | C41: Probability | D41: Cumulative prob. | E41: Award | F41: RTP | G41: Prob. Boss round
A42: Awards granted: | B42: 1 | C42: 0.525 | D42: =+SUM(C42:$C$42) -> 0.525 | E42: =+E5 -> 2 | F42: =+E42*C42 -> 1.05 | G42: 0 | H42: (*) Enemy killed
A43: Prize #2 | B43: Total | C43: =+SUM(C42:C42) -> 0.525 | F43: =+SUM(F42:F42) -> 1.05
A44: Prize #3
A46: Table 7 | B46: Prize # | C46: Probability | D46: Cumulative prob. | E46: Award | F46: RTP | G46: Prob. Boss round
A47: Awards granted: | B47: 2 | C47: 0.21 | D47: =+SUM(C$47:$C47) -> 0.21 | E47: =+E6 -> 5 | F47: =+E47*C47 -> 1.05 | G47: 0 | H47: (*) Enemy killed
A48: Prize #1 | B48: Total | C48: =+SUM(C47:C47) -> 0.21 | F48: =+SUM(F47:F47) -> 1.05
A49: Prize #3

Sheet Special weapon 3 (Mummy A)
A1: SPECIAL WEAPON 3 - Medium Mummy A (golden wrist bands)
A2: For each shot with a special weapon, draw the damage caused using the table according to prizes already granted by enemy that is being shot.
A4: Table 1 | B4: Prize # | C4: Probability | D4: Cumulative prob. | E4: Award | F4: RTP | G4: Prob. Boss round
A5: (Initial state) | B5: 1 | C5: 0.35 | D5: =+SUM($C$5:C5) -> 0.35 | E5: =+Summary!E26 -> 2 | F5: =+C5*E5 -> 0.7
B6: 2 | C6: 0.05 | D6: =+SUM($C$5:C6) -> 0.4 | E6: =+Summary!E27 -> 3 | F6: =+C6*E6 -> 0.15
B7: 1 and 2 | C7: 0.01 | D7: =+SUM($C$5:C7) -> 0.41 | E7: =+E5+E6 -> 5 | F7: =+C7*E7 -> 0.05 | G7: 0 | H7: (*) Enemy killed
B8: Total (*) | C8: =+SUM(C5:C7) -> 0.41 | F8: =+SUM(F5:F7) -> 0.9
B9: (*) Total probability is hit rate
A12: Table 6 | B12: Prize # | C12: Probability | D12: Cumulative prob. | E12: Award | F12: RTP | G12: Prob. Boss round
A13: Awards granted: | B13: 1 | C13: 0.45 | D13: =+SUM(C13:$C$13) -> 0.45 | E13: =+E5 -> 2 | F13: =+E13*C13 -> 0.9 | G13: 0 | H13: (*) Enemy killed
A14: Prize #2 | B14: Total | C14: =+SUM(C13:C13) -> 0.45 | F14: =+SUM(F13:F13) -> 0.9
A17: Table 7 | B17: Prize # | C17: Probability | D17: Cumulative prob. | E17: Award | F17: RTP | G17: Prob. Boss round
A18: Awards granted: | B18: 2 | C18: 0.3 | D18: =+SUM(C$18:$C18) -> 0.3 | E18: =+E6 -> 3 | F18: =+E18*C18 -> 0.9 | G18: 0 | H18: (*) Enemy killed
A19: Prize #1 | B19: Total | C19: =+SUM(C18:C18) -> 0.3 | F19: =+SUM(F18:F18) -> 0.9

Sheet Special weapon 3 (Mummy B)
A1: SPECIAL WEAPON 3 - Medium Mummy B (golden wrist bands and necklace)
A2: For each shot with a special weapon, draw the damage caused using the table according to prizes already granted by enemy that is being shot.
A4: Table 1 | B4: Prize # | C4: Probability | D4: Cumulative prob. | E4: Award | F4: RTP | G4: Prob. Boss round
A5: (Initial state) | B5: 1 | C5: 0.12 | D5: =+SUM($C$5:C5) -> 0.12 | E5: =+Summary!H26 -> 2 | F5: =+C5*E5 -> 0.24
B6: 2 | C6: 0.12 | D6: =+SUM($C$5:C6) -> 0.24 | E6: =+Summary!H27 -> 2 | F6: =+C6*E6 -> 0.24
B7: 3 | C7: 0.02 | D7: =+SUM($C$5:C7) -> 0.26 | E7: =+Summary!H28 -> 4 | F7: =+C7*E7 -> 0.08
B8: 1 and 2 | C8: 0.045 | D8: =+SUM($C$5:C8) -> 0.305 | E8: =+E5+E6 -> 4 | F8: =+C8*E8 -> 0.18
B9: 1 and 3 | C9: 0.01 | D9: =+SUM($C$5:C9) -> 0.315 | E9: =+E5+E7 -> 6 | F9: =+C9*E9 -> 0.06
B10: 2 and 3 | C10: 0.01 | D10: =+SUM($C$5:C10) -> 0.325 | E10: =+E6+E7 -> 6 | F10: =+C10*E10 -> 0.06
B11: 1, 2 and 3 (*) | C11: 0.005 | D11: =+SUM($C$5:C11) -> 0.33 | E11: =+E5+E6+E7 -> 8 | F11: =+C11*E11 -> 0.04 | G11: 0 | H11: (*) Enemy killed
B12: Total (*) | C12: =+SUM(C5:C11) -> 0.33 | F12: =+SUM(F5:F11) -> 0.9
B13: (*) Total probability is hit rate
A15: Table 2 | B15: Prize # | C15: Probability | D15: Cumulative prob. | E15: Award | F15: RTP | G15: Prob. Boss round
A16: Awards granted: | B16: 2 | C16: 0.33 | D16: =+SUM(C16:$C$16) -> 0.33 | E16: =+E6 -> 2 | F16: =+C16*E16 -> 0.66
A17: Prize #1 | B17: 3 | C17: 0.03 | D17: =+SUM(C$16:$C17) -> 0.36 | E17: =+E7 -> 4 | F17: =+C17*E17 -> 0.12
B18: 2 and 3 | C18: 0.02 | D18: =+SUM(C$16:$C18) -> 0.38 | E18: =+E16+E17 -> 6 | F18: =+C18*E18 -> 0.12 | G18: 0 | H18: (*) Enemy killed
B19: Total | C19: =+SUM(C16:C18) -> 0.38 | F19: =+SUM(F16:F18) -> 0.9
A22: Table 3 | B22: Prize # | C22: Probability | D22: Cumulative prob. | E22: Award | F22: RTP | G22: Prob. Boss round
A23: Awards granted: | B23: 1 | C23: 0.33 | D23: =+SUM(C23:$C$23) -> 0.33 | E23: =+E5 -> 2 | F23: =+C23*E23 -> 0.66
A24: Prize #2 | B24: 3 | C24: 0.03 | D24: =+SUM(C$23:$C24) -> 0.36 | E24: =+E7 -> 4 | F24: =+C24*E24 -> 0.12
B25: 1 and 3 | C25: 0.02 | D25: =+SUM(C$23:$C25) -> 0.38 | E25: =+E23+E24 -> 6 | F25: =+C25*E25 -> 0.12 | G25: 0 | H25: (*) Enemy killed
B26: Total | C26: =+SUM(C23:C25) -> 0.38 | F26: =+SUM(F23:F25) -> 0.9
A29: Table 4 | B29: Prize # | C29: Probability | D29: Cumulative prob. | E29: Award | F29: RTP | G29: Prob. Boss round
A30: Awards granted: | B30: 3 | C30: 0.225 | D30: =+SUM(C30:$C$30) -> 0.225 | E30: =+E7 -> 4 | F30: =+C30*E30 -> 0.9 | G30: 0 | H30: (*) Enemy killed
A31: Prize #1 | B31: Total | C31: =+SUM(C30:C30) -> 0.225 | F31: =+SUM(F30:F30) -> 0.9
A32: Prize #2
A34: Table 5 | B34: Prize # | C34: Probability | D34: Cumulative prob. | E34: Award | F34: RTP | G34: Prob. Boss round
A35: Awards granted: | B35: 1 | C35: 0.2 | D35: =+SUM(C35:$C$35) -> 0.2 | E35: =+E5 -> 2 | F35: =+C35*E35 -> 0.4
A36: Prize #3 | B36: 2 | C36: 0.2 | D36: =+SUM(C$35:$C36) -> 0.4 | E36: =+E6 -> 2 | F36: =+C36*E36 -> 0.4
B37: 1 and 2 | C37: 0.025 | D37: =+SUM(C$35:$C37) -> 0.425 | E37: =+E35+E36 -> 4 | F37: =+C37*E37 -> 0.1 | G37: 0 | H37: (*) Enemy killed
B38: Total | C38: =+SUM(C35:C37) -> 0.425 | F38: =+SUM(F35:F37) -> 0.9
A41: Table 6 | B41: Prize # | C41: Probability | D41: Cumulative prob. | E41: Award | F41: RTP
A42: Awards granted: | B42: 1 | C42: 0.45 | D42: =+SUM(C42:$C$42) -> 0.45 | E42: =+E5 -> 2 | F42: =+E42*C42 -> 0.9 | G42: 0 | H42: (*) Enemy killed
A43: Prize #2 | B43: Total | C43: =+SUM(C42:C42) -> 0.45 | F43: =+SUM(F42:F42) -> 0.9
A44: Prize #3
A46: Table 7 | B46: Prize # | C46: Probability | D46: Cumulative prob. | E46: Award | F46: RTP
A47: Awards granted: | B47: 2 | C47: 0.45 | D47: =+SUM(C$47:$C47) -> 0.45 | E47: =+E6 -> 2 | F47: =+E47*C47 -> 0.9 | G47: 0 | H47: (*) Enemy killed
A48: Prize #1 | B48: Total | C48: =+SUM(C47:C47) -> 0.45 | F48: =+SUM(F47:F47) -> 0.9
A49: Prize #3

Sheet Special weapon 3 (Mummy C)
A1: SPECIAL WEAPON 3 - Medium Mummy C (golden boots and wrist bands)
A2: For each shot with a special weapon, draw the damage caused using the table according to prizes already granted by enemy that is being shot.
A4: Table 1 | B4: Prize # | C4: Probability | D4: Cumulative prob. | E4: Award | F4: RTP | G4: Prob. Boss round
A5: (Initial state) | B5: 1 | C5: 0.09 | D5: =+SUM($C$5:C5) -> 0.09 | E5: =Summary!K26 -> 3 | F5: =+C5*E5 -> 0.27
B6: 2 | C6: 0.09 | D6: =+SUM($C$5:C6) -> 0.18 | E6: =Summary!K27 -> 3 | F6: =+C6*E6 -> 0.27
B7: 3 | C7: 0.01 | D7: =+SUM($C$5:C7) -> 0.19 | E7: =Summary!K28 -> 6 | F7: =+C7*E7 -> 0.06
B8: 1 and 2 | C8: 0.01 | D8: =+SUM($C$5:C8) -> 0.2 | E8: =+E5+E6 -> 6 | F8: =+C8*E8 -> 0.06
B9: 1 and 3 | C9: 0.01 | D9: =+SUM($C$5:C9) -> 0.21 | E9: =+E5+E7 -> 9 | F9: =+C9*E9 -> 0.09
B10: 2 and 3 | C10: 0.01 | D10: =+SUM($C$5:C10) -> 0.22 | E10: =+E6+E7 -> 9 | F10: =+C10*E10 -> 0.09
B11: 1, 2 and 3 (*) | C11: 0.005 | D11: =+SUM($C$5:C11) -> 0.225 | E11: =+E5+E6+E7 -> 12 | F11: =+C11*E11 -> 0.06 | G11: 0 | H11: (*) Enemy killed
B12: Total (*) | C12: =+SUM(C5:C11) -> 0.225 | F12: =+SUM(F5:F11) -> 0.9
B13: (*) Total probability is hit rate
A15: Table 2 | B15: Prize # | C15: Probability | D15: Cumulative prob. | E15: Award | F15: RTP | G15: Prob. Boss round
A16: Awards granted: | B16: 2 | C16: 0.2 | D16: =+SUM(C16:$C$16) -> 0.2 | E16: =+E6 -> 3 | F16: =+C16*E16 -> 0.6
