Workbook

Sheet Index
O5: Index | Q5: Summary
O7: Treasure Probabilities Table | Q7: Lists the probability of treasure types for each enemy (the probability of a given enemy dropping a treasure type)
O8: Treasure List | Q8: Lists all the available treasure that can be dropped, and their rarity value
O9: Award Values Table | Q9: List of values for items used for achievements
O10: Achievements Calculation Table | Q10: Shows the items used for achievements by level, and the formulas used to calculate the number to be used for each achievement and the associated rewards
O11: Level Up Rewards | Q11: Rewards for leveling up and promotion
O12: Enemy Destroyed Rewards | Q12: Rewards for firing the final shot that destroys an enemy
O13: All Contributions to players score | Q13: Table of all contributing factors to the players score
O14: Probability of Points Reward Chest | Q14: Probability of receiving Reward Chest and probability of different awards

Sheet Probabilities
L1: Hoard Values | N1: Prize | O1: 80 | Q1: Boss Values | S1: Prize | T1: 50
B2: Treasure Probabilities Table | F2: Note: These probabilites should be added together and one draw made from the total (so only a single item can be dropped) - the exception to this is the Boss, where a separate draw should be made for each item time (so multiple items can be dropped) | N2: Number of Enemies | O2: 10 | S2: Share of Prize | T2: 3
B3: Prize Values | C3: 1 | D3: 2 | E3: 3 | F3: 4 | G3: 5 | M3: 1 | N3: 2 | O3: 3 | P3: 4 | Q3: 5
B4: Enemy | C4: Common | D4: Uncommon | E4: Rare | F4: Very Rare | G4: Super Rare | H4: Total | I4: Enemy Strength | J4: Moderated Award | L4: Enemy | M4: Common | N4: Uncommon | O4: Rare | P4: Very Rare | Q4: Super Rare | R4: Total | S4: Enemy Strength | T4: Moderated Award
L5: =Table2[[#This Row],[Enemy]] -> 0 | M5: =Table2[[#This Row],[Common]] -> 0 | N5: =Table2[[#This Row],[Uncommon]] -> 0 | O5: =Table2[[#This Row],[Rare]] -> 0 | P5: =Table2[[#This Row],[Common]] -> 0 | Q5: =Table2[[#This Row],[Uncommon]] -> 0 | R5: =SUM(Table3[[#This Row],[Common]:[Super Rare]]) -> 0 | S5: =B37 -> 1
B6: Scarab black | C6: 0.1 | D6: 0.02 | H6: =SUM(C6:G6) -> 0.12 | I6: =B38 -> 1 | J6: =H6/I6 -> 0.12 | L6: =Table2[[#This Row],[Enemy]] -> Scarab black | M6: =Table2[[#This Row],[Common]]*$C$3*100 -> 10 | N6: =Table2[[#This Row],[Uncommon]]*$D$3*100 -> 4 | O6: =Table2[[#This Row],[Rare]]*$E$3*100 -> 0 | P6: =Table2[[#This Row],[Very Rare]]*$F$3*100 -> 0 | Q6: =Table2[[#This Row],[Super Rare]]*$G$3*100 -> 0 | R6: =SUM(Table3[[#This Row],[Common]:[Super Rare]]) -> 14 | S6: =B38 -> 1 | T6: =R6/S6 -> 14
B7: Scarab gold | C7: 0.1 | D7: 0.02 | E7: 0.01 | H7: =SUM(C7:G7) -> 0.13 | I7: =B39 -> 2 | J7: =H7/I7 -> 0.065 | L7: =Table2[[#This Row],[Enemy]] -> Scarab gold | M7: =Table2[[#This Row],[Common]]*$C$3*100 -> 10 | N7: =Table2[[#This Row],[Uncommon]]*$D$3*100 -> 4 | O7: =Table2[[#This Row],[Rare]]*$E$3*100 -> 3 | P7: =Table2[[#This Row],[Very Rare]]*$F$3*100 -> 0 | Q7: =Table2[[#This Row],[Super Rare]]*$G$3*100 -> 0 | R7: =SUM(Table3[[#This Row],[Common]:[Super Rare]]) -> 17 | S7: =B39 -> 2 | T7: =R7/S7 -> 8.5
B8: Scarab gem covered | C8: 0.12 | D8: 0.03 | E8: 0.02 | F8: 0.01 | H8: =SUM(C8:G8) -> 0.18 | I8: =B40 -> 3 | J8: =H8/I8 -> 0.06 | L8: =Table2[[#This Row],[Enemy]] -> Scarab gem covered | M8: =Table2[[#This Row],[Common]]*$C$3*100 -> 12 | N8: =Table2[[#This Row],[Uncommon]]*$D$3*100 -> 6 | O8: =Table2[[#This Row],[Rare]]*$E$3*100 -> 6 | P8: =Table2[[#This Row],[Very Rare]]*$F$3*100 -> 4 | Q8: =Table2[[#This Row],[Super Rare]]*$G$3*100 -> 0 | R8: =SUM(Table3[[#This Row],[Common]:[Super Rare]]) -> 28 | S8: =B40 -> 3 | T8: =R8/S8 -> 9.3333333
B9: Standard Mummy | C9: 0.12 | D9: 0.01 | E9: 0.01 | F9: 0.01 | H9: =SUM(C9:G9) -> 0.15 | I9: =B41 -> 2 | J9: =H9/I9 -> 0.075 | L9: =Table2[[#This Row],[Enemy]] -> Standard Mummy | M9: =Table2[[#This Row],[Common]]*$C$3*100 -> 12 | N9: =Table2[[#This Row],[Uncommon]]*$D$3*100 -> 2 | O9: =Table2[[#This Row],[Rare]]*$E$3*100 -> 3 | P9: =Table2[[#This Row],[Very Rare]]*$F$3*100 -> 4 | Q9: =Table2[[#This Row],[Super Rare]]*$G$3*100 -> 0 | R9: =SUM(Table3[[#This Row],[Common]:[Super Rare]]) -> 21 | S9: =B41 -> 2 | T9: =R9/S9 -> 10.5
B10: Medium Mummy A | C10: 0.15 | D10: 0.02 | E10: 0.01 | F10: 0.01 | H10: =SUM(C10:G10) -> 0.19 | I10: =B42 -> 3 | J10: =H10/I10 -> 0.063333333 | L10: =Table2[[#This Row],[Enemy]] -> Medium Mummy A | M10: =Table2[[#This Row],[Common]]*$C$3*100 -> 15 | N10: =Table2[[#This Row],[Uncommon]]*$D$3*100 -> 4 | O10: =Table2[[#This Row],[Rare]]*$E$3*100 -> 3 | P10: =Table2[[#This Row],[Very Rare]]*$F$3*100 -> 4 | Q10: =Table2[[#This Row],[Super Rare]]*$G$3*100 -> 0 | R10: =SUM(Table3[[#This Row],[Common]:[Super Rare]]) -> 26 | S10: =B42 -> 3 | T10: =R10/S10 -> 8.6666667
B11: Medium Mummy B | C11: 0.12 | D11: 0.03 | E11: 0.03 | H11: =SUM(C11:G11) -> 0.18 | I11: =B43 -> 4 | J11: =H11/I11 -> 0.045 | L11: =Table2[[#This Row],[Enemy]] -> Medium Mummy B | M11: =Table2[[#This Row],[Common]]*$C$3*100 -> 12 | N11: =Table2[[#This Row],[Uncommon]]*$D$3*100 -> 6 | O11: =Table2[[#This Row],[Rare]]*$E$3*100 -> 9 | P11: =Table2[[#This Row],[Very Rare]]*$F$3*100 -> 0 | Q11: =Table2[[#This Row],[Super Rare]]*$G$3*100 -> 0 | R11: =SUM(Table3[[#This Row],[Common]:[Super Rare]]) -> 27 | S11: =B43 -> 4 | T11: =R11/S11 -> 6.75
B12: Medium Mummy C | C12: 0.15 | D12: 0.02 | E12: 0.02 | F12: 0.03 | H12: =SUM(C12:G12) -> 0.22 | I12: =B44 -> 5 | J12: =H12/I12 -> 0.044 | L12: =Table2[[#This Row],[Enemy]] -> Medium Mummy C | M12: =Table2[[#This Row],[Common]]*$C$3*100 -> 15 | N12: =Table2[[#This Row],[Uncommon]]*$D$3*100 -> 4 | O12: =Table2[[#This Row],[Rare]]*$E$3*100 -> 6 | P12: =Table2[[#This Row],[Very Rare]]*$F$3*100 -> 12 | Q12: =Table2[[#This Row],[Super Rare]]*$G$3*100 -> 0 | R12: =SUM(Table3[[#This Row],[Common]:[Super Rare]]) -> 37 | S12: =B44 -> 5 | T12: =R12/S12 -> 7.4
B13: Powerful Pharaoh Mummy A | C13: 0.2 | D13: 0.26 | E13: 0.17 | F13: 0.05 | G13: 0.02 | H13: =SUM(C13:G13) -> 0.7 | I13: =B45 -> 8 | J13: =H13/I13 -> 0.0875 | L13: =Table2[[#This Row],[Enemy]] -> Powerful Pharaoh Mummy A | M13: =Table2[[#This Row],[Common]]*$C$3*100 -> 20 | N13: =Table2[[#This Row],[Uncommon]]*$D$3*100 -> 52 | O13: =Table2[[#This Row],[Rare]]*$E$3*100 -> 51 | P13: =Table2[[#This Row],[Very Rare]]*$F$3*100 -> 20 | Q13: =Table2[[#This Row],[Super Rare]]*$G$3*100 -> 10 | R13: =SUM(Table3[[#This Row],[Common]:[Super Rare]]) -> 153 | S13: =B45 -> 8 | T13: =R13/S13 -> 19.125
B14: Powerful Pharaoh Mummy B | C14: 0.25 | D14: 0.2 | E14: 0.15 | F14: 0.1 | G14: 0.05 | H14: =SUM(C14:G14) -> 0.75 | I14: =B46 -> 8 | J14: =H14/I14 -> 0.09375 | L14: =Table2[[#This Row],[Enemy]] -> Powerful Pharaoh Mummy B | M14: =Table2[[#This Row],[Common]]*$C$3*100 -> 25 | N14: =Table2[[#This Row],[Uncommon]]*$D$3*100 -> 40 | O14: =Table2[[#This Row],[Rare]]*$E$3*100 -> 45 | P14: =Table2[[#This Row],[Very Rare]]*$F$3*100 -> 40 | Q14: =Table2[[#This Row],[Super Rare]]*$G$3*100 -> 25 | R14: =SUM(Table3[[#This Row],[Common]:[Super Rare]]) -> 175 | S14: =B46 -> 8 | T14: =R14/S14 -> 21.875
B15: Standard Mummy (Hoard) | C15: 0.05 | D15: 0.1 | E15: 0.1 | F15: 0.05 | G15: 0.02 | H15: =SUM(C15:G15) -> 0.32 | I15: =#REF! -> #REF! | J15: =H15/I15 -> #REF! | L15: =Table2[[#This Row],[Enemy]] -> Standard Mummy (Hoard) | M15: =Table2[[#This Row],[Common]]*$C$3*100 -> 5 | N15: =Table2[[#This Row],[Uncommon]]*$D$3*100 -> 20 | O15: =Table2[[#This Row],[Rare]]*$E$3*100 -> 30 | P15: =Table2[[#This Row],[Very Rare]]*$F$3*100 -> 20 | Q15: =Table2[[#This Row],[Super Rare]]*$G$3*100 -> 10 | R15: =SUM(Table3[[#This Row],[Common]:[Super Rare]]) -> 85 | S15: =#REF! -> #REF! | T15: =R15/S15 -> #REF!
B16: Medium Mummy A (Hoard) | C16: 0.05 | D16: 0.15 | E16: 0.1 | F16: 0.15 | G16: 0.05 | H16: =SUM(C16:G16) -> 0.5 | I16: =B48 -> 15 | J16: =H16/I16 -> 0.033333333 | L16: =Table2[[#This Row],[Enemy]] -> Medium Mummy A (Hoard) | M16: =Table2[[#This Row],[Common]]*$C$3*100 -> 5 | N16: =Table2[[#This Row],[Uncommon]]*$D$3*100 -> 30 | O16: =Table2[[#This Row],[Rare]]*$E$3*100 -> 30 | P16: =Table2[[#This Row],[Very Rare]]*$F$3*100 -> 60 | Q16: =Table2[[#This Row],[Super Rare]]*$G$3*100 -> 25 | R16: =SUM(Table3[[#This Row],[Common]:[Super Rare]]) -> 150 | S16: =B48 -> 15 | T16: =R16/S16 -> 10
B17: Medium Mummy B (Hoard) | C17: 0.05 | D17: 0.1 | E17: 0.1 | F17: 0.05 | G17: 0.1 | H17: =SUM(C17:G17) -> 0.4 | I17: =B49 -> 15 | J17: =H17/I17 -> 0.026666667 | L17: =Table2[[#This Row],[Enemy]] -> Medium Mummy B (Hoard) | M17: =Table2[[#This Row],[Common]]*$C$3*100 -> 5 | N17: =Table2[[#This Row],[Uncommon]]*$D$3*100 -> 20 | O17: =Table2[[#This Row],[Rare]]*$E$3*100 -> 30 | P17: =Table2[[#This Row],[Very Rare]]*$F$3*100 -> 20 | Q17: =Table2[[#This Row],[Super Rare]]*$G$3*100 -> 50 | R17: =SUM(Table3[[#This Row],[Common]:[Super Rare]]) -> 125 | S17: =B49 -> 15 | T17: =R17/S17 -> 8.3333333
B18: Medium Mummy C (Hoard) | C18: 0.2 | D18: 0.05 | E18: 0.05 | F18: 0.15 | G18: 0.05 | H18: =SUM(C18:G18) -> 0.5 | I18: =B50 -> 15 | J18: =H18/I18 -> 0.033333333 | L18: =Table2[[#This Row],[Enemy]] -> Medium Mummy C (Hoard) | M18: =Table2[[#This Row],[Common]]*$C$3*100 -> 20 | N18: =Table2[[#This Row],[Uncommon]]*$D$3*100 -> 10 | O18: =Table2[[#This Row],[Rare]]*$E$3*100 -> 15 | P18: =Table2[[#This Row],[Very Rare]]*$F$3*100 -> 60 | Q18: =Table2[[#This Row],[Super Rare]]*$G$3*100 -> 25 | R18: =SUM(Table3[[#This Row],[Common]:[Super Rare]]) -> 130 | S18: =B50 -> 15 | T18: =R18/S18 -> 8.6666667
B19: Scarab black (Hoard) | C19: 0.15 | D19: 0.1 | H19: =SUM(C19:G19) -> 0.25 | I19: =B51 -> 0 | J19: =H19/I19 -> #DIV/0! | L19: =Table2[[#This Row],[Enemy]] -> Scarab black (Hoard) | M19: =Table2[[#This Row],[Common]]*$C$3*100 -> 15 | N19: =Table2[[#This Row],[Uncommon]]*$D$3*100 -> 20 | O19: =Table2[[#This Row],[Rare]]*$E$3*100 -> 0 | P19: =Table2[[#This Row],[Very Rare]]*$F$3*100 -> 0 | Q19: =Table2[[#This Row],[Super Rare]]*$G$3*100 -> 0 | R19: =SUM(Table3[[#This Row],[Common]:[Super Rare]]) -> 35 | S19: =B51 -> 0 | T19: =R19/S19 -> #DIV/0!
B20: Scarab gold (Hoard) | C20: 0.2 | D20: 0.1 | E20: 0.05 | H20: =SUM(C20:G20) -> 0.35 | I20: =B52 -> 0 | J20: =H20/I20 -> #DIV/0! | L20: =Table2[[#This Row],[Enemy]] -> Scarab gold (Hoard) | M20: =Table2[[#This Row],[Common]]*$C$3*100 -> 20 | N20: =Table2[[#This Row],[Uncommon]]*$D$3*100 -> 20 | O20: =Table2[[#This Row],[Rare]]*$E$3*100 -> 15 | P20: =Table2[[#This Row],[Very Rare]]*$F$3*100 -> 0 | Q20: =Table2[[#This Row],[Super Rare]]*$G$3*100 -> 0 | R20: =SUM(Table3[[#This Row],[Common]:[Super Rare]]) -> 55 | S20: =B52 -> 0 | T20: =R20/S20 -> #DIV/0!
B21: Scarab gem covered (Hoard) | C21: 0.25 | D21: 0.1 | E21: 0.05 | F21: 0.05 | G21: 0.02 | H21: =SUM(C21:G21) -> 0.47 | I21: =B53 -> 0 | J21: =H21/I21 -> #DIV/0! | L21: =Table2[[#This Row],[Enemy]] -> Scarab gem covered (Hoard) | M21: =Table2[[#This Row],[Common]]*$C$3*100 -> 25 | N21: =Table2[[#This Row],[Uncommon]]*$D$3*100 -> 20 | O21: =Table2[[#This Row],[Rare]]*$E$3*100 -> 15 | P21: =Table2[[#This Row],[Very Rare]]*$F$3*100 -> 20 | Q21: =Table2[[#This Row],[Super Rare]]*$G$3*100 -> 10 | R21: =SUM(Table3[[#This Row],[Common]:[Super Rare]]) -> 90 | S21: =B53 -> 0 | T21: =R21/S21 -> #DIV/0!
B22: Boss | D22: 0.3 | E22: 0.3 | F22: 0.2 | G22: 0.2 | H22: =SUM(C22:G22) -> 1 | I22: =B47 -> 0 | J22: =H22/I22 -> #DIV/0! | L22: =Table2[[#This Row],[Enemy]] -> Boss | M22: =Table2[[#This Row],[Common]]*$C$3*100 -> 0 | N22: =Table2[[#This Row],[Uncommon]]*$D$3*100 -> 60 | O22: =Table2[[#This Row],[Rare]]*$E$3*100 -> 90 | P22: =Table2[[#This Row],[Very Rare]]*$F$3*100 -> 80 | Q22: =Table2[[#This Row],[Super Rare]]*$G$3*100 -> 100 | R22: =SUM(Table3[[#This Row],[Common]:[Super Rare]]) -> 330 | S22: =B47 -> 0 | T22: =R22/S22 -> #DIV/0!
B23: Boss (Hoard) | D23: 0.25 | E23: 0.3 | F23: 0.2 | G23: 0.25 | H23: =SUM(C23:G23) -> 1 | I23: =B55 -> 0 | J23: =H23/I23 -> #DIV/0! | L23: =Table2[[#This Row],[Enemy]] -> Boss (Hoard) | M23: =Table2[[#This Row],[Common]]*$C$3*100 -> 0 | N23: =Table2[[#This Row],[Uncommon]]*$D$3*100 -> 50 | O23: =Table2[[#This Row],[Rare]]*$E$3*100 -> 90 | P23: =Table2[[#This Row],[Very Rare]]*$F$3*100 -> 80 | Q23: =Table2[[#This Row],[Super Rare]]*$G$3*100 -> 125 | R23: =SUM(Table3[[#This Row],[Common]:[Super Rare]]) -> 345 | S23: =B55 -> 0 | T23: =R23/S23 -> #DIV/0!
B24: Total | C24: =SUM(C6:C23) -> 2.26 | D24: =SUM(D6:D23) -> 1.86 | E24: =SUM(E6:E23) -> 1.47 | F24: =SUM(F6:F23) -> 1.06 | G24: =SUM(G6:G23) -> 0.76 | L24: =Table2[[#This Row],[Enemy]] -> Total | M24: =SUM(M6:M23) -> 226 | N24: =SUM(N6:N23) -> 372 | O24: =SUM(O6:O23) -> 441 | P24: =SUM(P6:P23) -> 424 | Q24: =SUM(Q6:Q23) -> 380 | R24: =SUM(Table3[[#This Row],[Common]:[Super Rare]]) -> 1843 | S24: =B56 -> 0 | T24: =H24/I24 -> #DIV/0!
B25: Frequency x Value | C25: =C24*C3 -> 2.26 | D25: =D24*D3 -> 3.72 | E25: =E24*E3 -> 4.41 | F25: =F24*F3 -> 4.24 | G25: =G24*G3 -> 3.8 | L25: =Table2[[#This Row],[Enemy]] -> Frequency x Value | M25: =M24*M3 -> 226 | N25: =N24*N3 -> 744 | O25: =O24*O3 -> 1323 | P25: =P24*P3 -> 1696 | Q25: =Q24*Q3 -> 1900 | R25: =SUM(Table3[[#This Row],[Common]:[Super Rare]]) -> 5889 | S25: =B57 -> 0 | T25: =H25/I25 -> #DIV/0!
B27: Treasure Achievements
B28: Treasure achievements are available in levels
A29: Rank
A31: Award | B31: Value | I31: Probability of Points Reward Chest | L31: If prize awarded, the these are the probability for the prize sizes
A32: Treasure - Common | B32: 1
A33: Treasure - Uncommon | B33: 2 | I33: Enemy | J33: Chance of Reward Chest | K33: 20 EXP | L33: 50 EXP | M33: 80 EXP | N33: 120 EXP | O33: 180 EXP | P33: 250 EXP | Q33: 500 EXP | R33: Total chance | S33: Total Value
A34: Treasure - Rare | B34: 3
A35: Treasure - Very Rare | B35: 4 | I35: Scarab black | J35: 0.05 | K35: 60 | L35: 20 | M35: 10 | N35: 5 | O35: 5 | R35: =SUM(K35:Q35) -> 100 | S35: =(K35*20)+(L35*50)+(M35*80)+(N35*120)+(O35+180)+(P35*250)+(Q35*500) -> 3785
A36: Treasure - Super Rare | B36: 5 | C36: Group | I36: Scarab gold | J36: 0.08 | K36: 50 | L36: 20 | M36: 20 | N36: 5 | O36: 5 | R36: =SUM(K36:Q36) -> 100 | S36: =(K36*20)+(L36*50)+(M36*80)+(N36*120)+(O36+180)+(P36*250)+(Q36*500) -> 4385
A37: Scarab | B37: 1 | C37: Scarab | I37: Scarab gem covered | J37: 0.08 | K37: 45 | L37: 40 | M37: 10 | N37: 5 | R37: =SUM(K37:Q37) -> 100 | S37: =(K37*20)+(L37*50)+(M37*80)+(N37*120)+(O37+180)+(P37*250)+(Q37*500) -> 4480
A38: Scarab black | B38: 1 | C38: Scarab | I38: Standard Mummy | J38: 0.08 | K38: 70 | L38: 10 | M38: 5 | N38: 5 | O38: 5 | P38: 5 | R38: =SUM(K38:Q38) -> 100 | S38: =(K38*20)+(L38*50)+(M38*80)+(N38*120)+(O38+180)+(P38*250)+(Q38*500) -> 4335
A39: Scarab gold | B39: 2 | C39: Scarab | I39: Medium Mummy A | J39: 0.1 | K39: 40 | L39: 20 | M39: 15 | N39: 10 | O39: 10 | P39: 5 | R39: =SUM(K39:Q39) -> 100 | S39: =(K39*20)+(L39*50)+(M39*80)+(N39*120)+(O39+180)+(P39*250)+(Q39*500) -> 5640
A40: Scarab gem covered | B40: 3 | C40: Scarab | I40: Medium Mummy B | J40: 0.12 | K40: 30 | L40: 35 | M40: 20 | N40: 5 | O40: 5 | P40: 5 | R40: =SUM(K40:Q40) -> 100 | S40: =(K40*20)+(L40*50)+(M40*80)+(N40*120)+(O40+180)+(P40*250)+(Q40*500) -> 5985
A41: Standard Mummy | B41: 2 | C41: Mummy | I41: Medium Mummy C | J41: 0.12 | K41: 20 | L41: 30 | M41: 25 | N41: 10 | O41: 5 | P41: 5 | R41: =SUM(K41:Q41) -> 95 | S41: =(K41*20)+(L41*50)+(M41*80)+(N41*120)+(O41+180)+(P41*250)+(Q41*500) -> 6535
A42: Medium Mummy A | B42: 3 | C42: Mummy | I42: Powerful Pharaoh Mummy A | J42: 0.15 | L42: 40 | M42: 20 | N42: 10 | O42: 10 | P42: 5 | Q42: 5 | R42: =SUM(K42:Q42) -> 90 | S42: =(K42*20)+(L42*50)+(M42*80)+(N42*120)+(O42+180)+(P42*250)+(Q42*500) -> 8740
...

Sheet TreasureList
E2: Treasure List
E4: ID | F4: Object image | G4: Name | H4: Probability | I4: Group
E6: 1 | G6: The Golden Bust of Nefertiti | H6: Super Rare | I6: Pharaohs
E7: 2 | G7: Sacred Golden Scarab | H7: Super Rare | I7: Scarabs
E8: 3 | G8: The Golden Cartouche | H8: Super Rare | I8: Ritual Objects
E9: 4 | G9: The Jade Brooch | H9: Super Rare | I9: Rare Jewelry
E10: 5 | G10: The Golden Scribe | H10: Super Rare | I10: Ritual Objects
E11: 6 | G11: Golden Bust of Anubis | H11: Super Rare | I11: Anubis
E12: 7 | G12: Sacred Golden Pyramid | H12: Super Rare | I12: Ritual Objects
E13: 8 | G13: Garnet Scarab Amulet | H13: Super Rare | I13: Scarabs
E14: 9 | G14: Onyx Statue of the Pharaoh | H14: Super Rare | I14: Pharaohs
E15: 10 | G15: Goblet of the Griffin | H15: Super Rare | I15: Ritual Objects
E16: 11 | G16: Offering Bowl of Gems | H16: Super Rare | I16: Ritual Objects
E17: 12 | G17: Golden Statue of Tutankhamun | H17: Super Rare | I17: Pharaohs
... E59: 54 | G59: Canopic Jar of Clay | H59: Common | I59: Bowls and Jars
F62: Totals | G62: Super Rare | H62: =COUNTIF(H6:H59,"Super Rare") -> 12
G63: Very Rare | H63: =COUNTIF(H7:H60,"Very Rare") -> 11
G64: Rare | H64: =COUNTIF(H8:H61,"Rare") -> 10
G65: Uncommon | H65: =COUNTIF(H9:H62,"Uncommon") -> 11
G66: Common | H66: =COUNTIF(H10:H63,"Common") -> 10
F68: Treasure Groups | G68: Group Name | H68: number of items
G69: Statues | H69: =COUNTIF(I$6:I$59,"Statues") -> 4
G70: Bowls and Jars | H70: =COUNTIF(I$6:I$59,"Bowls and Jars") -> 4
G71: Jewely | H71: =COUNTIF(I$6:I$59,"Jewely") -> 5
G72: Rare Jewelry | H72: =COUNTIF(I$6:I$59,"Rare Jewelry") -> 6
G73: Ritual Objects | H73: =COUNTIF(I$6:I$59,"Ritual Objects") -> 7
G74: Scarabs | H74: =COUNTIF(I$6:I$59,"Scarabs") -> 7
G75: Sphynxes | H75: =COUNTIF(I$6:I$59,"Sphynxes") -> 4
G76: Anubis | H76: =COUNTIF(I$6:I$59,"Anubis") -> 4
G77: Horus | H77: =COUNTIF(I$6:I$59,"Horus") -> 6
G78: Osiris | H78: =COUNTIF(I$6:I$59,"Osiris") -> 3
G79: Pharaohs | H79: =COUNTIF(I$6:I$59,"Pharaohs") -> 3
F81: Enemy Groups | G81: Scarab | H81: 4
G82: Mummy | H82: 6
G83: Gods | H83: 3

Sheet CreatingAchievements
A6: Award Values Table
H7: Achievements Calculation Table
A8: Award | B8: RarityValue | C8: Trigger | J8: Note: The table below shows the formulas for calculating the number of items in each achievement (they will always be of the same treasure item or same enemy, never a mix). The number of enemies required is the total max treasure value, divided by the 'value' of the items (shown in the Awards Value Table, in the RarityValue column).
A9: =Probabilities!A32 -> Treasure - Common | B9: =Probabilities!B32 -> 1 | C9: Completion of achievement
A10: =Probabilities!A33 -> Treasure - Uncommon | B10: =Probabilities!B33 -> 2 | C10: Completion of achievement
A11: =Probabilities!A34 -> Treasure - Rare | B11: =Probabilities!B34 -> 3 | C11: Completion of achievement | H11: Collection | I11: Collection award formula | J11: Prize points (number required for award) | K11: item award
A12: =Probabilities!A35 -> Treasure - Very Rare | B12: =Probabilities!B35 -> 4 | C12: Completion of achievement | H12: 1 | I12: SUM(All item award) * 1.5 | J12: 5 | K12: itemRarityValue * numberCollectedSinceLastAward
A13: =Probabilities!A36 -> Treasure - Super Rare | B13: =Probabilities!B36 -> 5 | C13: Completion of achievement | H13: 2 | J13: 10
A14: =Probabilities!A37 -> Scarab | B14: =Probabilities!B37 -> 1 | C14: Having fired the shot that destroyed the enemy | H14: 3 | J14: 15
A15: =Probabilities!A38 -> Scarab black | B15: =Probabilities!B38 -> 1 | C15: Having fired the shot that destroyed the enemy | H15: 4 | J15: 25
A16: =Probabilities!A39 -> Scarab gold | B16: =Probabilities!B39 -> 2 | C16: Having fired the shot that destroyed the enemy | H16: 5 | J16: 50
A17: =Probabilities!A40 -> Scarab gem covered | B17: =Probabilities!B40 -> 3 | C17: Having fired the shot that destroyed the enemy | H17: 6 | J17: 75
A18: =Probabilities!A41 -> Standard Mummy | B18: =Probabilities!B41 -> 2 | C18: Having fired the shot that destroyed the enemy | H18: 7 | J18: 100
A19: =Probabilities!A42 -> Medium Mummy A | B19: =Probabilities!B42 -> 3 | C19: Having fired the shot that destroyed the enemy | H19: 8 | J19: LastPrizePoint+NumberofPrizePoints(variable)
A20: =Probabilities!A43 -> Medium Mummy B | B20: =Probabilities!B43 -> 4 | C20: Having fired the shot that destroyed the enemy | H20: 9
A21: =Probabilities!A44 -> Medium Mummy C | B21: =Probabilities!B44 -> 5 | C21: Having fired the shot that destroyed the enemy | H21: 10
A22: =Probabilities!A45 -> Powerful Pharaoh Mummy A | B22: =Probabilities!B45 -> 8 | C22: Having fired the shot that destroyed the enemy | H22: 11
A23: =Probabilities!A46 -> Powerful Pharaoh Mummy B | B23: =Probabilities!B46 -> 8 | C23: Having fired the shot that destroyed the enemy | H23: 12
H24: 13
A25: =Probabilities!A48 -> Osiris | B25: =Probabilities!B48 -> 15 | C25: Having fired the shot that destroyed the enemy | H25: 14
A26: =Probabilities!A49 -> Anubis | B26: =Probabilities!B49 -> 15 | C26: Having fired the shot that destroyed the enemy | H26: 15
A27: =Probabilities!A50 -> Horus | B27: =Probabilities!B50 -> 15 | C27: Having fired the shot that destroyed the enemy | H27: 16
A28: =Probabilities!A51 -> 0 | B28: =Probabilities!B51 -> 0 | C28: Having fired the shot that destroyed the enemy | H28: 17
A29: =Probabilities!A52 -> 0 | B29: =Probabilities!B52 -> 0 | C29: Having fired the shot that destroyed the enemy | H29: 18
A30: =Probabilities!A53 -> 0 | B30: =Probabilities!B53 -> 0 | C30: Having fired the shot that destroyed the enemy | H30: 19
A31: =Probabilities!A47 -> Boss | B31: =Probabilities!B47 -> 0 | C31: Having fired the shot that destroyed the enemy | H31: 20
A32: =Probabilities!A55 -> 0 | B32: =Probabilities!B55 -> 0 | C32: Having fired the shot that destroyed the enemy

Sheet Players Score
C2: Level Up Rewards
C4: Rank | D4: Number of levels | E4: Level up award | F4: Rank Up award
C5: Apprentice | D5: 5 | E5: 3
C6: Journeyman | D6: 10 | E6: 4 | F6: 20
C7: Traveler | D7: 20 | E7: 5 | F7: 50
C8: Explorer | D8: 40 | E8: 7 | F8: 100
C9: Adventurer | D9: 70 | E9: 9 | F9: 200
C10: Ace | D10: 100 | E10: 12 | F10: 300
C11: Leader | D11: 150 | E11: 15 | F11: 400
C12: Hero | D12: 200 | E12: 20 | F12: 500
C13: Legend | D13: Infinite | E13: 25 | F13: 1000
H15: All Contributions to players score
C16: Enemy Destroyed Rewards | E16: Collection Group
C17: Scarab black | D17: 1 | E17: Scarab | H17: Event | I17: Contribution to score
C18: Scarab gold | D18: 2 | E18: Scarab | H18: Level Up | I18: Level Up Rewards Table
C19: Scarab gem covered | D19: 3 | E19: Scarab | H19: Enemy Destroyed | I19: Enemy Destroyed Rewards Table
C20: Standard Mummy | D20: 2 | E20: Mummy | H20: Achievements | I20: Achievements Calculation Table
C21: Medium Mummy A | D21: 3 | E21: Mummy | H21: Bonus Weapon collected | I21: 5
C22: Medium Mummy B | D22: 4 | E22: Mummy | H22: Collecting any item | I22: 1
C23: Medium Mummy C | D23: 5 | E23: Mummy | I23: 1
C24: Powerful Pharaoh Mummy A | D24: 8 | E24: Mummy | H24: Hitting any enemy
C25: Powerful Pharaoh Mummy B | D25: 8 | E25: Mummy | H25: Reward Chest | I25: Probability of Points Reward Chest
C26: Standard Mummy (Hoard) | D26: 4 | E26: same as standard version
C27: Medium Mummy A (Hoard) | D27: 6 | E27: same as standard version
C28: Medium Mummy B (Hoard) | D28: 8 | E28: same as standard version
C29: Medium Mummy C (Hoard) | D29: 8 | E29: same as standard version
C30: Scarab black (Hoard) | D30: 2 | E30: same as standard version
C31: Scarab gold (Hoard) | D31: 4 | E31: same as standard version
C32: Scarab gem covered (Hoard) | D32: 6 | E32: same as standard version
C33: Boss
C34: Anubis | D34: 15
C35: Osiris | D35: 15
C36: Horus | D36: 15
C37: Boss (Hoard) | D37: 20 | E37: same as standard version
