Workbook

Sheet Summary
A1: Notes: the number of enemies of each type in each location is irrelevant from the mathematical point of view.
A2: If locations act as "levels", it may be interesting to have weak enemies in the first location and add other species in the following locations.
A5: Feature | B5: RTP | C5: Freq | D5: Probability | E5: Max avg pay | F5: Max avg pay | G5: Min RTP
A6: Base game | B6: 0.6 | G6: 0.6
A7: Boss round | B7: 0.24 | C7: 200 | D7: =1/C7 -> 0.005 | E7: =+C7*B7 -> 48 | F7: 48 | G7: 0.24 | H7: Prize: 48x to be distributed between players according to total bet during triggering round
A8: Special weapon (*) | B8: =1/C8*E8 -> 0.1 | C8: 60 | D8: =1/C8 -> 0.016666667 | E8: =+'Special weapon'!D23 -> 6 | F8: =+'Special weapon'!D50 -> 3.8163043 | G8: =1/C8*F8 -> 0.063605072
A9: Leaderboard | B9: 0.02 | G9: 0.02
A10: Jackpot | B10: 0 | G10: 0
A11: Total | B11: =+SUM(B6:B10) -> 0.96 | G11: =+SUM(G6:G10) -> 0.92360507
A12: (*) To use in MAIN only. Shots using special weapons are not paid. Each special weapon has a limited number of shots and could be used any time in base game.
A13: When a player gets a GUARANTEE KNOCKOUT he/she can use it only in base game and optimal strategy is to kill a Powerful Pharaoh Mummy with no damage or a HV enemy. The prize is x15 (see table below)
A14: If player uses the special weapon in other case (imperfect play) then he/she will get a prize lower than x15.
A16: There are different kind of enemies. Each enemy has its own prizes. Stronger enemies grant bigger prizes but are more difficult to kill.
A19: Scarab black | D19: Scarab gold | G19: Scarab gem covered
A20: Prize # | B20: Pays | D20: Prize # | E20: Pays | G20: Prize # | H20: Pays
A21: 1 | B21: 2 | D21: 1 | E21: 5 | G21: 1 | H21: 8
A25: Standard Mummy | D25: Medium Mummy A | G25: Medium Mummy B | J25: Medium Mummy C
A26: Prize | B26: Pays | D26: Prize # | E26: Pays | G26: Prize # | H26: Pays | J26: Prize # | K26: Pays
A27: 1 | B27: 3 | D27: 2 | E27: 5 | G27: 1 | H27: 5 | J27: 1 | K27: 8
A28: 2 | B28: 5 | D28: 3 | E28: 10 | G28: 2 | H28: 10 | J28: 2 | K28: 12
A29: Total | B29: =+SUM(B27:B28) -> 8 | D29: Total | E29: =+SUM(E27:E28) -> 15 | G29: 3 | H29: 15 | J29: 3 | K29: 18
G30: Total | H30: =+SUM(H27:H29) -> 30 | J30: Total | K30: =+SUM(K27:K29) -> 38
A34: Powerful Pharaoh Mummy A | D34: Powerful Pharaoh Mummy B | G34: High Volatility enemy
A35: Prize # | B35: Pays | D35: Prize # | E35: Pays | G35: Prize # | H35: Pays
A36: 1 | B36: 12 | D36: 1 | E36: 12 | G36: 1 | H36: 2
A37: 2 | B37: 15 | D37: 2 | E37: 15 | G37: 2 | H37: 5
A38: 3 | B38: 20 | D38: 3 | E38: 20 | G38: 3 | H38: 10
A39: Total | B39: =+SUM(B36:B38) -> 47 | D39: Total | E39: =+SUM(E36:E38) -> 47 | G39: 4 | H39: 20
G40: 5 | H40: 50
G41: 6 | H41: 100
G42: 7 | H42: 500

Sheet Boss round
A1: Environmental Boss round
A2: As each shot to boss is a bet, the RTP for this bet should be the same as base game (94%) to avoid player's strategies.
A3: But players are also competing by the Boss prize (48x) which will be distributed according to damage done by each player (or bot).
A4: So, each shot can grant an extra prize (Table 1) and cause a damage. The RTP of these shots will be 94% plus the RTP from Boss prize.
A5: Extra prizes can be inmediately granted to players or they can be accumulate and granted at the end of the round added to the part of the Boss prize.
A6: For each shot, draw an extra prize (Table 1) and boss damage (Table 2 and 3 corrected by player's bet). They are independent events.
A8: Extra prize
A10: Table 1 | B10: Prize | C10: Probability | D10: Cumulative prob. | E10: RTP
B11: 5 | C11: 0.07 | D11: =+SUM(C$10:$C11) -> 0.07 | E11: =+B11*C11 -> 0.35
B12: 10 | C12: 0.009 | D12: =+SUM(C$10:$C12) -> 0.079 | E12: =+B12*C12 -> 0.09
B13: 15 | C13: 0.01 | D13: =+SUM(C$10:$C13) -> 0.089 | E13: =+B13*C13 -> 0.15
B14: 20 | C14: 0.01 | D14: =+SUM(C$10:$C14) -> 0.099 | E14: =+B14*C14 -> 0.2
B15: 50 | C15: 0.001 | D15: =+SUM(C$10:$C15) -> 0.1 | E15: =+B15*C15 -> 0.05
B16: 100 | C16: 0.001 | D16: =+SUM(C$10:$C16) -> 0.101 | E16: =+B16*C16 -> 0.1
B17: Total (*) | C17: =+SUM(C11:C16) -> 0.101 | E17: =+SUM(E11:E16) -> 0.94
A20: Boss damage
A22: Boss energy: | B22: =+Summary!E7 -> 48
A23: The total Boss prize must return to players. The part of this prize won by bots will be added to Leaderboard prizes.
A24: Each energy unit represents 1 credit. If player A has caused a damage of 15 energy units then player wins a prize of 15 credits plus the extra prizes.
A25: Players who have bet the most are likely to win the most. So, probabilities are proportional to player's total bet in the base game previous to Boss round.
A26: For each player the probabilities in the table below must be multiplied by player's total bet in base game previous to Boss round and divided by total bet in base game previous to Boss round.
A27: Probability factor correction (PFC): player's bet divided by total bet
A29: Table 2 | B29: Damage | C29: Probability Base line | D29: RTP
B30: 1 | C30: 0.01 | D30: =+B30*C30 -> 0.01
B31: 2 | C31: 0.01 | D31: =+B31*C31 -> 0.02
B32: 3 | C32: 0.01 | D32: =+B32*C32 -> 0.03
B33: 4 | C33: 0.01 | D33: =+B33*C33 -> 0.04
B34: 5 | C34: 0.01 | D34: =+B34*C34 -> 0.05
B35: Total | C35: =+SUM(C30:C34) -> 0.05 | D35: =+SUM(D30:D34) -> 0.15 | E35: <- this RTP is distributed between players
A37: When Boss energy is less than 5 some damage levels are not possible, in that case each player can only cause a damage of 1 unit with this probability:
A39: Table 3 | B39: Damage | C39: Probability Base line | D39: RTP
B40: 1 | C40: 0.15 | D40: =+C40*B40 -> 0.15
B41: Total | C41: =+SUM(C40) -> 0.15 | D41: =+D40 -> 0.15
A43: Example:
A44: Player 1 has bet 25 credits in base game.
A45: Player 2 has bet 50 credits in base game.
A46: Total bet: 25+50 = 75
A48: If Boss energy is at least 5 units the probabilities of damages are:
B50: Player 1 | C50: PFC= 25/75
B51: Damage | C51: Probability Base line | D51: PFC | E51: Player's probabilities | F51: RTP
...

Sheet Special weapon
A1: For each shot in base game with a regular weapon draw if player gets a special weapon or not. Except shots at High Volatility Enemy.
A2: Probability of getting a special weapon = 1/60
A3: If player gets a special weapon then draw which one he gets using the weights in the table below.
A6: Special weapons: | B6: Shots | C6: Avg pay by shot | D6: Total avg pay | E6: Weights
A7: Special weapon 1 | B7: 4 | C7: 1.2 | D7: =+B7*C7 -> 4.8 | E7: 350
A8: Special weapon 2 | B8: 5 | C8: 1.05 | D8: =+B8*C8 -> 5.25 | E8: 240
A9: Special weapon 3 | B9: 10 | C9: 0.9 | D9: =+B9*C9 -> 9 | E9: 200
A10: Guarantee knockout (*) | B10: 0 | C10: 15 | D10: =+B10*C10 -> 0 | E10: 0 | F10: (*) if there is not any Powerful Pharaoh Mummy in location we can discard this one to make it simpler.
F11: Otherwise, the best strategy would be to keep this weapon and use it in another location to kill a Powerful Pharaoh Mummy.
C12: Avg win | D12: =+SUMPRODUCT(D7:D9,E7:E9)/SUM(E7:E9) -> 6
A15: Special weapons can be use anytime in base game only.
A17: Special weapons: | B17: Shots | C17: Avg pay by shot | D17: Total avg pay | E17: Weights
A18: Special weapon 1 | B18: 4 | C18: 1.2 | D18: =+B18*C18 -> 4.8 | E18: 20
A19: Special weapon 2 | B19: 5 | C19: 1.05 | D19: =+B19*C19 -> 5.25 | E19: 16
A20: Special weapon 3 | B20: 10 | C20: 0.9 | D20: =+B20*C20 -> 9 | E20: 9
A21: Guarantee knockout (*) | B21: 1 | C21: 15 | D21: =+B21*C21 -> 15 | E21: 1 | F21: Skill: best strategy is to use it with a Powerful Pharaoh Mummy with no damage
A22: (*) avg pay using best strategy
C23: Avg win | D23: =+SUMPRODUCT(D18:D21,E18:E21)/SUM(E18:E21) -> 6
A25: Each special weapon has its own probabilities of damage for each kind of enemy. Prizes must be multiplied by the stake that triggered the feature.
A26: For instance, if player gets a special weapon betting 100 credits, at the moment he decides to use it the prizes must be multiplied by 100. It doesn’t matter if after getting the special weapon he changed the stake.
A29: Special weapons description
A30: Special weapon 1: double barrelled shotgun
A32: Special weapon 2: 1 bomb hitting 5 times.
A33: When the bomb is thrown hit the nearest enemy (i.e. draw the damage according to tables for special weapon 2), if that enemy is not defeated then hit him one more time, else hit the following nearest enemy. Repeat 3 more times (total: 5 "shots").
A34: Algorithmically is a sequential process but graphically it is shown as everything ocurring at the same moment.
A35: Alternative: when the bomb is thrown hit the 5 nearest enemies (i.e. draw the damage according to tables for special weapon 2 once for each enemy).
A37: Special weapon 3: every time a player gets special weapon 3 choose at random between a Chain gun or Ricochet.
A38: Chain Gun: 10 shots but each shot can be shown as a burst of several bullets. For example, each shot can be replaced by one burst of 10 bullets and this corresponds to only one draw using the probabilities of the tables.
A39: Ricochet: 5 shots but each shot bounces hitting a second enemy. The second enemy is chosen at random and it is not necessary the same kind of enemy that the player aimed.
A42: Worst strategy
A43: Special weapons: | B43: Shots | C43: Avg pay by shot | D43: Total avg pay | E43: Probability
A44: Special weapon 1 | B44: 4 | C44: 1.2 | D44: =+B44*C44 -> 4.8 | E44: =+E18/SUM($E$18:$E$21) -> 0.43478261
A45: Special weapon 2 | B45: 1 | C45: 1.05 | D45: =+B45*C45 -> 1.05 | E45: =+E19/SUM($E$18:$E$21) -> 0.34782609 | F45: (*) worst strategy is to shoot when there is only one enemy on screen. In this case 4 shots are wasted.
A46: Special weapon 3 (Chain gun) | B46: 10 | C46: 0.9 | D46: =+B46*C46 -> 9 | E46: =+E20/SUM($E$18:$E$21)*1/2 -> 0.097826087
A47: Special weapon 3 (Ricochet) (**) | B47: 5 | C47: 0.9 | D47: =+B47*C47 -> 4.5 | E47: =+E20/SUM($E$18:$E$21)*1/2 -> 0.097826087 | F47: (**) worst strategy is to shoot when there is only one enemy on screen. In this case every shot wastes the bounce shot.
A48: Guarantee knockout (***) | B48: 1 | C48: 2 | D48: =+B48*C48 -> 2 | E48: =+E21/SUM($E$18:$E$21) -> 0.02173913 | F48: (***) worst strategy is to use it agains an enemy paying only x2 (for example an scarab).
C50: Avg win | D50: =+SUMPRODUCT(D44:D48,E44:E48) -> 3.8163043

Sheet Prices Special weapon
A1: Player can buy special any special weapons, the price for each weapon is the table below.
A2: Special weapons can be use anytime in base game only.
A4: Crate price (credits) | B4: 20
A7: Crate content (random):
A9: Special weapons: | B9: Shots | C9: Avg pay by shot | D9: Total avg pay | E9: Weight | F9: Avg pay/price
A10: Special weapon 1 | B10: 8 | C10: 1.2 | D10: =+B10*C10 -> 9.6 | E10: 9 | F10: =+D10/$B$4 -> 0.48
A11: Special weapon 1 | B11: 12 | C11: 1.2 | D11: =+B11*C11 -> 14.4 | E11: 16 | F11: =+D11/$B$4 -> 0.72
A12: Special weapon 1 | B12: 16 | C12: 1.2 | D12: =+B12*C12 -> 19.2 | E12: 8 | F12: =+D12/$B$4 -> 0.96
A13: Special weapon 1 | B13: 20 | C13: 1.2 | D13: =+B13*C13 -> 24 | E13: 10 | F13: =+D13/$B$4 -> 1.2
A14: Special weapon 1 | B14: 80 | C14: 1.2 | D14: =+B14*C14 -> 96 | E14: 1 | F14: =+D14/$B$4 -> 4.8
A15: Special weapon 2 | B15: 10 | C15: 1.05 | D15: =+B15*C15 -> 10.5 | E15: 20 | F15: =+D15/$B$4 -> 0.525
A16: Special weapon 2 | B16: 15 | C16: 1.05 | D16: =+B16*C16 -> 15.75 | E16: 17 | F16: =+D16/$B$4 -> 0.7875
A17: Special weapon 2 | B17: 50 | C17: 1.05 | D17: =+B17*C17 -> 52.5 | E17: 2 | F17: =+D17/$B$4 -> 2.625
A18: Special weapon 3 | B18: 20 | C18: 0.9 | D18: =+B18*C18 -> 18 | E18: 10 | F18: =+D18/$B$4 -> 0.9
A19: Special weapon 3 | B19: 30 | C19: 0.9 | D19: =+B19*C19 -> 27 | E19: 5 | F19: =+D19/$B$4 -> 1.35
A20: Special weapon 3 | B20: 50 | C20: 0.9 | D20: =+B20*C20 -> 45 | E20: 1 | F20: =+D20/$B$4 -> 2.25
A21: Special weapon 3 | B21: 200 | C21: 0.9 | D21: =+B21*C21 -> 180 | E21: 1 | F21: =+D21/$B$4 -> 9
A22: Total | D22: =+SUMPRODUCT(D10:D21,E10:E21)/SUM(E10:E21) -> 19.2915 | E22: =+SUM(E10:E21) -> 100
A24: Total RTP: | B24: =+D22/B4 -> 0.964575
A26: In case of including Guranteed knockout in game please use the table below.
A27: Crate content including Guaranteed knockout (random):
A29: Special weapons: | B29: Shots | C29: Avg pay by shot | D29: Total avg pay | E29: Weight | F29: Avg pay/price
A30: Special weapon 1 | B30: 8 | C30: 1.2 | D30: =+B30*C30 -> 9.6 | E30: 10 | F30: =+D30/$B$4 -> 0.48
A31: Special weapon 1 | B31: 12 | C31: 1.2 | D31: =+B31*C31 -> 14.4 | E31: 21 | F31: =+D31/$B$4 -> 0.72
A32: Special weapon 1 | B32: 16 | C32: 1.2 | D32: =+B32*C32 -> 19.2 | E32: 9 | F32: =+D32/$B$4 -> 0.96
A33: Special weapon 1 | B33: 20 | C33: 1.2 | D33: =+B33*C33 -> 24 | E33: 10 | F33: =+D33/$B$4 -> 1.2
A34: Special weapon 1 | B34: 80 | C34: 1.2 | D34: =+B34*C34 -> 96 | E34: 1 | F34: =+D34/$B$4 -> 4.8
A35: Special weapon 2 | B35: 10 | C35: 1.05 | D35: =+B35*C35 -> 10.5 | E35: 25 | F35: =+D35/$B$4 -> 0.525
A36: Special weapon 2 | B36: 15 | C36: 1.05 | D36: =+B36*C36 -> 15.75 | E36: 17 | F36: =+D36/$B$4 -> 0.7875
A37: Special weapon 2 | B37: 50 | C37: 1.05 | D37: =+B37*C37 -> 52.5 | E37: 1 | F37: =+D37/$B$4 -> 2.625
A38: Special weapon 3 | B38: 20 | C38: 0.9 | D38: =+B38*C38 -> 18 | E38: 15 | F38: =+D38/$B$4 -> 0.9
A39: Special weapon 3 | B39: 30 | C39: 0.9 | D39: =+B39*C39 -> 27 | E39: 4 | F39: =+D39/$B$4 -> 1.35
A40: Special weapon 3 | B40: 50 | C40: 0.9 | D40: =+B40*C40 -> 45 | E40: 1 | F40: =+D40/$B$4 -> 2.25
A41: Special weapon 3 | B41: 200 | C41: 0.9 | D41: =+B41*C41 -> 180 | E41: 1 | F41: =+D41/$B$4 -> 9
... A44: Guaranteed knockout | B44: 5 | C44: 15 | D44: =+B44*C44 -> 75 | E44: 1 | F44: =+D44/$B$4 -> 3.75
A45: Total | D45: =+SUMPRODUCT(D30:D44,E30:E44)/SUM(E30:E44) -> 19.31625 | E45: =+SUM(E30:E44) -> 120
A47: Total RTP: | B47: =+D45/B4 -> 0.9658125

Sheet Base game (HV enemy)
A1: HIGH-Volatility Enemy (Jackpot)
A2: For each shot with a regular weapon, draw the damage caused using the tables below.
A3: Start using table 1 and every 100 shots received change to the following table.
A4: Note: The probability of defeating the enemy increases from one table to next table (the enemy gets weaker every 100 shots received)
A8: Table 1 | B8: Prize # | C8: Probability | D8: Cumulative prob. | E8: Award | F8: RTP
B9: 1 | C9: 0.05 | D9: =+SUM($C$9:C9) -> 0.05 | E9: =+Summary!H36 -> 2 | F9: =+C9*E9 -> 0.1
B10: 2 | C10: 0.03 | D10: =+SUM($C$9:C10) -> 0.08 | E10: =+Summary!H37 -> 5 | F10: =+C10*E10 -> 0.15
B11: 3 | C11: 0.009 | D11: =+SUM($C$9:C11) -> 0.089 | E11: =+Summary!H38 -> 10 | F11: =+C11*E11 -> 0.09
B12: 4 | C12: 0.005 | D12: =+SUM($C$9:C12) -> 0.094 | E12: =+Summary!H39 -> 20 | F12: =+C12*E12 -> 0.1
B13: 5 | C13: 0.003 | D13: =+SUM($C$9:C13) -> 0.097 | E13: =+Summary!H40 -> 50 | F13: =+C13*E13 -> 0.15
B14: 6 | C14: 0.001 | D14: =+SUM($C$9:C14) -> 0.098 | E14: =+Summary!H41 -> 100 | F14: =+C14*E14 -> 0.1
B15: 7 | C15: 0.0005 | D15: =+SUM($C$9:C15) -> 0.0985 | E15: =+Summary!H42 -> 500 | F15: =+C15*E15 -> 0.25 | G15: (*) Enemy killed
B16: Total (*) | C16: =+SUM(C9:C15) -> 0.0985 | F16: =+SUM(F9:F15) -> 0.94
B17: (*) Total probability is hit rate
A20: Table 2 | B20: Prize # | C20: Probability | D20: Cumulative prob. | E20: Award | F20: RTP
B21: 1 | C21: 0.05 | D21: =+SUM($C$21:C21) -> 0.05 | E21: =+Summary!H36 -> 2 | F21: =+C21*E21 -> 0.1
B22: 2 | C22: 0.033 | D22: =+SUM($C$21:C22) -> 0.083 | E22: =+Summary!H37 -> 5 | F22: =+C22*E22 -> 0.165
B23: 3 | C23: 0.005 | D23: =+SUM($C$21:C23) -> 0.088 | E23: =+Summary!H38 -> 10 | F23: =+C23*E23 -> 0.05
B24: 4 | C24: 0.005 | D24: =+SUM($C$21:C24) -> 0.093 | E24: =+Summary!H39 -> 20 | F24: =+C24*E24 -> 0.1
B25: 5 | C25: 0.0025 | D25: =+SUM($C$21:C25) -> 0.0955 | E25: =+Summary!H40 -> 50 | F25: =+C25*E25 -> 0.125
B26: 6 | C26: 0.001 | D26: =+SUM($C$21:C26) -> 0.0965 | E26: =+Summary!H41 -> 100 | F26: =+C26*E26 -> 0.1
B27: 7 | C27: 0.0006 | D27: =+SUM($C$21:C27) -> 0.0971 | E27: =+Summary!H42 -> 500 | F27: =+C27*E27 -> 0.3 | G27: (*) Enemy killed
B28: Total (*) | C28: =+SUM(C21:C27) -> 0.0971 | F28: =+SUM(F21:F27) -> 0.94
B29: (*) Total probability is hit rate
A32: Table 3 | B32: Prize # | C32: Probability | D32: Cumulative prob. | E32: Award | F32: RTP
B33: 1 | C33: 0.05 | D33: =+SUM($C$33:C33) -> 0.05 | E33: =+Summary!H36 -> 2 | F33: =+C33*E33 -> 0.1
B34: 2 | C34: 0.03 | D34: =+SUM($C$33:C34) -> 0.08 | E34: =+Summary!H37 -> 5 | F34: =+C34*E34 -> 0.15
B35: 3 | C35: 0.006 | D35: =+SUM($C$33:C35) -> 0.086 | E35: =+Summary!H38 -> 10 | F35: =+C35*E35 -> 0.06
B36: 4 | C36: 0.004 | D36: =+SUM($C$33:C36) -> 0.09 | E36: =+Summary!H39 -> 20 | F36: =+C36*E36 -> 0.08
B37: 5 | C37: 0.001 | D37: =+SUM($C$33:C37) -> 0.091 | E37: =+Summary!H40 -> 50 | F37: =+C37*E37 -> 0.05
B38: 6 | C38: 0.0005 | D38: =+SUM($C$33:C38) -> 0.0915 | E38: =+Summary!H41 -> 100 | F38: =+C38*E38 -> 0.05
B39: 7 | C39: 0.0009 | D39: =+SUM($C$33:C39) -> 0.0924 | E39: =+Summary!H42 -> 500 | F39: =+C39*E39 -> 0.45 | G39: (*) Enemy killed
B40: Total (*) | C40: =+SUM(C33:C39) -> 0.0924 | F40: =+SUM(F33:F39) -> 0.94
B41: (*) Total probability is hit rate
A44: Table 4 | B44: Prize # | C44: Probability | D44: Cumulative prob. | E44: Award | F44: RTP
B45: 1 | C45: 0.03 | D45: =+SUM($C$45:C45) -> 0.03 | E45: =+Summary!H36 -> 2 | F45: =+C45*E45 -> 0.06
B46: 2 | C46: 0.03 | D46: =+SUM($C$45:C46) -> 0.06 | E46: =+Summary!H37 -> 5 | F46: =+C46*E46 -> 0.15
B47: 3 | C47: 0.005 | D47: =+SUM($C$45:C47) -> 0.065 | E47: =+Summary!H38 -> 10 | F47: =+C47*E47 -> 0.05
B48: 4 | C48: 0.004 | D48: =+SUM($C$45:C48) -> 0.069 | E48: =+Summary!H39 -> 20 | F48: =+C48*E48 -> 0.08
B49: 5 | C49: 0.001 | D49: =+SUM($C$45:C49) -> 0.07 | E49: =+Summary!H40 -> 50 | F49: =+C49*E49 -> 0.05
...

Sheet Special weapon 1 (HV enemy)
A1: SPECIAL WEAPON 1 - High Volatility Enemy
A2: For each shot with a regular weapon, draw the damage caused using the tables below.
A3: Start using table 1 and every 100 shots received change to the following table.
A4: Note: The probability of defeating the enemy increases from one table to next table (the enemy gets weaker every 100 shots received)
A8: Table 1 | B8: Prize # | C8: Probability | D8: Cumulative prob. | E8: Award | F8: Avg payout
B9: 1 | C9: 0.1 | D9: =+SUM($C$9:C9) -> 0.1 | E9: =+Summary!H36 -> 2 | F9: =+C9*E9 -> 0.2
B10: 2 | C10: 0.05 | D10: =+SUM($C$9:C10) -> 0.15 | E10: =+Summary!H37 -> 5 | F10: =+C10*E10 -> 0.25
B11: 3 | C11: 0.01 | D11: =+SUM($C$9:C11) -> 0.16 | E11: =+Summary!H38 -> 10 | F11: =+C11*E11 -> 0.1
B12: 4 | C12: 0.005 | D12: =+SUM($C$9:C12) -> 0.165 | E12: =+Summary!H39 -> 20 | F12: =+C12*E12 -> 0.1
B13: 5 | C13: 0.003 | D13: =+SUM($C$9:C13) -> 0.168 | E13: =+Summary!H40 -> 50 | F13: =+C13*E13 -> 0.15
B14: 6 | C14: 0.001 | D14: =+SUM($C$9:C14) -> 0.169 | E14: =+Summary!H41 -> 100 | F14: =+C14*E14 -> 0.1
B15: 7 | C15: 0.0006 | D15: =+SUM($C$9:C15) -> 0.1696 | E15: =+Summary!H42 -> 500 | F15: =+C15*E15 -> 0.3 | G15: (*) Enemy killed
B16: Total (*) | C16: =+SUM(C9:C15) -> 0.1696 | F16: =+SUM(F9:F15) -> 1.2
B17: (*) Total probability is hit rate
A20: Table 2 | B20: Prize # | C20: Probability | D20: Cumulative prob. | E20: Award | F20: Avg payout
B21: 1 | C21: 0.1 | D21: =+SUM($C$21:C21) -> 0.1 | E21: =+Summary!H36 -> 2 | F21: =+C21*E21 -> 0.2
B22: 2 | C22: 0.04 | D22: =+SUM($C$21:C22) -> 0.14 | E22: =+Summary!H37 -> 5 | F22: =+C22*E22 -> 0.2
B23: 3 | C23: 0.01 | D23: =+SUM($C$21:C23) -> 0.15 | E23: =+Summary!H38 -> 10 | F23: =+C23*E23 -> 0.1
B24: 4 | C24: 0.005 | D24: =+SUM($C$21:C24) -> 0.155 | E24: =+Summary!H39 -> 20 | F24: =+C24*E24 -> 0.1
B25: 5 | C25: 0.002 | D25: =+SUM($C$21:C25) -> 0.157 | E25: =+Summary!H40 -> 50 | F25: =+C25*E25 -> 0.1
B26: 6 | C26: 0.001 | D26: =+SUM($C$21:C26) -> 0.158 | E26: =+Summary!H41 -> 100 | F26: =+C26*E26 -> 0.1
B27: 7 | C27: 0.0008 | D27: =+SUM($C$21:C27) -> 0.1588 | E27: =+Summary!H42 -> 500 | F27: =+C27*E27 -> 0.4 | G27: (*) Enemy killed
B28: Total (*) | C28: =+SUM(C21:C27) -> 0.1588 | F28: =+SUM(F21:F27) -> 1.2
B29: (*) Total probability is hit rate
A32: Table 3 | B32: Prize # | C32: Probability | D32: Cumulative prob. | E32: Award | F32: Avg payout
B33: 1 | C33: 0.1 | D33: =+SUM($C$33:C33) -> 0.1 | E33: =+Summary!H36 -> 2 | F33: =+C33*E33 -> 0.2
B34: 2 | C34: 0.03 | D34: =+SUM($C$33:C34) -> 0.13 | E34: =+Summary!H37 -> 5 | F34: =+C34*E34 -> 0.15
B35: 3 | C35: 0.01 | D35: =+SUM($C$33:C35) -> 0.14 | E35: =+Summary!H38 -> 10 | F35: =+C35*E35 -> 0.1
B36: 4 | C36: 0.005 | D36: =+SUM($C$33:C36) -> 0.145 | E36: =+Summary!H39 -> 20 | F36: =+C36*E36 -> 0.1
B37: 5 | C37: 0.002 | D37: =+SUM($C$33:C37) -> 0.147 | E37: =+Summary!H40 -> 50 | F37: =+C37*E37 -> 0.1
B38: 6 | C38: 0.001 | D38: =+SUM($C$33:C38) -> 0.148 | E38: =+Summary!H41 -> 100 | F38: =+C38*E38 -> 0.1
B39: 7 | C39: 0.0009 | D39: =+SUM($C$33:C39) -> 0.1489 | E39: =+Summary!H42 -> 500 | F39: =+C39*E39 -> 0.45 | G39: (*) Enemy killed
B40: Total (*) | C40: =+SUM(C33:C39) -> 0.1489 | F40: =+SUM(F33:F39) -> 1.2
B41: (*) Total probability is hit rate
A44: Table 4 | B44: Prize # | C44: Probability | D44: Cumulative prob. | E44: Award | F44: Avg payout
B45: 1 | C45: 0.1 | D45: =+SUM($C$45:C45) -> 0.1 | E45: =+Summary!H36 -> 2 | F45: =+C45*E45 -> 0.2
B46: 2 | C46: 0.02 | D46: =+SUM($C$45:C46) -> 0.12 | E46: =+Summary!H37 -> 5 | F46: =+C46*E46 -> 0.1
B47: 3 | C47: 0.01 | D47: =+SUM($C$45:C47) -> 0.13 | E47: =+Summary!H38 -> 10 | F47: =+C47*E47 -> 0.1
B48: 4 | C48: 0.005 | D48: =+SUM($C$45:C48) -> 0.135 | E48: =+Summary!H39 -> 20 | F48: =+C48*E48 -> 0.1
B49: 5 | C49: 0.002 | D49: =+SUM($C$45:C49) -> 0.137 | E49: =+Summary!H40 -> 50 | F49: =+C49*E49 -> 0.1
...

Sheet Special weapon 2 (HV enemy)
A1: SPECIAL WEAPON 2 - High Volatility Enemy
A2: For each shot with a regular weapon, draw the damage caused using the tables below.
A3: Start using table 1 and every 100 shots received change to the following table.
A4: Note: The probability of defeating the enemy increases from one table to next table (the enemy gets weaker every 100 shots received)
A8: Table 1 | B8: Prize # | C8: Probability | D8: Cumulative prob. | E8: Award | F8: Avg payout
B9: 1 | C9: 0.08 | D9: =+SUM($C$9:C9) -> 0.08 | E9: =+Summary!H36 -> 2 | F9: =+C9*E9 -> 0.16
B10: 2 | C10: 0.03 | D10: =+SUM($C$9:C10) -> 0.11 | E10: =+Summary!H37 -> 5 | F10: =+C10*E10 -> 0.15
B11: 3 | C11: 0.009 | D11: =+SUM($C$9:C11) -> 0.119 | E11: =+Summary!H38 -> 10 | F11: =+C11*E11 -> 0.09
B12: 4 | C12: 0.005 | D12: =+SUM($C$9:C12) -> 0.124 | E12: =+Summary!H39 -> 20 | F12: =+C12*E12 -> 0.1
B13: 5 | C13: 0.003 | D13: =+SUM($C$9:C13) -> 0.127 | E13: =+Summary!H40 -> 50 | F13: =+C13*E13 -> 0.15
B14: 6 | C14: 0.001 | D14: =+SUM($C$9:C14) -> 0.128 | E14: =+Summary!H41 -> 100 | F14: =+C14*E14 -> 0.1
B15: 7 | C15: 0.0006 | D15: =+SUM($C$9:C15) -> 0.1286 | E15: =+Summary!H42 -> 500 | F15: =+C15*E15 -> 0.3 | G15: (*) Enemy killed
B16: Total (*) | C16: =+SUM(C9:C15) -> 0.1286 | F16: =+SUM(F9:F15) -> 1.05
B17: (*) Total probability is hit rate
A20: Table 2 | B20: Prize # | C20: Probability | D20: Cumulative prob. | E20: Award | F20: Avg payout
B21: 1 | C21: 0.08 | D21: =+SUM($C$21:C21) -> 0.08 | E21: =+Summary!H36 -> 2 | F21: =+C21*E21 -> 0.16
B22: 2 | C22: 0.02 | D22: =+SUM($C$21:C22) -> 0.1 | E22: =+Summary!H37 -> 5 | F22: =+C22*E22 -> 0.1
B23: 3 | C23: 0.009 | D23: =+SUM($C$21:C23) -> 0.109 | E23: =+Summary!H38 -> 10 | F23: =+C23*E23 -> 0.09
B24: 4 | C24: 0.005 | D24: =+SUM($C$21:C24) -> 0.114 | E24: =+Summary!H39 -> 20 | F24: =+C24*E24 -> 0.1
B25: 5 | C25: 0.003 | D25: =+SUM($C$21:C25) -> 0.117 | E25: =+Summary!H40 -> 50 | F25: =+C25*E25 -> 0.15
B26: 6 | C26: 0.001 | D26: =+SUM($C$21:C26) -> 0.118 | E26: =+Summary!H41 -> 100 | F26: =+C26*E26 -> 0.1
B27: 7 | C27: 0.0007 | D27: =+SUM($C$21:C27) -> 0.1187 | E27: =+Summary!H42 -> 500 | F27: =+C27*E27 -> 0.35 | G27: (*) Enemy killed
B28: Total (*) | C28: =+SUM(C21:C27) -> 0.1187 | F28: =+SUM(F21:F27) -> 1.05
B29: (*) Total probability is hit rate
A32: Table 3 | B32: Prize # | C32: Probability | D32: Cumulative prob. | E32: Award | F32: Avg payout
B33: 1 | C33: 0.08 | D33: =+SUM($C$33:C33) -> 0.08 | E33: =+Summary!H36 -> 2 | F33: =+C33*E33 -> 0.16
B34: 2 | C34: 0.01 | D34: =+SUM($C$33:C34) -> 0.09 | E34: =+Summary!H37 -> 5 | F34: =+C34*E34 -> 0.05
B35: 3 | C35: 0.009 | D35: =+SUM($C$33:C35) -> 0.099 | E35: =+Summary!H38 -> 10 | F35: =+C35*E35 -> 0.09
B36: 4 | C36: 0.005 | D36: =+SUM($C$33:C36) -> 0.104 | E36: =+Summary!H39 -> 20 | F36: =+C36*E36 -> 0.1
B37: 5 | C37: 0.003 | D37: =+SUM($C$33:C37) -> 0.107 | E37: =+Summary!H40 -> 50 | F37: =+C37*E37 -> 0.15
B38: 6 | C38: 0.001 | D38: =+SUM($C$33:C38) -> 0.108 | E38: =+Summary!H41 -> 100 | F38: =+C38*E38 -> 0.1
B39: 7 | C39: 0.0008 | D39: =+SUM($C$33:C39) -> 0.1088 | E39: =+Summary!H42 -> 500 | F39: =+C39*E39 -> 0.4 | G39: (*) Enemy killed
B40: Total (*) | C40: =+SUM(C33:C39) -> 0.1088 | F40: =+SUM(F33:F39) -> 1.05
B41: (*) Total probability is hit rate
A44: Table 4 | B44: Prize # | C44: Probability | D44: Cumulative prob. | E44: Award | F44: Avg payout
B45: 1 | C45: 0.06 | D45: =+SUM($C$45:C45) -> 0.06 | E45: =+Summary!H36 -> 2 | F45: =+C45*E45 -> 0.12
B46: 2 | C46: 0.01 | D46: =+SUM($C$45:C46) -> 0.07 | E46: =+Summary!H37 -> 5 | F46: =+C46*E46 -> 0.05
B47: 3 | C47: 0.003 | D47: =+SUM($C$45:C47) -> 0.073 | E47: =+Summary!H38 -> 10 | F47: =+C47*E47 -> 0.03
B48: 4 | C48: 0.005 | D48: =+SUM($C$45:C48) -> 0.078 | E48: =+Summary!H39 -> 20 | F48: =+C48*E48 -> 0.1
B49: 5 | C49: 0.003 | D49: =+SUM($C$45:C49) -> 0.081 | E49: =+Summary!H40 -> 50 | F49: =+C49*E49 -> 0.15
...

Sheet Special weapon 3 (HV enemy)
A1: SPECIAL WEAPON 3 - High Volatility Enemy
A2: For each shot with a regular weapon, draw the damage caused using the tables below.
A3: Start using table 1 and every 100 shots received change to the following table.
A4: Note: The probability of defeating the enemy increases from one table to next table (the enemy gets weaker every 100 shots received)
A8: Table 1 | B8: Prize # | C8: Probability | D8: Cumulative prob. | E8: Award | F8: Avg payout
B9: 1 | C9: 0.05 | D9: =+SUM($C$9:C9) -> 0.05 | E9: =+Summary!H36 -> 2 | F9: =+C9*E9 -> 0.1
B10: 2 | C10: 0.02 | D10: =+SUM($C$9:C10) -> 0.07 | E10: =+Summary!H37 -> 5 | F10: =+C10*E10 -> 0.1
B11: 3 | C11: 0.01 | D11: =+SUM($C$9:C11) -> 0.08 | E11: =+Summary!H38 -> 10 | F11: =+C11*E11 -> 0.1
B12: 4 | C12: 0.005 | D12: =+SUM($C$9:C12) -> 0.085 | E12: =+Summary!H39 -> 20 | F12: =+C12*E12 -> 0.1
B13: 5 | C13: 0.003 | D13: =+SUM($C$9:C13) -> 0.088 | E13: =+Summary!H40 -> 50 | F13: =+C13*E13 -> 0.15
B14: 6 | C14: 0.001 | D14: =+SUM($C$9:C14) -> 0.089 | E14: =+Summary!H41 -> 100 | F14: =+C14*E14 -> 0.1
B15: 7 | C15: 0.0005 | D15: =+SUM($C$9:C15) -> 0.0895 | E15: =+Summary!H42 -> 500 | F15: =+C15*E15 -> 0.25 | G15: (*) Enemy killed
B16: Total (*) | C16: =+SUM(C9:C15) -> 0.0895 | F16: =+SUM(F9:F15) -> 0.9
B17: (*) Total probability is hit rate
A20: Table 2 | B20: Prize # | C20: Probability | D20: Cumulative prob. | E20: Award | F20: Avg payout
B21: 1 | C21: 0.04 | D21: =+SUM($C$21:C21) -> 0.04 | E21: =+Summary!H36 -> 2 | F21: =+C21*E21 -> 0.08
B22: 2 | C22: 0.02 | D22: =+SUM($C$21:C22) -> 0.06 | E22: =+Summary!H37 -> 5 | F22: =+C22*E22 -> 0.1
B23: 3 | C23: 0.01 | D23: =+SUM($C$21:C23) -> 0.07 | E23: =+Summary!H38 -> 10 | F23: =+C23*E23 -> 0.1
B24: 4 | C24: 0.0035 | D24: =+SUM($C$21:C24) -> 0.0735 | E24: =+Summary!H39 -> 20 | F24: =+C24*E24 -> 0.07
B25: 5 | C25: 0.003 | D25: =+SUM($C$21:C25) -> 0.0765 | E25: =+Summary!H40 -> 50 | F25: =+C25*E25 -> 0.15
B26: 6 | C26: 0.001 | D26: =+SUM($C$21:C26) -> 0.0775 | E26: =+Summary!H41 -> 100 | F26: =+C26*E26 -> 0.1
B27: 7 | C27: 0.0006 | D27: =+SUM($C$21:C27) -> 0.0781 | E27: =+Summary!H42 -> 500 | F27: =+C27*E27 -> 0.3 | G27: (*) Enemy killed
B28: Total (*) | C28: =+SUM(C21:C27) -> 0.0781 | F28: =+SUM(F21:F27) -> 0.9
B29: (*) Total probability is hit rate
A32: Table 3 | B32: Prize # | C32: Probability | D32: Cumulative prob. | E32: Award | F32: Avg payout
B33: 1 | C33: 0.035 | D33: =+SUM($C$33:C33) -> 0.035 | E33: =+Summary!H36 -> 2 | F33: =+C33*E33 -> 0.07
B34: 2 | C34: 0.01 | D34: =+SUM($C$33:C34) -> 0.045 | E34: =+Summary!H37 -> 5 | F34: =+C34*E34 -> 0.05
B35: 3 | C35: 0.01 | D35: =+SUM($C$33:C35) -> 0.055 | E35: =+Summary!H38 -> 10 | F35: =+C35*E35 -> 0.1
B36: 4 | C36: 0.004 | D36: =+SUM($C$33:C36) -> 0.059 | E36: =+Summary!H39 -> 20 | F36: =+C36*E36 -> 0.08
B37: 5 | C37: 0.003 | D37: =+SUM($C$33:C37) -> 0.062 | E37: =+Summary!H40 -> 50 | F37: =+C37*E37 -> 0.15
B38: 6 | C38: 0.001 | D38: =+SUM($C$33:C38) -> 0.063 | E38: =+Summary!H41 -> 100 | F38: =+C38*E38 -> 0.1
B39: 7 | C39: 0.0007 | D39: =+SUM($C$33:C39) -> 0.0637 | E39: =+Summary!H42 -> 500 | F39: =+C39*E39 -> 0.35 | G39: (*) Enemy killed
B40: Total (*) | C40: =+SUM(C33:C39) -> 0.0637 | F40: =+SUM(F33:F39) -> 0.9
B41: (*) Total probability is hit rate
A44: Table 4 | B44: Prize # | C44: Probability | D44: Cumulative prob. | E44: Award | F44: Avg payout
B45: 1 | C45: 0.035 | D45: =+SUM($C$45:C45) -> 0.035 | E45: =+Summary!H36 -> 2 | F45: =+C45*E45 -> 0.07
B46: 2 | C46: 0.01 | D46: =+SUM($C$45:C46) -> 0.045 | E46: =+Summary!H37 -> 5 | F46: =+C46*E46 -> 0.05
B47: 3 | C47: 0.009 | D47: =+SUM($C$45:C47) -> 0.054 | E47: =+Summary!H38 -> 10 | F47: =+C47*E47 -> 0.09
B48: 4 | C48: 0.003 | D48: =+SUM($C$45:C48) -> 0.057 | E48: =+Summary!H39 -> 20 | F48: =+C48*E48 -> 0.06
B49: 5 | C49: 0.003 | D49: =+SUM($C$45:C49) -> 0.06 | E49: =+Summary!H40 -> 50 | F49: =+C49*E49 -> 0.15
...

Sheet Plasma Gun (HV enemy)
A1: SPECIAL WEAPON 3 - High Volatility Enemy
A2: For each shot with a regular weapon, draw the damage caused using the tables below.
A3: Start using table 1 and every 100 shots received change to the following table.
A4: Note: The probability of defeating the enemy increases from one table to next table (the enemy gets weaker every 100 shots received)
A8: Table 1 | B8: Prize # | C8: Probability | D8: Cumulative prob. | E8: Award | F8: Avg payout
B9: 1 | C9: 0 | D9: =+SUM($C$9:C9) -> 0 | E9: =+Summary!H36 -> 2 | F9: =+C9*E9 -> 0
B10: 2 | C10: 0.1 | D10: =+SUM($C$9:C10) -> 0.1 | E10: =+Summary!H37 -> 5 | F10: =+C10*E10 -> 0.5
B11: 3 | C11: 0.05 | D11: =+SUM($C$9:C11) -> 0.15 | E11: =+Summary!H38 -> 10 | F11: =+C11*E11 -> 0.5
B12: 4 | C12: 0.05 | D12: =+SUM($C$9:C12) -> 0.2 | E12: =+Summary!H39 -> 20 | F12: =+C12*E12 -> 1
B13: 5 | C13: 0.05 | D13: =+SUM($C$9:C13) -> 0.25 | E13: =+Summary!H40 -> 50 | F13: =+C13*E13 -> 2.5
B14: 6 | C14: 0.08 | D14: =+SUM($C$9:C14) -> 0.33 | E14: =+Summary!H41 -> 100 | F14: =+C14*E14 -> 8
B15: 7 | C15: 0.005 | D15: =+SUM($C$9:C15) -> 0.335 | E15: =+Summary!H42 -> 500 | F15: =+C15*E15 -> 2.5 | G15: (*) Enemy killed
B16: Total (*) | C16: =+SUM(C9:C15) -> 0.335 | F16: =+SUM(F9:F15) -> 15
B17: (*) Total probability is hit rate
A20: Table 2 | B20: Prize # | C20: Probability | D20: Cumulative prob. | E20: Award | F20: Avg payout
B21: 1 | C21: 0 | D21: =+SUM($C$21:C21) -> 0 | E21: =+Summary!H36 -> 2 | F21: =+C21*E21 -> 0
B22: 2 | C22: 0.2 | D22: =+SUM($C$21:C22) -> 0.2 | E22: =+Summary!H37 -> 5 | F22: =+C22*E22 -> 1
B23: 3 | C23: 0.1 | D23: =+SUM($C$21:C23) -> 0.3 | E23: =+Summary!H38 -> 10 | F23: =+C23*E23 -> 1
B24: 4 | C24: 0.1 | D24: =+SUM($C$21:C24) -> 0.4 | E24: =+Summary!H39 -> 20 | F24: =+C24*E24 -> 2
B25: 5 | C25: 0.1 | D25: =+SUM($C$21:C25) -> 0.5 | E25: =+Summary!H40 -> 50 | F25: =+C25*E25 -> 5
B26: 6 | C26: 0.03 | D26: =+SUM($C$21:C26) -> 0.53 | E26: =+Summary!H41 -> 100 | F26: =+C26*E26 -> 3
B27: 7 | C27: 0.006 | D27: =+SUM($C$21:C27) -> 0.536 | E27: =+Summary!H42 -> 500 | F27: =+C27*E27 -> 3 | G27: (*) Enemy killed
B28: Total (*) | C28: =+SUM(C21:C27) -> 0.536 | F28: =+SUM(F21:F27) -> 15
B29: (*) Total probability is hit rate
A32: Table 3 | B32: Prize # | C32: Probability | D32: Cumulative prob. | E32: Award | F32: Avg payout
B33: 1 | C33: 0 | D33: =+SUM($C$33:C33) -> 0 | E33: =+Summary!H36 -> 2 | F33: =+C33*E33 -> 0
B34: 2 | C34: 0.2 | D34: =+SUM($C$33:C34) -> 0.2 | E34: =+Summary!H37 -> 5 | F34: =+C34*E34 -> 1
B35: 3 | C35: 0.15 | D35: =+SUM($C$33:C35) -> 0.35 | E35: =+Summary!H38 -> 10 | F35: =+C35*E35 -> 1.5
B36: 4 | C36: 0.1 | D36: =+SUM($C$33:C36) -> 0.45 | E36: =+Summary!H39 -> 20 | F36: =+C36*E36 -> 2
B37: 5 | C37: 0.1 | D37: =+SUM($C$33:C37) -> 0.55 | E37: =+Summary!H40 -> 50 | F37: =+C37*E37 -> 5
B38: 6 | C38: 0.02 | D38: =+SUM($C$33:C38) -> 0.57 | E38: =+Summary!H41 -> 100 | F38: =+C38*E38 -> 2
B39: 7 | C39: 0.007 | D39: =+SUM($C$33:C39) -> 0.577 | E39: =+Summary!H42 -> 500 | F39: =+C39*E39 -> 3.5 | G39: (*) Enemy killed
B40: Total (*) | C40: =+SUM(C33:C39) -> 0.577 | F40: =+SUM(F33:F39) -> 15
B41: (*) Total probability is hit rate
A44: Table 4 | B44: Prize # | C44: Probability | D44: Cumulative prob. | E44: Award | F44: Avg payout
B45: 1 | C45: 0 | D45: =+SUM($C$45:C45) -> 0 | E45: =+Summary!H36 -> 2 | F45: =+C45*E45 -> 0
B46: 2 | C46: 0.2 | D46: =+SUM($C$45:C46) -> 0.2 | E46: =+Summary!H37 -> 5 | F46: =+C46*E46 -> 1
B47: 3 | C47: 0.1 | D47: =+SUM($C$45:C47) -> 0.3 | E47: =+Summary!H38 -> 10 | F47: =+C47*E47 -> 1
B48: 4 | C48: 0.1 | D48: =+SUM($C$45:C48) -> 0.4 | E48: =+Summary!H39 -> 20 | F48: =+C48*E48 -> 2
B49: 5 | C49: 0.1 | D49: =+SUM($C$45:C49) -> 0.5 | E49: =+Summary!H40 -> 50 | F49: =+C49*E49 -> 5
...

Sheet Base game (Mummy A)
A1: Medium Mummy A (golden wrist bands)
A2: For each shot with a regular weapon, draw the damage caused using the table according to prizes already granted by enemy that is being shot.
A4: Table 1 | B4: Prize # | C4: Probability | D4: Cumulative prob. | E4: Award | F4: RTP | G4: Prob. Boss round
A5: (Initial state) | B5: 1 | C5: 0.08 | D5: =+SUM($C$5:C5) -> 0.08 | E5: =+Summary!E27 -> 5 | F5: =+C5*E5 -> 0.4
B6: 2 | C6: 0.011 | D6: =+SUM($C$5:C6) -> 0.091 | E6: =+Summary!E28 -> 10 | F6: =+C6*E6 -> 0.11
B7: 1 and 2 | C7: 0.006 | D7: =+SUM($C$5:C7) -> 0.097 | E7: =+E5+E6 -> 15 | F7: =+C7*E7 -> 0.09 | G7: 0.83333333 | H7: (*) Enemy killed
B8: Total (*) | C8: =+SUM(C5:C7) -> 0.097 | F8: =+SUM(F5:F7) -> 0.6
B9: (*) Total probability is hit rate
A12: Table 6 | B12: Prize # | C12: Probability | D12: Cumulative prob. | E12: Award | F12: RTP | G12: Prob. Boss round
A13: Awards granted: | B13: 1 | C13: 0.12 | D13: =+SUM(C13:$C$13) -> 0.12 | E13: =+E5 -> 5 | F13: =+E13*C13 -> 0.6 | G13: 0.041666667 | H13: (*) Enemy killed
A14: Prize #2 | B14: Total | C14: =+SUM(C13:C13) -> 0.12 | F14: =+SUM(F13:F13) -> 0.6
A17: Table 7 | B17: Prize # | C17: Probability | D17: Cumulative prob. | E17: Award | F17: RTP | G17: Prob. Boss round
A18: Awards granted: | B18: 2 | C18: 0.06 | D18: =+SUM(C$18:$C18) -> 0.06 | E18: =+E6 -> 10 | F18: =+E18*C18 -> 0.6 | G18: 0.083333333 | H18: (*) Enemy killed
A19: Prize #1 | B19: Total | C19: =+SUM(C18:C18) -> 0.06 | F19: =+SUM(F18:F18) -> 0.6

Sheet Base game (Mummy B)
A1: Medium Mummy B (golden wrist bands and necklace)
A2: For each shot with a regular weapon, draw the damage caused using the table according to prizes already granted by enemy that is being shot.
A4: Table 1 | B4: Prize # | C4: Probability | D4: Cumulative prob. | E4: Award | F4: RTP | G4: Prob. Boss round
A5: (Initial state) | B5: 1 | C5: 0.053 | D5: =+SUM($C$5:C5) -> 0.053 | E5: =+Summary!H27 -> 5 | F5: =+C5*E5 -> 0.265
B6: 2 | C6: 0.005 | D6: =+SUM($C$5:C6) -> 0.058 | E6: =+Summary!H28 -> 10 | F6: =+C6*E6 -> 0.05
B7: 3 | C7: 0.005 | D7: =+SUM($C$5:C7) -> 0.063 | E7: =+Summary!H29 -> 15 | F7: =+C7*E7 -> 0.075
B8: 1 and 2 | C8: 0.001 | D8: =+SUM($C$5:C8) -> 0.064 | E8: =+E5+E6 -> 15 | F8: =+C8*E8 -> 0.015
B9: 1 and 3 | C9: 0.001 | D9: =+SUM($C$5:C9) -> 0.065 | E9: =+E5+E7 -> 20 | F9: =+C9*E9 -> 0.02
B10: 2 and 3 | C10: 0.001 | D10: =+SUM($C$5:C10) -> 0.066 | E10: =+E6+E7 -> 25 | F10: =+C10*E10 -> 0.025
B11: 1, 2 and 3 (*) | C11: 0.005 | D11: =+SUM($C$5:C11) -> 0.071 | E11: =+E5+E6+E7 -> 30 | F11: =+C11*E11 -> 0.15 | G11: =1/C11/200 -> 1 | H11: (*) Enemy killed
B12: Total (*) | C12: =+SUM(C5:C11) -> 0.071 | F12: =+SUM(F5:F11) -> 0.6
B13: (*) Total probability is hit rate
A15: Table 2 | B15: Prize # | C15: Probability | D15: Cumulative prob. | E15: Award | F15: RTP | G15: Prob. Boss round
A16: Awards granted: | B16: 2 | C16: 0.04 | D16: =+SUM(C16:$C$16) -> 0.04 | E16: =+E6 -> 10 | F16: =+C16*E16 -> 0.4
A17: Prize #1 | B17: 3 | C17: 0.005 | D17: =+SUM(C$16:$C17) -> 0.045 | E17: =+E7 -> 15 | F17: =+C17*E17 -> 0.075
B18: 2 and 3 | C18: 0.005 | D18: =+SUM(C$16:$C18) -> 0.05 | E18: =+E16+E17 -> 25 | F18: =+C18*E18 -> 0.125 | G18: =1/C18/200 -> 1 | H18: (*) Enemy killed
B19: Total | C19: =+SUM(C16:C18) -> 0.05 | F19: =+SUM(F16:F18) -> 0.6
A22: Table 3 | B22: Prize # | C22: Probability | D22: Cumulative prob. | E22: Award | F22: RTP | G22: Prob. Boss round
A23: Awards granted: | B23: 1 | C23: 0.08 | D23: =+SUM(C23:$C$23) -> 0.08 | E23: =+E5 -> 5 | F23: =+C23*E23 -> 0.4
A24: Prize #2 | B24: 3 | C24: 0.004 | D24: =+SUM(C$23:$C24) -> 0.084 | E24: =+E7 -> 15 | F24: =+C24*E24 -> 0.06
B25: 1 and 3 | C25: 0.007 | D25: =+SUM(C$23:$C25) -> 0.091 | E25: =+E23+E24 -> 20 | F25: =+C25*E25 -> 0.14 | G25: =1/C25/200 -> 0.71428571 | H25: (*) Enemy killed
B26: Total | C26: =+SUM(C23:C25) -> 0.091 | F26: =+SUM(F23:F25) -> 0.6
A29: Table 4 | B29: Prize # | C29: Probability | D29: Cumulative prob. | E29: Award | F29: RTP | G29: Prob. Boss round
A30: Awards granted: | B30: 3 | C30: 0.04 | D30: =+SUM(C30:$C$30) -> 0.04 | E30: =+E7 -> 15 | F30: =+C30*E30 -> 0.6 | G30: 0.125 | H30: (*) Enemy killed
A31: Prize #1 | B31: Total | C31: =+SUM(C30:C30) -> 0.04 | F31: =+SUM(F30:F30) -> 0.6
A32: Prize #2
A34: Table 5 | B34: Prize # | C34: Probability | D34: Cumulative prob. | E34: Award | F34: RTP | G34: Prob. Boss round
A35: Awards granted: | B35: 1 | C35: 0.085 | D35: =+SUM(C35:$C$35) -> 0.085 | E35: =+E5 -> 5 | F35: =+C35*E35 -> 0.425
A36: Prize #3 | B36: 2 | C36: 0.01 | D36: =+SUM(C$35:$C36) -> 0.095 | E36: =+E6 -> 10 | F36: =+C36*E36 -> 0.1
B37: 1 and 2 | C37: 0.005 | D37: =+SUM(C$35:$C37) -> 0.1 | E37: =+E35+E36 -> 15 | F37: =+C37*E37 -> 0.075 | G37: 1 | H37: (*) Enemy killed
B38: Total | C38: =+SUM(C35:C37) -> 0.1 | F38: =+SUM(F35:F37) -> 0.6
A41: Table 6 | B41: Prize # | C41: Probability | D41: Cumulative prob. | E41: Award | F41: RTP | G41: Prob. Boss round
A42: Awards granted: | B42: 1 | C42: 0.12 | D42: =+SUM(C42:$C$42) -> 0.12 | E42: =+E5 -> 5 | F42: =+E42*C42 -> 0.6 | G42: 0.041666667 | H42: (*) Enemy killed
A43: Prize #2 | B43: Total | C43: =+SUM(C42:C42) -> 0.12 | F43: =+SUM(F42:F42) -> 0.6
A44: Prize #3
A46: Table 7 | B46: Prize # | C46: Probability | D46: Cumulative prob. | E46: Award | F46: RTP | G46: Prob. Boss round
A47: Awards granted: | B47: 2 | C47: 0.06 | D47: =+SUM(C$47:$C47) -> 0.06 | E47: =+E6 -> 10 | F47: =+E47*C47 -> 0.6 | G47: 0.083333333 | H47: (*) Enemy killed
A48: Prize #1 | B48: Total | C48: =+SUM(C47:C47) -> 0.06 | F48: =+SUM(F47:F47) -> 0.6
A49: Prize #3

Sheet Base game (Mummy C)
A1: Medium Mummy C (golden boots and wrist bands)
A2: For each shot with a regular weapon, draw the damage caused using the table according to prizes already granted by enemy that is being shot.
A4: Table 1 | B4: Prize # | C4: Probability | D4: Cumulative prob. | E4: Award | F4: RTP | G4: Prob. Boss round
A5: (Initial state) | B5: 1 | C5: 0.03 | D5: =+SUM($C$5:C5) -> 0.03 | E5: =+Summary!K27 -> 8 | F5: =+C5*E5 -> 0.24
B6: 2 | C6: 0.008 | D6: =+SUM($C$5:C6) -> 0.038 | E6: =+Summary!K28 -> 12 | F6: =+C6*E6 -> 0.096
B7: 3 | C7: 0.004 | D7: =+SUM($C$5:C7) -> 0.042 | E7: =+Summary!K29 -> 18 | F7: =+C7*E7 -> 0.072
B8: 1 and 2 | C8: 0.0001 | D8: =+SUM($C$5:C8) -> 0.0421 | E8: =+E5+E6 -> 20 | F8: =+C8*E8 -> 0.002
B9: 1 and 3 | C9: 0 | D9: =+SUM($C$5:C9) -> 0.0421 | E9: =+E5+E7 -> 26 | F9: =+C9*E9 -> 0
B10: 2 and 3 | C10: 0 | D10: =+SUM($C$5:C10) -> 0.0421 | E10: =+E6+E7 -> 30 | F10: =+C10*E10 -> 0
B11: 1, 2 and 3 (*) | C11: 0.005 | D11: =+SUM($C$5:C11) -> 0.0471 | E11: =+E5+E6+E7 -> 38 | F11: =+C11*E11 -> 0.19 | G11: 1 | H11: (*) Enemy killed
B12: Total (*) | C12: =+SUM(C5:C11) -> 0.0471 | F12: =+SUM(F5:F11) -> 0.6
B13: (*) Total probability is hit rate
A15: Table 2 | B15: Prize # | C15: Probability | D15: Cumulative prob. | E15: Award | F15: RTP | G15: Prob. Boss round
A16: Awards granted: | B16: 2 | C16: 0.03 | D16: =+SUM(C16:$C$16) -> 0.03 | E16: =+E6 -> 12 | F16: =+C16*E16 -> 0.36
A17: Prize #1 | B17: 3 | C17: 0.005 | D17: =+SUM(C$16:$C17) -> 0.035 | E17: =+E7 -> 18 | F17: =+C17*E17 -> 0.09
B18: 2 and 3 | C18: 0.005 | D18: =+SUM(C$16:$C18) -> 0.04 | E18: =+E16+E17 -> 30 | F18: =+C18*E18 -> 0.15 | G18: 1 | H18: (*) Enemy killed
B19: Total | C19: =+SUM(C16:C18) -> 0.04 | F19: =+SUM(F16:F18) -> 0.6
A22: Table 3 | B22: Prize # | C22: Probability | D22: Cumulative prob. | E22: Award | F22: RTP | G22: Prob. Boss round
A23: Awards granted: | B23: 1 | C23: 0.02 | D23: =+SUM(C23:$C$23) -> 0.02 | E23: =+E5 -> 8 | F23: =+C23*E23 -> 0.16
A24: Prize #2 | B24: 3 | C24: 0.01 | D24: =+SUM(C$23:$C24) -> 0.03 | E24: =+E7 -> 18 | F24: =+C24*E24 -> 0.18
B25: 1 and 3 | C25: 0.01 | D25: =+SUM(C$23:$C25) -> 0.04 | E25: =+E23+E24 -> 26 | F25: =+C25*E25 -> 0.26 | G25: 0.5 | H25: (*) Enemy killed
B26: Total | C26: =+SUM(C23:C25) -> 0.04 | F26: =+SUM(F23:F25) -> 0.6
A29: Table 4 | B29: Prize # | C29: Probability | D29: Cumulative prob. | E29: Award | F29: RTP | G29: Prob. Boss round
A30: Awards granted: | B30: 3 | C30: 0.033333333 | D30: =+SUM(C30:$C$30) -> 0.033333333 | E30: =+E7 -> 18 | F30: =+C30*E30 -> 0.6 | G30: 0.15 | H30: (*) Enemy killed
A31: Prize #1 | B31: Total | C31: =+SUM(C30:C30) -> 0.033333333 | F31: =+SUM(F30:F30) -> 0.6
A32: Prize #2
A34: Table 5 | B34: Prize # | C34: Probability | D34: Cumulative prob. | E34: Award | F34: RTP | G34: Prob. Boss round
A35: Awards granted: | B35: 1 | C35: 0.0425 | D35: =+SUM(C35:$C$35) -> 0.0425 | E35: =+E5 -> 8 | F35: =+C35*E35 -> 0.34
A36: Prize #3 | B36: 2 | C36: 0.005 | D36: =+SUM(C$35:$C36) -> 0.0475 | E36: =+E6 -> 12 | F36: =+C36*E36 -> 0.06
B37: 1 and 2 | C37: 0.01 | D37: =+SUM(C$35:$C37) -> 0.0575 | E37: =+E35+E36 -> 20 | F37: =+C37*E37 -> 0.2 | G37: 0.5 | H37: (*) Enemy killed
B38: Total | C38: =+SUM(C35:C37) -> 0.0575 | F38: =+SUM(F35:F37) -> 0.6
A41: Table 6 | B41: Prize # | C41: Probability | D41: Cumulative prob. | E41: Award | F41: RTP | G41: Prob. Boss round
A42: Awards granted: | B42: 1 | C42: 0.075 | D42: =+SUM(C42:$C$42) -> 0.075 | E42: =+E5 -> 8 | F42: =+E42*C42 -> 0.6 | G42: 0.066666667 | H42: (*) Enemy killed
A43: Prize #2 | B43: Total | C43: =+SUM(C42:C42) -> 0.075 | F43: =+SUM(F42:F42) -> 0.6
A44: Prize #3
A46: Table 7 | B46: Prize # | C46: Probability | D46: Cumulative prob. | E46: Award | F46: RTP | G46: Prob. Boss round
A47: Awards granted: | B47: 2 | C47: 0.05 | D47: =+SUM(C$47:$C47) -> 0.05 | E47: =+E6 -> 12 | F47: =+E47*C47 -> 0.6 | G47: 0.1 | H47: (*) Enemy killed
A48: Prize #1 | B48: Total | C48: =+SUM(C47:C47) -> 0.05 | F48: =+SUM(F47:F47) -> 0.6
A49: Prize #3

Sheet Base game (Standard Mummy)
A1: Standard Mummy
A2: For each shot with a regular weapon, draw the damage caused using the table according to prizes already granted by enemy that is being shot.
A4: Table 1 | B4: Prize # | C4: Probability | D4: Cumulative prob. | E4: Award | F4: RTP | G4: Prob. Boss round
A5: (Initial state) | B5: 1 | C5: 0.09 | D5: =+SUM($C$5:C5) -> 0.09 | E5: =+Summary!B27 -> 3 | F5: =+C5*E5 -> 0.27
B6: 2 | C6: 0.058 | D6: =+SUM($C$5:C6) -> 0.148 | E6: =+Summary!B28 -> 5 | F6: =+C6*E6 -> 0.29
B7: 1 and 2 | C7: 0.005 | D7: =+SUM($C$5:C7) -> 0.153 | E7: =+E5+E6 -> 8 | F7: =+C7*E7 -> 0.04 | G7: 1 | H7: (*) Enemy killed
B8: Total (*) | C8: =+SUM(C5:C7) -> 0.153 | F8: =+SUM(F5:F7) -> 0.6
B9: (*) Total probability is hit rate
A12: Table 6 | B12: Prize # | C12: Probability | D12: Cumulative prob. | E12: Award | F12: RTP | G12: Prob. Boss round
A13: Awards granted: | B13: 1 | C13: 0.2 | D13: =+SUM(C13:$C$13) -> 0.2 | E13: =+E5 -> 3 | F13: =+E13*C13 -> 0.6 | G13: 0.025 | H13: (*) Enemy killed
A14: Prize #2 | B14: Total | C14: =+SUM(C13:C13) -> 0.2 | F14: =+SUM(F13:F13) -> 0.6
A17: Table 7 | B17: Prize # | C17: Probability | D17: Cumulative prob. | E17: Award | F17: RTP | G17: Prob. Boss round
A18: Awards granted: | B18: 2 | C18: 0.12 | D18: =+SUM(C$18:$C18) -> 0.12 | E18: =+E6 -> 5 | F18: =+E18*C18 -> 0.6 | G18: 0.041666667 | H18: (*) Enemy killed
A19: Prize #1 | B19: Total | C19: =+SUM(C18:C18) -> 0.12 | F19: =+SUM(F18:F18) -> 0.6

Sheet Base game (Scarabs)
A1: Scarabs
A4: Scarab black | B4: Prize # | C4: Probability | D4: Cumulative prob. | E4: Award | F4: RTP | G4: Prob. Boss round
B5: 1 | C5: 0.3 | D5: =+SUM(C5:$C$5) -> 0.3 | E5: =+Summary!B21 -> 2 | F5: =+E5*C5 -> 0.6 | G5: 0.016666667 | H5: (*) Enemy killed
B6: Total | C6: =+SUM(C5:C5) -> 0.3 | F6: =+SUM(F5:F5) -> 0.6
A9: Scarab gold | B9: Prize # | C9: Probability | D9: Cumulative prob. | E9: Award | F9: RTP | G9: Prob. Boss round
B10: 1 | C10: 0.12 | D10: =1/6 -> 0.16666667 | E10: =+Summary!E21 -> 5 | F10: =+E10*C10 -> 0.6 | G10: 0.041666667 | H10: (*) Enemy killed
B11: Total | C11: =+SUM(C10:C10) -> 0.12 | F11: =+SUM(F10:F10) -> 0.6
A14: Scarab gem covered | B14: Prize # | C14: Probability | D14: Cumulative prob. | E14: Award | F14: RTP | G14: Prob. Boss round
B15: 1 | C15: 0.075 | D15: =+SUM(C$15:$C15) -> 0.075 | E15: =+Summary!H21 -> 8 | F15: =+E15*C15 -> 0.6 | G15: 0.066666667 | H15: (*) Enemy killed
B16: Total | C16: =+SUM(C15:C15) -> 0.075 | F16: =+SUM(F15:F15) -> 0.6

Sheet Base game (Pharaoh A & B)
A1: Powerful Pharaoh Mummy A & B
A2: For each shot with a regular weapon, draw the damage caused using the table according to prizes already granted by enemy that is being shot.
A4: Table 1 | B4: Prize # | C4: Probability | D4: Cumulative prob. | E4: Award | F4: RTP | G4: Prob. Boss round
A5: (Initial state) | B5: 1 | C5: 0.01625 | D5: =+SUM($C$5:C5) -> 0.01625 | E5: =+Summary!B36 -> 12 | F5: =+C5*E5 -> 0.195
B6: 2 | C6: 0.01 | D6: =+SUM($C$5:C6) -> 0.02625 | E6: =+Summary!B37 -> 15 | F6: =+C6*E6 -> 0.15
B7: 3 | C7: 0.001 | D7: =+SUM($C$5:C7) -> 0.02725 | E7: =+Summary!B38 -> 20 | F7: =+C7*E7 -> 0.02
B8: 1 and 2 | C8: 0 | D8: =+SUM($C$5:C8) -> 0.02725 | E8: =+E5+E6 -> 27 | F8: =+C8*E8 -> 0
B9: 1 and 3 | C9: 0 | D9: =+SUM($C$5:C9) -> 0.02725 | E9: =+E5+E7 -> 32 | F9: =+C9*E9 -> 0
B10: 2 and 3 | C10: 0 | D10: =+SUM($C$5:C10) -> 0.02725 | E10: =+E6+E7 -> 35 | F10: =+C10*E10 -> 0
B11: 1, 2 and 3 (*) | C11: 0.005 | D11: =+SUM($C$5:C11) -> 0.03225 | E11: =+E5+E6+E7 -> 47 | F11: =+C11*E11 -> 0.235 | G11: 1 | H11: (*) Enemy killed
B12: Total (*) | C12: =+SUM(C5:C11) -> 0.03225 | F12: =+SUM(F5:F11) -> 0.6
B13: (*) Total probability is hit rate
A15: Table 2 | B15: Prize # | C15: Probability | D15: Cumulative prob. | E15: Award | F15: RTP | G15: Prob. Boss round
A16: Awards granted: | B16: 2 | C16: 0.015 | D16: =+SUM(C16:$C$16) -> 0.015 | E16: =+E6 -> 15 | F16: =+C16*E16 -> 0.225
A17: Prize #1 | B17: 3 | C17: 0.01 | D17: =+SUM(C$16:$C17) -> 0.025 | E17: =+E7 -> 20 | F17: =+C17*E17 -> 0.2
B18: 2 and 3 | C18: 0.005 | D18: =+SUM(C$16:$C18) -> 0.03 | E18: =+E16+E17 -> 35 | F18: =+C18*E18 -> 0.175 | G18: 1 | H18: (*) Enemy killed
B19: Total | C19: =+SUM(C16:C18) -> 0.03 | F19: =+SUM(F16:F18) -> 0.6
A22: Table 3 | B22: Prize # | C22: Probability | D22: Cumulative prob. | E22: Award | F22: RTP | G22: Prob. Boss round
A23: Awards granted: | B23: 1 | C23: 0.02 | D23: =+SUM(C23:$C$23) -> 0.02 | E23: =+E5 -> 12 | F23: =+C23*E23 -> 0.24
A24: Prize #2 | B24: 3 | C24: 0.01 | D24: =+SUM(C$23:$C24) -> 0.03 | E24: =+E7 -> 20 | F24: =+C24*E24 -> 0.2
B25: 1 and 3 | C25: 0.005 | D25: =+SUM(C$23:$C25) -> 0.035 | E25: =+E23+E24 -> 32 | F25: =+C25*E25 -> 0.16 | G25: 1 | H25: (*) Enemy killed
B26: Total | C26: =+SUM(C23:C25) -> 0.035 | F26: =+SUM(F23:F25) -> 0.6
A29: Table 4 | B29: Prize # | C29: Probability | D29: Cumulative prob. | E29: Award | F29: RTP | G29: Prob. Boss round
A30: Awards granted: | B30: 3 | C30: 0.03 | D30: =+SUM(C30:$C$30) -> 0.03 | E30: =+E7 -> 20 | F30: =+C30*E30 -> 0.6 | G30: 0.16666667 | H30: (*) Enemy killed
A31: Prize #1 | B31: Total | C31: =+SUM(C30:C30) -> 0.03 | F31: =+SUM(F30:F30) -> 0.6
A32: Prize #2
A34: Table 5 | B34: Prize # | C34: Probability | D34: Cumulative prob. | E34: Award | F34: RTP | G34: Prob. Boss round
A35: Awards granted: | B35: 1 | C35: 0.015 | D35: =+SUM(C35:$C$35) -> 0.015 | E35: =+E5 -> 12 | F35: =+C35*E35 -> 0.18
A36: Prize #3 | B36: 2 | C36: 0.01 | D36: =+SUM(C$35:$C36) -> 0.025 | E36: =+E6 -> 15 | F36: =+C36*E36 -> 0.15
B37: 1 and 2 | C37: 0.01 | D37: =+SUM(C$35:$C37) -> 0.035 | E37: =+E35+E36 -> 27 | F37: =+C37*E37 -> 0.27 | G37: 0.5 | H37: (*) Enemy killed
B38: Total | C38: =+SUM(C35:C37) -> 0.035 | F38: =+SUM(F35:F37) -> 0.6
A41: Table 6 | B41: Prize # | C41: Probability | D41: Cumulative prob. | E41: Award | F41: RTP | G41: Prob. Boss round
A42: Awards granted: | B42: 1 | C42: 0.05 | D42: =+SUM(C42:$C$42) -> 0.05 | E42: =+E5 -> 12 | F42: =+E42*C42 -> 0.6 | G42: 0.1 | H42: (*) Enemy killed
A43: Prize #2 | B43: Total | C43: =+SUM(C42:C42) -> 0.05 | F43: =+SUM(F42:F42) -> 0.6
A44: Prize #3
A46: Table 7 | B46: Prize # | C46: Probability | D46: Cumulative prob. | E46: Award | F46: RTP | G46: Prob. Boss round
A47: Awards granted: | B47: 2 | C47: 0.04 | D47: =+SUM(C$47:$C47) -> 0.04 | E47: =+E6 -> 15 | F47: =+E47*C47 -> 0.6 | G47: =3*0.041666666666666 -> 0.125 | H47: (*) Enemy killed
A48: Prize #1 | B48: Total | C48: =+SUM(C47:C47) -> 0.04 | F48: =+SUM(F47:F47) -> 0.6
A49: Prize #3

Sheet Special weapon 1 (Mummy A)
A1: SPECIAL WEAPON 1 - Medium Mummy A (golden wrist bands)
A2: For each shot with a special weapon, draw the damage caused using the table according to prizes already granted by enemy that is being shot.
A4: Table 1 | B4: Prize # | C4: Probability | D4: Cumulative prob. | E4: Award | F4: Avg payout | G4: Prob. Boss round
A5: (Initial state) | B5: 1 | C5: 0.1 | D5: =+SUM($C$5:C5) -> 0.1 | E5: =+Summary!E27 -> 5 | F5: =+C5*E5 -> 0.5
B6: 2 | C6: 0.01 | D6: =+SUM($C$5:C6) -> 0.11 | E6: =+Summary!E28 -> 10 | F6: =+C6*E6 -> 0.1
B7: 1 and 2 | C7: 0.04 | D7: =+SUM($C$5:C7) -> 0.15 | E7: =+E5+E6 -> 15 | F7: =+C7*E7 -> 0.6 | G7: 0 | H7: (*) Enemy killed
B8: Total (*) | C8: =+SUM(C5:C7) -> 0.15 | F8: =+SUM(F5:F7) -> 1.2
B9: (*) Total probability is hit rate
A12: Table 6 | B12: Prize # | C12: Probability | D12: Cumulative prob. | E12: Award | F12: Avg payout | G12: Prob. Boss round
A13: Awards granted: | B13: 1 | C13: 0.24 | D13: =+SUM(C13:$C$13) -> 0.24 | E13: =+E5 -> 5 | F13: =+E13*C13 -> 1.2 | G13: 0 | H13: (*) Enemy killed
A14: Prize #2 | B14: Total | C14: =+SUM(C13:C13) -> 0.24 | F14: =+SUM(F13:F13) -> 1.2
A17: Table 7 | B17: Prize # | C17: Probability | D17: Cumulative prob. | E17: Award | F17: Avg payout | G17: Prob. Boss round
A18: Awards granted: | B18: 2 | C18: 0.12 | D18: =+SUM(C$18:$C18) -> 0.12 | E18: =+E6 -> 10 | F18: =+E18*C18 -> 1.2 | G18: 0 | H18: (*) Enemy killed
A19: Prize #1 | B19: Total | C19: =+SUM(C18:C18) -> 0.12 | F19: =+SUM(F18:F18) -> 1.2

Sheet Special weapon 1 (Mummy B)
A1: SPECIAL WEAPON 1 - Medium Mummy B (golden wrist bands and necklace)
A2: For each shot with a special weapon, draw the damage caused using the table according to prizes already granted by enemy that is being shot.
A4: Table 1 | B4: Prize # | C4: Probability | D4: Cumulative prob. | E4: Award | F4: Avg payout | G4: Prob. Boss round
A5: (Initial state) | B5: 1 | C5: 0.06 | D5: =+SUM($C$5:C5) -> 0.06 | E5: =+Summary!H27 -> 5 | F5: =+C5*E5 -> 0.3
B6: 2 | C6: 0.05 | D6: =+SUM($C$5:C6) -> 0.11 | E6: =+Summary!H28 -> 10 | F6: =+C6*E6 -> 0.5
B7: 3 | C7: 0.006 | D7: =+SUM($C$5:C7) -> 0.116 | E7: =+Summary!H29 -> 15 | F7: =+C7*E7 -> 0.09
B8: 1 and 2 | C8: 0.001 | D8: =+SUM($C$5:C8) -> 0.117 | E8: =+E5+E6 -> 15 | F8: =+C8*E8 -> 0.015
B9: 1 and 3 | C9: 0.0015 | D9: =+SUM($C$5:C9) -> 0.1185 | E9: =+E5+E7 -> 20 | F9: =+C9*E9 -> 0.03
B10: 2 and 3 | C10: 0.001 | D10: =+SUM($C$5:C10) -> 0.1195 | E10: =+E6+E7 -> 25 | F10: =+C10*E10 -> 0.025
B11: 1, 2 and 3 (*) | C11: 0.008 | D11: =+SUM($C$5:C11) -> 0.1275 | E11: =+E5+E6+E7 -> 30 | F11: =+C11*E11 -> 0.24 | G11: 0 | H11: (*) Enemy killed
B12: Total (*) | C12: =+SUM(C5:C11) -> 0.1275 | F12: =+SUM(F5:F11) -> 1.2
B13: (*) Total probability is hit rate
A15: Table 2 | B15: Prize # | C15: Probability | D15: Cumulative prob. | E15: Award | F15: Avg payout | G15: Prob. Boss round
A16: Awards granted: | B16: 2 | C16: 0.08 | D16: =+SUM(C16:$C$16) -> 0.08 | E16: =+E6 -> 10 | F16: =+C16*E16 -> 0.8
A17: Prize #1 | B17: 3 | C17: 0.01 | D17: =+SUM(C$16:$C17) -> 0.09 | E17: =+E7 -> 15 | F17: =+C17*E17 -> 0.15
B18: 2 and 3 | C18: 0.01 | D18: =+SUM(C$16:$C18) -> 0.1 | E18: =+E16+E17 -> 25 | F18: =+C18*E18 -> 0.25 | G18: 0 | H18: (*) Enemy killed
B19: Total | C19: =+SUM(C16:C18) -> 0.1 | F19: =+SUM(F16:F18) -> 1.2
A22: Table 3 | B22: Prize # | C22: Probability | D22: Cumulative prob. | E22: Award | F22: Avg payout | G22: Prob. Boss round
A23: Awards granted: | B23: 1 | C23: 0.08 | D23: =+SUM(C23:$C$23) -> 0.08 | E23: =+E5 -> 5 | F23: =+C23*E23 -> 0.4
A24: Prize #2 | B24: 3 | C24: 0.02 | D24: =+SUM(C$23:$C24) -> 0.1 | E24: =+E7 -> 15 | F24: =+C24*E24 -> 0.3
B25: 1 and 3 | C25: 0.025 | D25: =+SUM(C$23:$C25) -> 0.125 | E25: =+E23+E24 -> 20 | F25: =+C25*E25 -> 0.5 | G25: 0 | H25: (*) Enemy killed
B26: Total | C26: =+SUM(C23:C25) -> 0.125 | F26: =+SUM(F23:F25) -> 1.2
A29: Table 4 | B29: Prize # | C29: Probability | D29: Cumulative prob. | E29: Award | F29: Avg payout | G29: Prob. Boss round
A30: Awards granted: | B30: 3 | C30: 0.08 | D30: =+SUM(C30:$C$30) -> 0.08 | E30: =+E7 -> 15 | F30: =+C30*E30 -> 1.2 | G30: 0 | H30: (*) Enemy killed
A31: Prize #1 | B31: Total | C31: =+SUM(C30:C30) -> 0.08 | F31: =+SUM(F30:F30) -> 1.2
A32: Prize #2
A34: Table 5 | B34: Prize # | C34: Probability | D34: Cumulative prob. | E34: Award | F34: Avg payout | G34: Prob. Boss round
A35: Awards granted: | B35: 1 | C35: 0.08 | D35: =+SUM(C35:$C$35) -> 0.08 | E35: =+E5 -> 5 | F35: =+C35*E35 -> 0.4
A36: Prize #3 | B36: 2 | C36: 0.05 | D36: =+SUM(C$35:$C36) -> 0.13 | E36: =+E6 -> 10 | F36: =+C36*E36 -> 0.5
B37: 1 and 2 | C37: 0.02 | D37: =+SUM(C$35:$C37) -> 0.15 | E37: =+E35+E36 -> 15 | F37: =+C37*E37 -> 0.3 | G37: 0 | H37: (*) Enemy killed
B38: Total | C38: =+SUM(C35:C37) -> 0.15 | F38: =+SUM(F35:F37) -> 1.2
A41: Table 6 | B41: Prize # | C41: Probability | D41: Cumulative prob. | E41: Award | F41: Avg payout
A42: Awards granted: | B42: 1 | C42: 0.24 | D42: =+SUM(C42:$C$42) -> 0.24 | E42: =+E5 -> 5 | F42: =+E42*C42 -> 1.2 | G42: 0 | H42: (*) Enemy killed
A43: Prize #2 | B43: Total | C43: =+SUM(C42:C42) -> 0.24 | F43: =+SUM(F42:F42) -> 1.2
A44: Prize #3
A46: Table 7 | B46: Prize # | C46: Probability | D46: Cumulative prob. | E46: Award | F46: Avg payout
A47: Awards granted: | B47: 2 | C47: 0.12 | D47: =+SUM(C$47:$C47) -> 0.12 | E47: =+E6 -> 10 | F47: =+E47*C47 -> 1.2 | G47: 0 | H47: (*) Enemy killed
A48: Prize #1 | B48: Total | C48: =+SUM(C47:C47) -> 0.12 | F48: =+SUM(F47:F47) -> 1.2
A49: Prize #3

Sheet Special weapon 1 (Mummy C)
A1: SPECIAL WEAPON 1 - Medium Mummy C (golden boots and wrist bands)
A2: For each shot with a special weapon, draw the damage caused using the table according to prizes already granted by enemy that is being shot.
A4: Table 1 | B4: Prize # | C4: Probability | D4: Cumulative prob. | E4: Award | F4: Avg payout | G4: Prob. Boss round
A5: (Initial state) | B5: 1 | C5: 0.0525 | D5: =+SUM($C$5:C5) -> 0.0525 | E5: =Summary!K27 -> 8 | F5: =+C5*E5 -> 0.42
B6: 2 | C6: 0.01 | D6: =+SUM($C$5:C6) -> 0.0625 | E6: =Summary!K28 -> 12 | F6: =+C6*E6 -> 0.12
B7: 3 | C7: 0.005 | D7: =+SUM($C$5:C7) -> 0.0675 | E7: =Summary!K29 -> 18 | F7: =+C7*E7 -> 0.09
B8: 1 and 2 | C8: 0.005 | D8: =+SUM($C$5:C8) -> 0.0725 | E8: =+E5+E6 -> 20 | F8: =+C8*E8 -> 0.1
B9: 1 and 3 | C9: 0.005 | D9: =+SUM($C$5:C9) -> 0.0775 | E9: =+E5+E7 -> 26 | F9: =+C9*E9 -> 0.13
B10: 2 and 3 | C10: 0.005 | D10: =+SUM($C$5:C10) -> 0.0825 | E10: =+E6+E7 -> 30 | F10: =+C10*E10 -> 0.15
B11: 1, 2 and 3 (*) | C11: 0.005 | D11: =+SUM($C$5:C11) -> 0.0875 | E11: =+E5+E6+E7 -> 38 | F11: =+C11*E11 -> 0.19 | G11: 0 | H11: (*) Enemy killed
B12: Total (*) | C12: =+SUM(C5:C11) -> 0.0875 | F12: =+SUM(F5:F11) -> 1.2
B13: (*) Total probability is hit rate
A15: Table 2 | B15: Prize # | C15: Probability | D15: Cumulative prob. | E15: Award | F15: Avg payout | G15: Prob. Boss round
A16: Awards granted: | B16: 2 | C16: 0.06 | D16: =+SUM(C16:$C$16) -> 0.06 | E16: =+E6 -> 12 | F16: =+C16*E16 -> 0.72
A17: Prize #1 | B17: 3 | C17: 0.01 | D17: =+SUM(C$16:$C17) -> 0.07 | E17: =+E7 -> 18 | F17: =+C17*E17 -> 0.18
B18: 2 and 3 | C18: 0.01 | D18: =+SUM(C$16:$C18) -> 0.08 | E18: =+E16+E17 -> 30 | F18: =+C18*E18 -> 0.3 | G18: 0 | H18: (*) Enemy killed
B19: Total | C19: =+SUM(C16:C18) -> 0.08 | F19: =+SUM(F16:F18) -> 1.2
A22: Table 3 | B22: Prize # | C22: Probability | D22: Cumulative prob. | E22: Award | F22: Avg payout | G22: Prob. Boss round
A23: Awards granted: | B23: 1 | C23: 0.0725 | D23: =+SUM(C23:$C$23) -> 0.0725 | E23: =+E5 -> 8 | F23: =+C23*E23 -> 0.58
A24: Prize #2 | B24: 3 | C24: 0.02 | D24: =+SUM(C$23:$C24) -> 0.0925 | E24: =+E7 -> 18 | F24: =+C24*E24 -> 0.36
B25: 1 and 3 | C25: 0.01 | D25: =+SUM(C$23:$C25) -> 0.1025 | E25: =+E23+E24 -> 26 | F25: =+C25*E25 -> 0.26 | G25: 0 | H25: (*) Enemy killed
B26: Total | C26: =+SUM(C23:C25) -> 0.1025 | F26: =+SUM(F23:F25) -> 1.2
A29: Table 4 | B29: Prize # | C29: Probability | D29: Cumulative prob. | E29: Award | F29: Avg payout | G29: Prob. Boss round
A30: Awards granted: | B30: 3 | C30: 0.066666667 | D30: =+SUM(C30:$C$30) -> 0.066666667 | E30: =+E7 -> 18 | F30: =+C30*E30 -> 1.2 | G30: 0 | H30: (*) Enemy killed
A31: Prize #1 | B31: Total | C31: =+SUM(C30:C30) -> 0.066666667 | F31: =+SUM(F30:F30) -> 1.2
A32: Prize #2
A34: Table 5 | B34: Prize # | C34: Probability | D34: Cumulative prob. | E34: Award | F34: Avg payout | G34: Prob. Boss round
A35: Awards granted: | B35: 1 | C35: 0.06 | D35: =+SUM(C35:$C$35) -> 0.06 | E35: =+E5 -> 8 | F35: =+C35*E35 -> 0.48
A36: Prize #3 | B36: 2 | C36: 0.01 | D36: =+SUM(C$35:$C36) -> 0.07 | E36: =+E6 -> 12 | F36: =+C36*E36 -> 0.12
B37: 1 and 2 | C37: 0.03 | D37: =+SUM(C$35:$C37) -> 0.1 | E37: =+E35+E36 -> 20 | F37: =+C37*E37 -> 0.6 | G37: 0 | H37: (*) Enemy killed
B38: Total | C38: =+SUM(C35:C37) -> 0.1 | F38: =+SUM(F35:F37) -> 1.2
A41: Table 6 | B41: Prize # | C41: Probability | D41: Cumulative prob. | E41: Award | F41: Avg payout
A42: Awards granted: | B42: 1 | C42: 0.15 | D42: =+SUM(C42:$C$42) -> 0.15 | E42: =+E5 -> 8 | F42: =+E42*C42 -> 1.2 | G42: 0 | H42: (*) Enemy killed
A43: Prize #2 | B43: Total | C43: =+SUM(C42:C42) -> 0.15 | F43: =+SUM(F42:F42) -> 1.2
A44: Prize #3
A46: Table 7 | B46: Prize # | C46: Probability | D46: Cumulative prob. | E46: Award | F46: Avg payout
A47: Awards granted: | B47: 2 | C47: 0.1 | D47: =+SUM(C$47:$C47) -> 0.1 | E47: =+E6 -> 12 | F47: =+E47*C47 -> 1.2 | G47: 0 | H47: (*) Enemy killed
A48: Prize #1 | B48: Total | C48: =+SUM(C47:C47) -> 0.1 | F48: =+SUM(F47:F47) -> 1.2
A49: Prize #3

Sheet Special weapon 1 (Std Mummy)
A1: SPECIAL WEAPON 1 - Standard Mummy
A2: For each shot with a special weapon, draw the damage caused using the table according to prizes already granted by enemy that is being shot.
A4: Table 1 | B4: Prize # | C4: Probability | D4: Cumulative prob. | E4: Award | F4: Avg payout | G4: Prob. Boss round
A5: (Initial state) | B5: 1 | C5: 0.1 | D5: =+SUM($C$5:C5) -> 0.1 | E5: =+Summary!B27 -> 3 | F5: =+C5*E5 -> 0.3
B6: 2 | C6: 0.1 | D6: =+SUM($C$5:C6) -> 0.2 | E6: =+Summary!B28 -> 5 | F6: =+C6*E6 -> 0.5
B7: 1 and 2 | C7: 0.05 | D7: =+SUM($C$5:C7) -> 0.25 | E7: =+E5+E6 -> 8 | F7: =+C7*E7 -> 0.4 | G7: 0 | H7: (*) Enemy killed
B8: Total (*) | C8: =+SUM(C5:C7) -> 0.25 | F8: =+SUM(F5:F7) -> 1.2
B9: (*) Total probability is hit rate
A12: Table 6 | B12: Prize # | C12: Probability | D12: Cumulative prob. | E12: Award | F12: Avg payout | G12: Prob. Boss round
A13: Awards granted: | B13: 1 | C13: 0.4 | D13: =+SUM(C13:$C$13) -> 0.4 | E13: =+E5 -> 3 | F13: =+E13*C13 -> 1.2 | G13: 0 | H13: (*) Enemy killed
A14: Prize #2 | B14: Total | C14: =+SUM(C13:C13) -> 0.4 | F14: =+SUM(F13:F13) -> 1.2
A17: Table 7 | B17: Prize # | C17: Probability | D17: Cumulative prob. | E17: Award | F17: Avg payout | G17: Prob. Boss round
