Workbook

Sheet Base game (HV scarab)
A1: HIGH-Volatility Scarab
A2: For each shot with a regular weapon, draw the damage caused using the tables below.
A3: Start using table 1 and every 100 shots received change to the following table.
A4: Note: The probability of defeating the enemy increases from one table to next table (the enemy gets weaker every 100 shots received)
A8: Table 1 | B8: Prize # | C8: Probability | D8: Cumulative prob. | E8: Award | F8: Avg payout
B9: 1 | C9: 0.0625 | D9: =+SUM($C$9:C9) -> 0.0625 | E9: =+Summary!K36 -> 2 | F9: =+C9*E9 -> 0.125
B10: 2 | C10: 0.025 | D10: =+SUM($C$9:C10) -> 0.0875 | E10: =+Summary!K37 -> 5 | F10: =+C10*E10 -> 0.125
B11: 3 | C11: 0.005 | D11: =+SUM($C$9:C11) -> 0.0925 | E11: =+Summary!K38 -> 10 | F11: =+C11*E11 -> 0.05
B12: 4 | C12: 0.005 | D12: =+SUM($C$9:C12) -> 0.0975 | E12: =+Summary!K39 -> 15 | F12: =+C12*E12 -> 0.075
B13: 5 | C13: 0.004 | D13: =+SUM($C$9:C13) -> 0.1015 | E13: =+Summary!K40 -> 20 | F13: =+C13*E13 -> 0.08
B14: 6 | C14: 0.004 | D14: =+SUM($C$9:C14) -> 0.1055 | E14: =+Summary!K41 -> 50 | F14: =+C14*E14 -> 0.2
B15: 7 | C15: 0.003 | D15: =+SUM($C$9:C15) -> 0.1085 | E15: =+Summary!K42 -> 100 | F15: =+C15*E15 -> 0.3 | G15: (*) Enemy killed
B16: Total (*) | C16: =+SUM(C9:C15) -> 0.1085 | F16: =+SUM(F9:F15) -> 0.955
B17: (*) Total probability is hit rate
A20: Table 2 | B20: Prize # | C20: Probability | D20: Cumulative prob. | E20: Award | F20: Avg payout
B21: 1 | C21: 0.075 | D21: =+SUM($C$21:C21) -> 0.075 | E21: =+Summary!K36 -> 2 | F21: =+C21*E21 -> 0.15
B22: 2 | C22: 0.022 | D22: =+SUM($C$21:C22) -> 0.097 | E22: =+Summary!K37 -> 5 | F22: =+C22*E22 -> 0.11
B23: 3 | C23: 0.004 | D23: =+SUM($C$21:C23) -> 0.101 | E23: =+Summary!K38 -> 10 | F23: =+C23*E23 -> 0.04
B24: 4 | C24: 0.003 | D24: =+SUM($C$21:C24) -> 0.104 | E24: =+Summary!K39 -> 15 | F24: =+C24*E24 -> 0.045
B25: 5 | C25: 0.003 | D25: =+SUM($C$21:C25) -> 0.107 | E25: =+Summary!K40 -> 20 | F25: =+C25*E25 -> 0.06
B26: 6 | C26: 0.001 | D26: =+SUM($C$21:C26) -> 0.108 | E26: =+Summary!K41 -> 50 | F26: =+C26*E26 -> 0.05
B27: 7 | C27: 0.005 | D27: =+SUM($C$21:C27) -> 0.113 | E27: =+Summary!K42 -> 100 | F27: =+C27*E27 -> 0.5 | G27: (*) Enemy killed
B28: Total (*) | C28: =+SUM(C21:C27) -> 0.113 | F28: =+SUM(F21:F27) -> 0.955
B29: (*) Total probability is hit rate
A32: Table 3 | B32: Prize # | C32: Probability | D32: Cumulative prob. | E32: Award | F32: Avg payout
B33: 1 | C33: 0.055 | D33: =+SUM($C$33:C33) -> 0.055 | E33: =+Summary!K36 -> 2 | F33: =+C33*E33 -> 0.11
B34: 2 | C34: 0.01 | D34: =+SUM($C$33:C34) -> 0.065 | E34: =+Summary!K37 -> 5 | F34: =+C34*E34 -> 0.05
B35: 3 | C35: 0.001 | D35: =+SUM($C$33:C35) -> 0.066 | E35: =+Summary!K38 -> 10 | F35: =+C35*E35 -> 0.01
B36: 4 | C36: 0.001 | D36: =+SUM($C$33:C36) -> 0.067 | E36: =+Summary!K39 -> 15 | F36: =+C36*E36 -> 0.015
B37: 5 | C37: 0.001 | D37: =+SUM($C$33:C37) -> 0.068 | E37: =+Summary!K40 -> 20 | F37: =+C37*E37 -> 0.02
B38: 6 | C38: 0.001 | D38: =+SUM($C$33:C38) -> 0.069 | E38: =+Summary!K41 -> 50 | F38: =+C38*E38 -> 0.05
B39: 7 | C39: 0.007 | D39: =+SUM($C$33:C39) -> 0.076 | E39: =+Summary!K42 -> 100 | F39: =+C39*E39 -> 0.7 | G39: (*) Enemy killed
B40: Total (*) | C40: =+SUM(C33:C39) -> 0.076 | F40: =+SUM(F33:F39) -> 0.955
B41: (*) Total probability is hit rate
A44: Table 4 | B44: Prize # | C44: Probability | D44: Cumulative prob. | E44: Award | F44: Avg payout
B45: 1 | C45: 0.0625 | D45: =+SUM($C$45:C45) -> 0.0625 | E45: =+Summary!K36 -> 2 | F45: =+C45*E45 -> 0.125
B46: 2 | C46: 0.001 | D46: =+SUM($C$45:C46) -> 0.0635 | E46: =+Summary!K37 -> 5 | F46: =+C46*E46 -> 0.005
B47: 3 | C47: 0.001 | D47: =+SUM($C$45:C47) -> 0.0645 | E47: =+Summary!K38 -> 10 | F47: =+C47*E47 -> 0.01
B48: 4 | C48: 0.001 | D48: =+SUM($C$45:C48) -> 0.0655 | E48: =+Summary!K39 -> 15 | F48: =+C48*E48 -> 0.015
B49: 5 | C49: 0 | D49: =+SUM($C$45:C49) -> 0.0655 | E49: =+Summary!K40 -> 20 | F49: =+C49*E49 -> 0
...

Sheet Special weapon 1 (HV scarab)
A1: SPECIAL WEAPON 1 - High Volatility Scarab
A2: For each shot with a regular weapon, draw the damage caused using the tables below.
A3: Start using table 1 and every 100 shots received change to the following table.
A4: Note: The probability of defeating the enemy increases from one table to next table (the enemy gets weaker every 100 shots received)
A8: Table 1 | B8: Prize # | C8: Probability | D8: Cumulative prob. | E8: Award | F8: Avg payout
B9: 1 | C9: 0.18 | D9: =+SUM($C$9:C9) -> 0.18 | E9: =+Summary!K36 -> 2 | F9: =+C9*E9 -> 0.36
B10: 2 | C10: 0.035 | D10: =+SUM($C$9:C10) -> 0.215 | E10: =+Summary!K37 -> 5 | F10: =+C10*E10 -> 0.175
B11: 3 | C11: 0.005 | D11: =+SUM($C$9:C11) -> 0.22 | E11: =+Summary!K38 -> 10 | F11: =+C11*E11 -> 0.05
B12: 4 | C12: 0.005 | D12: =+SUM($C$9:C12) -> 0.225 | E12: =+Summary!K39 -> 15 | F12: =+C12*E12 -> 0.075
B13: 5 | C13: 0.002 | D13: =+SUM($C$9:C13) -> 0.227 | E13: =+Summary!K40 -> 20 | F13: =+C13*E13 -> 0.04
B14: 6 | C14: 0.002 | D14: =+SUM($C$9:C14) -> 0.229 | E14: =+Summary!K41 -> 50 | F14: =+C14*E14 -> 0.1
B15: 7 | C15: 0.004 | D15: =+SUM($C$9:C15) -> 0.233 | E15: =+Summary!K42 -> 100 | F15: =+C15*E15 -> 0.4 | G15: (*) Enemy killed
B16: Total (*) | C16: =+SUM(C9:C15) -> 0.233 | F16: =+SUM(F9:F15) -> 1.2
B17: (*) Total probability is hit rate
A20: Table 2 | B20: Prize # | C20: Probability | D20: Cumulative prob. | E20: Award | F20: Avg payout
B21: 1 | C21: 0.135 | D21: =+SUM($C$21:C21) -> 0.135 | E21: =+Summary!K36 -> 2 | F21: =+C21*E21 -> 0.27
B22: 2 | C22: 0.02 | D22: =+SUM($C$21:C22) -> 0.155 | E22: =+Summary!K37 -> 5 | F22: =+C22*E22 -> 0.1
B23: 3 | C23: 0.003 | D23: =+SUM($C$21:C23) -> 0.158 | E23: =+Summary!K38 -> 10 | F23: =+C23*E23 -> 0.03
B24: 4 | C24: 0.002 | D24: =+SUM($C$21:C24) -> 0.16 | E24: =+Summary!K39 -> 15 | F24: =+C24*E24 -> 0.03
B25: 5 | C25: 0.001 | D25: =+SUM($C$21:C25) -> 0.161 | E25: =+Summary!K40 -> 20 | F25: =+C25*E25 -> 0.02
B26: 6 | C26: 0.001 | D26: =+SUM($C$21:C26) -> 0.162 | E26: =+Summary!K41 -> 50 | F26: =+C26*E26 -> 0.05
B27: 7 | C27: 0.007 | D27: =+SUM($C$21:C27) -> 0.169 | E27: =+Summary!K42 -> 100 | F27: =+C27*E27 -> 0.7 | G27: (*) Enemy killed
B28: Total (*) | C28: =+SUM(C21:C27) -> 0.169 | F28: =+SUM(F21:F27) -> 1.2
B29: (*) Total probability is hit rate
A32: Table 3 | B32: Prize # | C32: Probability | D32: Cumulative prob. | E32: Award | F32: Avg payout
B33: 1 | C33: 0.085 | D33: =+SUM($C$33:C33) -> 0.085 | E33: =+Summary!K36 -> 2 | F33: =+C33*E33 -> 0.17
B34: 2 | C34: 0.004 | D34: =+SUM($C$33:C34) -> 0.089 | E34: =+Summary!K37 -> 5 | F34: =+C34*E34 -> 0.02
B35: 3 | C35: 0.001 | D35: =+SUM($C$33:C35) -> 0.09 | E35: =+Summary!K38 -> 10 | F35: =+C35*E35 -> 0.01
B36: 4 | C36: 0.002 | D36: =+SUM($C$33:C36) -> 0.092 | E36: =+Summary!K39 -> 15 | F36: =+C36*E36 -> 0.03
B37: 5 | C37: 0.001 | D37: =+SUM($C$33:C37) -> 0.093 | E37: =+Summary!K40 -> 20 | F37: =+C37*E37 -> 0.02
B38: 6 | C38: 0.001 | D38: =+SUM($C$33:C38) -> 0.094 | E38: =+Summary!K41 -> 50 | F38: =+C38*E38 -> 0.05
B39: 7 | C39: 0.009 | D39: =+SUM($C$33:C39) -> 0.103 | E39: =+Summary!K42 -> 100 | F39: =+C39*E39 -> 0.9 | G39: (*) Enemy killed
B40: Total (*) | C40: =+SUM(C33:C39) -> 0.103 | F40: =+SUM(F33:F39) -> 1.2
B41: (*) Total probability is hit rate
A44: Table 4 | B44: Prize # | C44: Probability | D44: Cumulative prob. | E44: Award | F44: Avg payout
B45: 1 | C45: 0.075 | D45: =+SUM($C$45:C45) -> 0.075 | E45: =+Summary!K36 -> 2 | F45: =+C45*E45 -> 0.15
B46: 2 | C46: 0.001 | D46: =+SUM($C$45:C46) -> 0.076 | E46: =+Summary!K37 -> 5 | F46: =+C46*E46 -> 0.005
B47: 3 | C47: 0.001 | D47: =+SUM($C$45:C47) -> 0.077 | E47: =+Summary!K38 -> 10 | F47: =+C47*E47 -> 0.01
B48: 4 | C48: 0.001 | D48: =+SUM($C$45:C48) -> 0.078 | E48: =+Summary!K39 -> 15 | F48: =+C48*E48 -> 0.015
B49: 5 | C49: 0.0005 | D49: =+SUM($C$45:C49) -> 0.0785 | E49: =+Summary!K40 -> 20 | F49: =+C49*E49 -> 0.01
...

Sheet Special weapon 2 (HV scarab)
A1: SPECIAL WEAPON 2 - High Volatility Scarab
A2: For each shot with a regular weapon, draw the damage caused using the tables below.
A3: Start using table 1 and every 100 shots received change to the following table.
A4: Note: The probability of defeating the enemy increases from one table to next table (the enemy gets weaker every 100 shots received)
A8: Table 1 | B8: Prize # | C8: Probability | D8: Cumulative prob. | E8: Award | F8: Avg payout
B9: 1 | C9: 0.13 | D9: =+SUM($C$9:C9) -> 0.13 | E9: =+Summary!K36 -> 2 | F9: =+C9*E9 -> 0.26
B10: 2 | C10: 0.035 | D10: =+SUM($C$9:C10) -> 0.165 | E10: =+Summary!K37 -> 5 | F10: =+C10*E10 -> 0.175
B11: 3 | C11: 0.006 | D11: =+SUM($C$9:C11) -> 0.171 | E11: =+Summary!K38 -> 10 | F11: =+C11*E11 -> 0.06
B12: 4 | C12: 0.005 | D12: =+SUM($C$9:C12) -> 0.176 | E12: =+Summary!K39 -> 15 | F12: =+C12*E12 -> 0.075
B13: 5 | C13: 0.004 | D13: =+SUM($C$9:C13) -> 0.18 | E13: =+Summary!K40 -> 20 | F13: =+C13*E13 -> 0.08
B14: 6 | C14: 0.002 | D14: =+SUM($C$9:C14) -> 0.182 | E14: =+Summary!K41 -> 50 | F14: =+C14*E14 -> 0.1
B15: 7 | C15: 0.003 | D15: =+SUM($C$9:C15) -> 0.185 | E15: =+Summary!K42 -> 100 | F15: =+C15*E15 -> 0.3 | G15: (*) Enemy killed
B16: Total (*) | C16: =+SUM(C9:C15) -> 0.185 | F16: =+SUM(F9:F15) -> 1.05
B17: (*) Total probability is hit rate
A20: Table 2 | B20: Prize # | C20: Probability | D20: Cumulative prob. | E20: Award | F20: Avg payout
B21: 1 | C21: 0.11 | D21: =+SUM($C$21:C21) -> 0.11 | E21: =+Summary!K36 -> 2 | F21: =+C21*E21 -> 0.22
B22: 2 | C22: 0.03 | D22: =+SUM($C$21:C22) -> 0.14 | E22: =+Summary!K37 -> 5 | F22: =+C22*E22 -> 0.15
B23: 3 | C23: 0.004 | D23: =+SUM($C$21:C23) -> 0.144 | E23: =+Summary!K38 -> 10 | F23: =+C23*E23 -> 0.04
B24: 4 | C24: 0.002 | D24: =+SUM($C$21:C24) -> 0.146 | E24: =+Summary!K39 -> 15 | F24: =+C24*E24 -> 0.03
B25: 5 | C25: 0.003 | D25: =+SUM($C$21:C25) -> 0.149 | E25: =+Summary!K40 -> 20 | F25: =+C25*E25 -> 0.06
B26: 6 | C26: 0.001 | D26: =+SUM($C$21:C26) -> 0.15 | E26: =+Summary!K41 -> 50 | F26: =+C26*E26 -> 0.05
B27: 7 | C27: 0.005 | D27: =+SUM($C$21:C27) -> 0.155 | E27: =+Summary!K42 -> 100 | F27: =+C27*E27 -> 0.5 | G27: (*) Enemy killed
B28: Total (*) | C28: =+SUM(C21:C27) -> 0.155 | F28: =+SUM(F21:F27) -> 1.05
B29: (*) Total probability is hit rate
A32: Table 3 | B32: Prize # | C32: Probability | D32: Cumulative prob. | E32: Award | F32: Avg payout
B33: 1 | C33: 0.065 | D33: =+SUM($C$33:C33) -> 0.065 | E33: =+Summary!K36 -> 2 | F33: =+C33*E33 -> 0.13
B34: 2 | C34: 0.02 | D34: =+SUM($C$33:C34) -> 0.085 | E34: =+Summary!K37 -> 5 | F34: =+C34*E34 -> 0.1
B35: 3 | C35: 0.002 | D35: =+SUM($C$33:C35) -> 0.087 | E35: =+Summary!K38 -> 10 | F35: =+C35*E35 -> 0.02
B36: 4 | C36: 0.002 | D36: =+SUM($C$33:C36) -> 0.089 | E36: =+Summary!K39 -> 15 | F36: =+C36*E36 -> 0.03
B37: 5 | C37: 0.001 | D37: =+SUM($C$33:C37) -> 0.09 | E37: =+Summary!K40 -> 20 | F37: =+C37*E37 -> 0.02
B38: 6 | C38: 0.001 | D38: =+SUM($C$33:C38) -> 0.091 | E38: =+Summary!K41 -> 50 | F38: =+C38*E38 -> 0.05
B39: 7 | C39: 0.007 | D39: =+SUM($C$33:C39) -> 0.098 | E39: =+Summary!K42 -> 100 | F39: =+C39*E39 -> 0.7 | G39: (*) Enemy killed
B40: Total (*) | C40: =+SUM(C33:C39) -> 0.098 | F40: =+SUM(F33:F39) -> 1.05
B41: (*) Total probability is hit rate
A44: Table 4 | B44: Prize # | C44: Probability | D44: Cumulative prob. | E44: Award | F44: Avg payout
B45: 1 | C45: 0.05 | D45: =+SUM($C$45:C45) -> 0.05 | E45: =+Summary!K36 -> 2 | F45: =+C45*E45 -> 0.1
B46: 2 | C46: 0.001 | D46: =+SUM($C$45:C46) -> 0.051 | E46: =+Summary!K37 -> 5 | F46: =+C46*E46 -> 0.005
B47: 3 | C47: 0.001 | D47: =+SUM($C$45:C47) -> 0.052 | E47: =+Summary!K38 -> 10 | F47: =+C47*E47 -> 0.01
B48: 4 | C48: 0.001 | D48: =+SUM($C$45:C48) -> 0.053 | E48: =+Summary!K39 -> 15 | F48: =+C48*E48 -> 0.015
B49: 5 | C49: 0.001 | D49: =+SUM($C$45:C49) -> 0.054 | E49: =+Summary!K40 -> 20 | F49: =+C49*E49 -> 0.02
...

Sheet Special weapon 3 (HV scarab)
A1: SPECIAL WEAPON 3 - High Volatility Scarab
A2: For each shot with a regular weapon, draw the damage caused using the tables below.
A3: Start using table 1 and every 100 shots received change to the following table.
A4: Note: The probability of defeating the enemy increases from one table to next table (the enemy gets weaker every 100 shots received)
A8: Table 1 | B8: Prize # | C8: Probability | D8: Cumulative prob. | E8: Award | F8: Avg payout
B9: 1 | C9: 0.12 | D9: =+SUM($C$9:C9) -> 0.12 | E9: =+Summary!K36 -> 2 | F9: =+C9*E9 -> 0.24
B10: 2 | C10: 0.04 | D10: =+SUM($C$9:C10) -> 0.16 | E10: =+Summary!K37 -> 5 | F10: =+C10*E10 -> 0.2
B11: 3 | C11: 0.006 | D11: =+SUM($C$9:C11) -> 0.166 | E11: =+Summary!K38 -> 10 | F11: =+C11*E11 -> 0.06
B12: 4 | C12: 0.004 | D12: =+SUM($C$9:C12) -> 0.17 | E12: =+Summary!K39 -> 15 | F12: =+C12*E12 -> 0.06
B13: 5 | C13: 0.002 | D13: =+SUM($C$9:C13) -> 0.172 | E13: =+Summary!K40 -> 20 | F13: =+C13*E13 -> 0.04
B14: 6 | C14: 0.002 | D14: =+SUM($C$9:C14) -> 0.174 | E14: =+Summary!K41 -> 50 | F14: =+C14*E14 -> 0.1
B15: 7 | C15: 0.002 | D15: =+SUM($C$9:C15) -> 0.176 | E15: =+Summary!K42 -> 100 | F15: =+C15*E15 -> 0.2 | G15: (*) Enemy killed
B16: Total (*) | C16: =+SUM(C9:C15) -> 0.176 | F16: =+SUM(F9:F15) -> 0.9
B17: (*) Total probability is hit rate
A20: Table 2 | B20: Prize # | C20: Probability | D20: Cumulative prob. | E20: Award | F20: Avg payout
B21: 1 | C21: 0.09 | D21: =+SUM($C$21:C21) -> 0.09 | E21: =+Summary!K36 -> 2 | F21: =+C21*E21 -> 0.18
B22: 2 | C22: 0.032 | D22: =+SUM($C$21:C22) -> 0.122 | E22: =+Summary!K37 -> 5 | F22: =+C22*E22 -> 0.16
B23: 3 | C23: 0.004 | D23: =+SUM($C$21:C23) -> 0.126 | E23: =+Summary!K38 -> 10 | F23: =+C23*E23 -> 0.04
B24: 4 | C24: 0.002 | D24: =+SUM($C$21:C24) -> 0.128 | E24: =+Summary!K39 -> 15 | F24: =+C24*E24 -> 0.03
B25: 5 | C25: 0.002 | D25: =+SUM($C$21:C25) -> 0.13 | E25: =+Summary!K40 -> 20 | F25: =+C25*E25 -> 0.04
B26: 6 | C26: 0.001 | D26: =+SUM($C$21:C26) -> 0.131 | E26: =+Summary!K41 -> 50 | F26: =+C26*E26 -> 0.05
B27: 7 | C27: 0.004 | D27: =+SUM($C$21:C27) -> 0.135 | E27: =+Summary!K42 -> 100 | F27: =+C27*E27 -> 0.4 | G27: (*) Enemy killed
B28: Total (*) | C28: =+SUM(C21:C27) -> 0.135 | F28: =+SUM(F21:F27) -> 0.9
B29: (*) Total probability is hit rate
A32: Table 3 | B32: Prize # | C32: Probability | D32: Cumulative prob. | E32: Award | F32: Avg payout
B33: 1 | C33: 0.07 | D33: =+SUM($C$33:C33) -> 0.07 | E33: =+Summary!K36 -> 2 | F33: =+C33*E33 -> 0.14
B34: 2 | C34: 0.02 | D34: =+SUM($C$33:C34) -> 0.09 | E34: =+Summary!K37 -> 5 | F34: =+C34*E34 -> 0.1
B35: 3 | C35: 0.001 | D35: =+SUM($C$33:C35) -> 0.091 | E35: =+Summary!K38 -> 10 | F35: =+C35*E35 -> 0.01
B36: 4 | C36: 0.002 | D36: =+SUM($C$33:C36) -> 0.093 | E36: =+Summary!K39 -> 15 | F36: =+C36*E36 -> 0.03
B37: 5 | C37: 0.001 | D37: =+SUM($C$33:C37) -> 0.094 | E37: =+Summary!K40 -> 20 | F37: =+C37*E37 -> 0.02
B38: 6 | C38: 0 | D38: =+SUM($C$33:C38) -> 0.094 | E38: =+Summary!K41 -> 50 | F38: =+C38*E38 -> 0
B39: 7 | C39: 0.006 | D39: =+SUM($C$33:C39) -> 0.1 | E39: =+Summary!K42 -> 100 | F39: =+C39*E39 -> 0.6 | G39: (*) Enemy killed
B40: Total (*) | C40: =+SUM(C33:C39) -> 0.1 | F40: =+SUM(F33:F39) -> 0.9
B41: (*) Total probability is hit rate
A44: Table 4 | B44: Prize # | C44: Probability | D44: Cumulative prob. | E44: Award | F44: Avg payout
B45: 1 | C45: 0.075 | D45: =+SUM($C$45:C45) -> 0.075 | E45: =+Summary!K36 -> 2 | F45: =+C45*E45 -> 0.15
B46: 2 | C46: 0.001 | D46: =+SUM($C$45:C46) -> 0.076 | E46: =+Summary!K37 -> 5 | F46: =+C46*E46 -> 0.005
B47: 3 | C47: 0.001 | D47: =+SUM($C$45:C47) -> 0.077 | E47: =+Summary!K38 -> 10 | F47: =+C47*E47 -> 0.01
B48: 4 | C48: 0.001 | D48: =+SUM($C$45:C48) -> 0.078 | E48: =+Summary!K39 -> 15 | F48: =+C48*E48 -> 0.015
B49: 5 | C49: 0.001 | D49: =+SUM($C$45:C49) -> 0.079 | E49: =+Summary!K40 -> 20 | F49: =+C49*E49 -> 0.02
...

Sheet Plasma Gun (HV scarab)
A1: SPECIAL WEAPON 3 - High Volatility Scarab
A2: For each shot with a regular weapon, draw the damage caused using the tables below.
A3: Start using table 1 and every 100 shots received change to the following table.
A4: Note: The probability of defeating the enemy increases from one table to next table (the enemy gets weaker every 100 shots received)
A8: Table 1 | B8: Prize # | C8: Probability | D8: Cumulative prob. | E8: Award | F8: Avg payout
B9: 1 | C9: 0.3 | D9: =+SUM($C$9:C9) -> 0.3 | E9: =+Summary!K36 -> 2 | F9: =+C9*E9 -> 0.6
B10: 2 | C10: 0.1 | D10: =+SUM($C$9:C10) -> 0.4 | E10: =+Summary!K37 -> 5 | F10: =+C10*E10 -> 0.5
B11: 3 | C11: 0.04 | D11: =+SUM($C$9:C11) -> 0.44 | E11: =+Summary!K38 -> 10 | F11: =+C11*E11 -> 0.4
B12: 4 | C12: 0.1 | D12: =+SUM($C$9:C12) -> 0.54 | E12: =+Summary!K39 -> 15 | F12: =+C12*E12 -> 1.5
B13: 5 | C13: 0.05 | D13: =+SUM($C$9:C13) -> 0.59 | E13: =+Summary!K40 -> 20 | F13: =+C13*E13 -> 1
B14: 6 | C14: 0.02 | D14: =+SUM($C$9:C14) -> 0.61 | E14: =+Summary!K41 -> 50 | F14: =+C14*E14 -> 1
B15: 7 | C15: 0.1 | D15: =+SUM($C$9:C15) -> 0.71 | E15: =+Summary!K42 -> 100 | F15: =+C15*E15 -> 10 | G15: (*) Enemy killed
B16: Total (*) | C16: =+SUM(C9:C15) -> 0.71 | F16: =+SUM(F9:F15) -> 15
B17: (*) Total probability is hit rate
A20: Table 2 | B20: Prize # | C20: Probability | D20: Cumulative prob. | E20: Award | F20: Avg payout
B21: 1 | C21: 0.3 | D21: =+SUM($C$21:C21) -> 0.3 | E21: =+Summary!K36 -> 2 | F21: =+C21*E21 -> 0.6
B22: 2 | C22: 0.08 | D22: =+SUM($C$21:C22) -> 0.38 | E22: =+Summary!K37 -> 5 | F22: =+C22*E22 -> 0.4
B23: 3 | C23: 0.1 | D23: =+SUM($C$21:C23) -> 0.48 | E23: =+Summary!K38 -> 10 | F23: =+C23*E23 -> 1
B24: 4 | C24: 0.02 | D24: =+SUM($C$21:C24) -> 0.5 | E24: =+Summary!K39 -> 15 | F24: =+C24*E24 -> 0.3
B25: 5 | C25: 0.01 | D25: =+SUM($C$21:C25) -> 0.51 | E25: =+Summary!K40 -> 20 | F25: =+C25*E25 -> 0.2
B26: 6 | C26: 0.03 | D26: =+SUM($C$21:C26) -> 0.54 | E26: =+Summary!K41 -> 50 | F26: =+C26*E26 -> 1.5
B27: 7 | C27: 0.11 | D27: =+SUM($C$21:C27) -> 0.65 | E27: =+Summary!K42 -> 100 | F27: =+C27*E27 -> 11 | G27: (*) Enemy killed
B28: Total (*) | C28: =+SUM(C21:C27) -> 0.65 | F28: =+SUM(F21:F27) -> 15
B29: (*) Total probability is hit rate
A32: Table 3 | B32: Prize # | C32: Probability | D32: Cumulative prob. | E32: Award | F32: Avg payout
B33: 1 | C33: 0.2 | D33: =+SUM($C$33:C33) -> 0.2 | E33: =+Summary!K36 -> 2 | F33: =+C33*E33 -> 0.4
B34: 2 | C34: 0.14 | D34: =+SUM($C$33:C34) -> 0.34 | E34: =+Summary!K37 -> 5 | F34: =+C34*E34 -> 0.7
B35: 3 | C35: 0.05 | D35: =+SUM($C$33:C35) -> 0.39 | E35: =+Summary!K38 -> 10 | F35: =+C35*E35 -> 0.5
B36: 4 | C36: 0.02 | D36: =+SUM($C$33:C36) -> 0.41 | E36: =+Summary!K39 -> 15 | F36: =+C36*E36 -> 0.3
B37: 5 | C37: 0.03 | D37: =+SUM($C$33:C37) -> 0.44 | E37: =+Summary!K40 -> 20 | F37: =+C37*E37 -> 0.6
B38: 6 | C38: 0.01 | D38: =+SUM($C$33:C38) -> 0.45 | E38: =+Summary!K41 -> 50 | F38: =+C38*E38 -> 0.5
B39: 7 | C39: 0.12 | D39: =+SUM($C$33:C39) -> 0.57 | E39: =+Summary!K42 -> 100 | F39: =+C39*E39 -> 12 | G39: (*) Enemy killed
B40: Total (*) | C40: =+SUM(C33:C39) -> 0.57 | F40: =+SUM(F33:F39) -> 15
B41: (*) Total probability is hit rate
A44: Table 4 | B44: Prize # | C44: Probability | D44: Cumulative prob. | E44: Award | F44: Avg payout
B45: 1 | C45: 0.1 | D45: =+SUM($C$45:C45) -> 0.1 | E45: =+Summary!K36 -> 2 | F45: =+C45*E45 -> 0.2
B46: 2 | C46: 0.08 | D46: =+SUM($C$45:C46) -> 0.18 | E46: =+Summary!K37 -> 5 | F46: =+C46*E46 -> 0.4
B47: 3 | C47: 0.1 | D47: =+SUM($C$45:C47) -> 0.28 | E47: =+Summary!K38 -> 10 | F47: =+C47*E47 -> 1
B48: 4 | C48: 0.01 | D48: =+SUM($C$45:C48) -> 0.29 | E48: =+Summary!K39 -> 15 | F48: =+C48*E48 -> 0.15
B49: 5 | C49: 0.01 | D49: =+SUM($C$45:C49) -> 0.3 | E49: =+Summary!K40 -> 20 | F49: =+C49*E49 -> 0.2
...

Sheet Summary
A1: Notes: the number of enemies of each type in each location is irrelevant from the mathematical point of view.
A2: If locations act as "levels", it may be interesting to have weak enemies in the first location and add other species in the following locations.
A5: Feature | B5: RTP | C5: Freq | D5: Probability | E5: Max avg pay | F5: Min avg pay | G5: Min RTP
A6: Base game | B6: 0.655 | G6: 0.655
A7: Boss round | B7: 0.2 | C7: 500 | D7: =1/C7 -> 0.002 | E7: =+C7*B7 -> 100 | F7: 100 | G7: 0.2 | H7: Prize: 80x to be distributed between players according to total bet during triggering round
A8: Special weapon (*) | B8: =1/C8*E8 -> 0.1 | C8: 60 | D8: =1/C8 -> 0.016666667 | E8: =+'Special weapon'!D14 -> 6 | F8: =+'Special weapon'!D41 -> 3.8163043 | G8: =1/C8*F8 -> 0.063605072
A9: Leaderboard | B9: 0.02 | G9: 0.02
A10: Jackpot | B10: 0 | G10: 0
A11: Total | B11: =+SUM(B6:B10) -> 0.975 | G11: =+SUM(G6:G10) -> 0.93860507
A12: (*) To use in MAIN only. Shots using special weapons are not paid. Each special weapon has a limited number of shots and could be used any time in base game.
A13: When a player gets a GUARANTEE KNOCKOUT he/she can use it only in base game and optimal strategy is to kill a Powerful Pharaoh Mummy with no damage or a HV enemy. The prize is x15 (see table below)
A14: If player uses the special weapon in other case (imperfect play) then he/she will get a prize lower than x15.
A16: There are different kind of enemies. Each enemy has its own prizes. Stronger enemies grant bigger prizes but are more difficult to kill.
A19: Scarab black | D19: Scarab gold | G19: Scarab gem covered
A20: Prize # | B20: Pays | D20: Prize # | E20: Pays | G20: Prize # | H20: Pays
A21: 1 | B21: 2 | D21: 1 | E21: 5 | G21: 1 | H21: 8
A25: Standard Mummy | D25: Medium Mummy A | G25: Medium Mummy B | J25: Medium Mummy C
A26: Prize | B26: Pays | D26: Prize # | E26: Pays | G26: Prize # | H26: Pays | J26: Prize # | K26: Pays
A27: 1 | B27: 3 | D27: 2 | E27: 5 | G27: 1 | H27: 5 | J27: 1 | K27: 5
A28: 2 | B28: 5 | D28: 3 | E28: 10 | G28: 2 | H28: 10 | J28: 2 | K28: 12
A29: Total | B29: =+SUM(B27:B28) -> 8 | D29: Total | E29: =+SUM(E27:E28) -> 15 | G29: 3 | H29: 15 | J29: 3 | K29: 18
G30: Total | H30: =+SUM(H27:H29) -> 30 | J30: Total | K30: =+SUM(K27:K29) -> 35
A34: Powerful Pharaoh Mummy A | D34: Powerful Pharaoh Mummy B | G34: High Volatility enemy | J34: High Volatility Scarab
A35: Prize # | B35: Pays | D35: Prize # | E35: Pays | G35: Prize # | H35: Pays | J35: Prize # | K35: Pays
A36: 1 | B36: 7 | D36: 1 | E36: 7 | G36: 1 | H36: 2 | J36: 1 | K36: 2
A37: 2 | B37: 15 | D37: 2 | E37: 15 | G37: 2 | H37: 5 | J37: 2 | K37: 5
A38: 3 | B38: 20 | D38: 3 | E38: 20 | G38: 3 | H38: 10 | J38: 3 | K38: 10
A39: Total | B39: =+SUM(B36:B38) -> 42 | D39: Total | E39: =+SUM(E36:E38) -> 42 | G39: 4 | H39: 20 | J39: 4 | K39: 15
G40: 5 | H40: 50 | J40: 5 | K40: 20
G41: 6 | H41: 100 | J41: 6 | K41: 50
G42: 7 | H42: 500 | J42: 7 | K42: 100

Sheet Boss round (1,2,or 3 players)
A1: Environmental Boss round
A2: As each shot to boss is a bet, the RTP for this bet should be the same as base game (95.5%) to avoid player's strategies.
A3: But players are also competing by the Boss prize (100x) which will be distributed according to damage done by each player (or bot).
A4: So, each shot can grant an extra prize (Table 1) and cause a damage. The RTP of these shots will be 95.5% plus the RTP from Boss prize.
A5: Extra prizes can be inmediately granted to players or they can be accumulate and granted at the end of the round added to the part of the Boss prize.
A6: For each shot, draw an extra prize (Table 1) and boss damage (Table 2 and 3 corrected by player's bet). They are independent events.
A8: Extra prize
A10: Table 1 | B10: Prize | C10: Probability | D10: Cumulative prob. | E10: RTP
B11: 5 | C11: 0.083 | D11: =+SUM(C$10:$C11) -> 0.083 | E11: =+B11*C11 -> 0.415
B12: 10 | C12: 0.031 | D12: =+SUM(C$10:$C12) -> 0.114 | E12: =+B12*C12 -> 0.31
B13: 15 | C13: 0.008 | D13: =+SUM(C$10:$C13) -> 0.122 | E13: =+B13*C13 -> 0.12
B14: 20 | C14: 0.001 | D14: =+SUM(C$10:$C14) -> 0.123 | E14: =+B14*C14 -> 0.02
B15: 50 | C15: 0.001 | D15: =+SUM(C$10:$C15) -> 0.124 | E15: =+B15*C15 -> 0.05
B16: 100 | C16: 0.0004 | D16: =+SUM(C$10:$C16) -> 0.1244 | E16: =+B16*C16 -> 0.04
B17: Total (*) | C17: =+SUM(C11:C16) -> 0.1244 | E17: =+SUM(E11:E16) -> 0.955
A20: Boss damage
A22: Boss energy: | B22: =+Summary!E7 -> 100
A23: The total Boss prize must return to players. The part of this prize won by bots will be added to Leaderboard prizes.
A24: Each energy unit is equivalent to the stake that has triggered the boss round. The boss prize is 100 times the stake that has triggered the boss round (in the same currency).
A25: If player A has caused a damage of 15 energy units then player wins a prize of 15 times the triggering stake (it probably needs to be converted to player's currency) plus the extra prizes (in player currency).
A26: Players who have bet the most are likely to win the most. So, probabilities are proportional to player's total bet in the base game previous to Boss round.
A27: For each player the probabilities in the table below must be multiplied by player's total bet in base game previous to Boss round and divided by total bet in base game previous to Boss round.
A28: Probability factor correction (PFC): player's bet divided by total bet
A31: Table 2 | B31: Damage | C31: Probability Base line | D31: RTP
B32: 1 | C32: 0.02 | D32: =+B32*C32 -> 0.02
B33: 2 | C33: 0.03 | D33: =+B33*C33 -> 0.06
B34: 3 | C34: 0.05 | D34: =+B34*C34 -> 0.15
B35: 4 | C35: 0.08 | D35: =+B35*C35 -> 0.32
B36: 5 | C36: 0.05 | D36: =+B36*C36 -> 0.25
B37: Total | C37: =+SUM(C32:C36) -> 0.23 | D37: =+SUM(D32:D36) -> 0.8 | E37: <- this RTP is distributed between players
A39: When Boss energy is less than 5 some damage levels are not possible, in that case each player can only cause a damage of 1 unit with this probability:
A41: Table 3 | B41: Damage | C41: Probability Base line | D41: RTP
B42: 1 | C42: 0.8 | D42: =+C42*B42 -> 0.8
B43: Total | C43: =+SUM(C42) -> 0.8 | D43: =+D42 -> 0.8
A45: Example:
A46: Player 1 has bet 25 EUR in base game.
A47: Player 2 has bet 50 EUR in base game.
A48: Total bet: 25+50 = 75
A50: If Boss energy is at least 5 units the probabilities of damages are:
B52: Player 1 | C52: PFC= 25/75
...

Sheet Boss round (4 or more players)
A1: Environmental Boss round
A2: As each shot to boss is a bet, the RTP for this bet should be the same as base game (95.5%) to avoid player's strategies.
A3: But players are also competing by the Boss prize (100x) which will be distributed according to damage done by each player (or bot).
A4: So, each shot can grant an extra prize (Table 1) and cause a damage. The RTP of these shots will be 95.5% plus the RTP from Boss prize.
A5: Extra prizes can be inmediately granted to players or they can be accumulate and granted at the end of the round added to the part of the Boss prize.
A6: For each shot, draw an extra prize (Table 1) and boss damage (Table 2 and 3 corrected by player's bet). They are independent events.
A8: Extra prize
A10: Table 1 | B10: Prize | C10: Probability | D10: Cumulative prob. | E10: RTP
B11: 5 | C11: 0.083 | D11: =+SUM(C$10:$C11) -> 0.083 | E11: =+B11*C11 -> 0.415
B12: 10 | C12: 0.031 | D12: =+SUM(C$10:$C12) -> 0.114 | E12: =+B12*C12 -> 0.31
B13: 15 | C13: 0.008 | D13: =+SUM(C$10:$C13) -> 0.122 | E13: =+B13*C13 -> 0.12
B14: 20 | C14: 0.001 | D14: =+SUM(C$10:$C14) -> 0.123 | E14: =+B14*C14 -> 0.02
B15: 50 | C15: 0.001 | D15: =+SUM(C$10:$C15) -> 0.124 | E15: =+B15*C15 -> 0.05
B16: 100 | C16: 0.0004 | D16: =+SUM(C$10:$C16) -> 0.1244 | E16: =+B16*C16 -> 0.04
B17: Total (*) | C17: =+SUM(C11:C16) -> 0.1244 | E17: =+SUM(E11:E16) -> 0.955
A20: Boss damage
A22: Boss energy: | B22: =+Summary!E7 -> 100
A23: The total Boss prize must return to players. The part of this prize won by bots will be added to Leaderboard prizes.
A24: Each energy unit is equivalent to the stake that has triggered the boss round. The boss prize is 100 times the stake that has triggered the boss round (in the same currency).
A25: If player A has caused a damage of 15 energy units then player wins a prize of 15 times the triggering stake (it probably needs to be converted to player's currency) plus the extra prizes (in player currency).
A26: Players who have bet the most are likely to win the most. So, probabilities are proportional to player's total bet in the base game previous to Boss round.
A27: For each player the probabilities in the table below must be multiplied by player's total bet in base game previous to Boss round and divided by total bet in base game previous to Boss round.
A28: Probability factor correction (PFC): player's bet divided by total bet
A31: Table 2 | B31: Damage | C31: Probability Base line | D31: RTP
B32: 1 | C32: 0.01 | D32: =+B32*C32 -> 0.01
B33: 2 | C33: 0.01 | D33: =+B33*C33 -> 0.02
B34: 3 | C34: 0.01 | D34: =+B34*C34 -> 0.03
B35: 4 | C35: 0.01 | D35: =+B35*C35 -> 0.04
B36: 5 | C36: 0.01 | D36: =+B36*C36 -> 0.05
B37: Total | C37: =+SUM(C32:C36) -> 0.05 | D37: =+SUM(D32:D36) -> 0.15 | E37: <- this RTP is distributed between players
A39: When Boss energy is less than 5 some damage levels are not possible, in that case each player can only cause a damage of 1 unit with this probability:
A41: Table 3 | B41: Damage | C41: Probability Base line | D41: RTP
B42: 1 | C42: 0.15 | D42: =+C42*B42 -> 0.15
B43: Total | C43: =+SUM(C42) -> 0.15 | D43: =+D42 -> 0.15
A45: Example:
A46: Player 1 has bet 25 EUR in base game.
A47: Player 2 has bet 50 EUR in base game.
A48: Total bet: 25+50 = 75
A50: If Boss energy is at least 5 units the probabilities of damages are:
B52: Player 1 | C52: PFC= 25/75
...

Sheet Special weapon
A1: For each shot in base game with a regular weapon draw if player gets a special weapon or not. Except shots at High Volatility Enemy and High Volatility Scarab.
A2: Probability of getting a special weapon = 1/60
A3: If player gets a special weapon then draw which one he gets using the weights in the table below.
A6: Special weapons can be use anytime in base game only.
A8: Special weapons: | B8: Shots | C8: Avg pay by shot | D8: Total avg pay | E8: Weights
A9: Special weapon 1 | B9: 4 | C9: 1.2 | D9: =+B9*C9 -> 4.8 | E9: 20
A10: Special weapon 2 | B10: 5 | C10: 1.05 | D10: =+B10*C10 -> 5.25 | E10: 16
A11: Special weapon 3 | B11: 10 | C11: 0.9 | D11: =+B11*C11 -> 9 | E11: 9
A12: Guarantee knockout (*) | B12: 1 | C12: 15 | D12: =+B12*C12 -> 15 | E12: 1 | F12: (*) best strategy
A13: (*) avg pay using best strategy
C14: Avg win | D14: =+SUMPRODUCT(D9:D12,E9:E12)/SUM(E9:E12) -> 6
A16: Each special weapon has its own probabilities of damage for each kind of enemy. Prizes must be multiplied by the stake that triggered the feature.
A17: For instance, if player gets a special weapon betting 100 credits, at the moment he decides to use it the prizes must be multiplied by 100. It doesn’t matter if after getting the special weapon he changed the stake.
A20: Special weapons description
A21: Special weapon 1: double barrelled shotgun
A23: Special weapon 2: 1 bomb hitting 5 times.
A24: When the bomb is thrown hit the nearest enemy (i.e. draw the damage according to tables for special weapon 2), if that enemy is not defeated then hit him one more time, else hit the following nearest enemy. Repeat 3 more times (total: 5 "shots").
A25: Algorithmically is a sequential process but graphically it is shown as everything ocurring at the same moment.
A26: Alternative: when the bomb is thrown hit the 5 nearest enemies (i.e. draw the damage according to tables for special weapon 2 once for each enemy).
A28: Special weapon 3: every time a player gets special weapon 3 choose at random between a Chain gun or Ricochet.
A29: Chain Gun: 10 shots but each shot can be shown as a burst of several bullets. For example, each shot can be replaced by one burst of 10 bullets and this corresponds to only one draw using the probabilities of the tables.
A30: Ricochet: 5 shots but each shot bounces hitting a second enemy. The second enemy is chosen at random and it is not necessary the same kind of enemy that the player aimed.
A33: Worst strategy
A34: Special weapons: | B34: Shots | C34: Avg pay by shot | D34: Total avg pay | E34: Probability
A35: Special weapon 1 | B35: 4 | C35: 1.2 | D35: =+B35*C35 -> 4.8 | E35: =+E9/SUM($E$9:$E$12) -> 0.43478261
A36: Special weapon 2 | B36: 1 | C36: 1.05 | D36: =+B36*C36 -> 1.05 | E36: =+E10/SUM($E$9:$E$12) -> 0.34782609 | F36: (*) worst strategy is to shoot when there is only one enemy on screen. In this case 4 shots are wasted.
A37: Special weapon 3 (Chain gun) | B37: 10 | C37: 0.9 | D37: =+B37*C37 -> 9 | E37: =+E11/SUM($E$9:$E$12)*1/2 -> 0.097826087
A38: Special weapon 3 (Ricochet) (**) | B38: 5 | C38: 0.9 | D38: =+B38*C38 -> 4.5 | E38: =+E11/SUM($E$9:$E$12)*1/2 -> 0.097826087 | F38: (**) worst strategy is to shoot when there is only one enemy on screen. In this case every shot wastes the bounce shot.
A39: Guarantee knockout (***) | B39: 1 | C39: 2 | D39: =+B39*C39 -> 2 | E39: =+E12/SUM($E$9:$E$12) -> 0.02173913 | F39: (***) worst strategy is to use it agains an enemy paying only x2 (for example an scarab).
C41: Avg win | D41: =+SUMPRODUCT(D35:D39,E35:E39) -> 3.8163043

Sheet Prices Special weapon
A1: Player can buy special any special weapons, the price for each weapon is the table below.
A2: Special weapons can be use anytime in base game only.
A4: Crate price (credits) | B4: 20
A7: Crate content (random):
A9: Special weapons: | B9: Shots | C9: Avg pay by shot | D9: Total avg pay | E9: Weight | F9: Avg pay/price
A10: Special weapon 1 | B10: 8 | C10: 1.2 | D10: =+B10*C10 -> 9.6 | E10: 8 | F10: =+D10/$B$4 -> 0.48
A11: Special weapon 1 | B11: 12 | C11: 1.2 | D11: =+B11*C11 -> 14.4 | E11: 16 | F11: =+D11/$B$4 -> 0.72
A12: Special weapon 1 | B12: 16 | C12: 1.2 | D12: =+B12*C12 -> 19.2 | E12: 10 | F12: =+D12/$B$4 -> 0.96
A13: Special weapon 1 | B13: 20 | C13: 1.2 | D13: =+B13*C13 -> 24 | E13: 9 | F13: =+D13/$B$4 -> 1.2
A14: Special weapon 1 | B14: 80 | C14: 1.2 | D14: =+B14*C14 -> 96 | E14: 1 | F14: =+D14/$B$4 -> 4.8
A15: Special weapon 2 | B15: 10 | C15: 1.05 | D15: =+B15*C15 -> 10.5 | E15: 20 | F15: =+D15/$B$4 -> 0.525
A16: Special weapon 2 | B16: 15 | C16: 1.05 | D16: =+B16*C16 -> 15.75 | E16: 17 | F16: =+D16/$B$4 -> 0.7875
A17: Special weapon 2 | B17: 50 | C17: 1.05 | D17: =+B17*C17 -> 52.5 | E17: 2 | F17: =+D17/$B$4 -> 2.625
A18: Special weapon 3 | B18: 20 | C18: 0.9 | D18: =+B18*C18 -> 18 | E18: 10 | F18: =+D18/$B$4 -> 0.9
A19: Special weapon 3 | B19: 30 | C19: 0.9 | D19: =+B19*C19 -> 27 | E19: 4 | F19: =+D19/$B$4 -> 1.35
A20: Special weapon 3 | B20: 50 | C20: 0.9 | D20: =+B20*C20 -> 45 | E20: 2 | F20: =+D20/$B$4 -> 2.25
A21: Special weapon 3 | B21: 200 | C21: 0.9 | D21: =+B21*C21 -> 180 | E21: 1 | F21: =+D21/$B$4 -> 9
A22: Total | D22: =+SUMPRODUCT(D10:D21,E10:E21)/SUM(E10:E21) -> 19.5195 | E22: =+SUM(E10:E21) -> 100
A24: Total RTP: | B24: =+D22/B4 -> 0.975975
A26: In case of including Guranteed knockout in game please use the table below.
A27: Crate content including Guaranteed knockout (random):
A29: Special weapons: | B29: Shots | C29: Avg pay by shot | D29: Total avg pay | E29: Weight | F29: Avg pay/price
A30: Special weapon 1 | B30: 8 | C30: 1.2 | D30: =+B30*C30 -> 9.6 | E30: 10 | F30: =+D30/$B$4 -> 0.48
A31: Special weapon 1 | B31: 12 | C31: 1.2 | D31: =+B31*C31 -> 14.4 | E31: 20 | F31: =+D31/$B$4 -> 0.72
A32: Special weapon 1 | B32: 16 | C32: 1.2 | D32: =+B32*C32 -> 19.2 | E32: 10 | F32: =+D32/$B$4 -> 0.96
A33: Special weapon 1 | B33: 20 | C33: 1.2 | D33: =+B33*C33 -> 24 | E33: 10 | F33: =+D33/$B$4 -> 1.2
A34: Special weapon 1 | B34: 80 | C34: 1.2 | D34: =+B34*C34 -> 96 | E34: 1 | F34: =+D34/$B$4 -> 4.8
A35: Special weapon 2 | B35: 10 | C35: 1.05 | D35: =+B35*C35 -> 10.5 | E35: 25 | F35: =+D35/$B$4 -> 0.525
A36: Special weapon 2 | B36: 15 | C36: 1.05 | D36: =+B36*C36 -> 15.75 | E36: 17 | F36: =+D36/$B$4 -> 0.7875
A37: Special weapon 2 | B37: 50 | C37: 1.05 | D37: =+B37*C37 -> 52.5 | E37: 1 | F37: =+D37/$B$4 -> 2.625
A38: Special weapon 3 | B38: 20 | C38: 0.9 | D38: =+B38*C38 -> 18 | E38: 13 | F38: =+D38/$B$4 -> 0.9
A39: Special weapon 3 | B39: 30 | C39: 0.9 | D39: =+B39*C39 -> 27 | E39: 6 | F39: =+D39/$B$4 -> 1.35
A40: Special weapon 3 | B40: 50 | C40: 0.9 | D40: =+B40*C40 -> 45 | E40: 1 | F40: =+D40/$B$4 -> 2.25
A41: Special weapon 3 | B41: 200 | C41: 0.9 | D41: =+B41*C41 -> 180 | E41: 1 | F41: =+D41/$B$4 -> 9
... A44: Guaranteed knockout | B44: 5 | C44: 15 | D44: =+B44*C44 -> 75 | E44: 1 | F44: =+D44/$B$4 -> 3.75
A45: Total | D45: =+SUMPRODUCT(D30:D44,E30:E44)/SUM(E30:E44) -> 19.50625 | E45: =+SUM(E30:E44) -> 120
A47: Total RTP: | B47: =+D45/B4 -> 0.9753125

Sheet Base game (HV enemy)
A1: HIGH-Volatility Enemy
A2: For each shot with a regular weapon, draw the damage caused using the tables below.
A3: Start using table 1 and every 100 shots received change to the following table.
A4: Note: The probability of defeating the enemy increases from one table to next table (the enemy gets weaker every 100 shots received)
A8: Table 1 | B8: Prize # | C8: Probability | D8: Cumulative prob. | E8: Award | F8: RTP
B9: 1 | C9: 0.09 | D9: =+SUM($C$9:C9) -> 0.09 | E9: =+Summary!H36 -> 2 | F9: =+C9*E9 -> 0.18
B10: 2 | C10: 0.02 | D10: =+SUM($C$9:C10) -> 0.11 | E10: =+Summary!H37 -> 5 | F10: =+C10*E10 -> 0.1
B11: 3 | C11: 0.015 | D11: =+SUM($C$9:C11) -> 0.125 | E11: =+Summary!H38 -> 10 | F11: =+C11*E11 -> 0.15
B12: 4 | C12: 0.001 | D12: =+SUM($C$9:C12) -> 0.126 | E12: =+Summary!H39 -> 20 | F12: =+C12*E12 -> 0.02
B13: 5 | C13: 8e-05 | D13: =+SUM($C$9:C13) -> 0.12608 | E13: =+Summary!H40 -> 50 | F13: =+C13*E13 -> 0.004
B14: 6 | C14: 1e-05 | D14: =+SUM($C$9:C14) -> 0.12609 | E14: =+Summary!H41 -> 100 | F14: =+C14*E14 -> 0.001
B15: 7 | C15: 0.001 | D15: =+SUM($C$9:C15) -> 0.12709 | E15: =+Summary!H42 -> 500 | F15: =+C15*E15 -> 0.5 | G15: (*) Enemy killed
B16: Total (*) | C16: =+SUM(C9:C15) -> 0.12709 | F16: =+SUM(F9:F15) -> 0.955
B17: (*) Total probability is hit rate
A20: Table 2 | B20: Prize # | C20: Probability | D20: Cumulative prob. | E20: Award | F20: RTP
B21: 1 | C21: 0.085 | D21: =+SUM($C$21:C21) -> 0.085 | E21: =+Summary!H36 -> 2 | F21: =+C21*E21 -> 0.17
B22: 2 | C22: 0.03 | D22: =+SUM($C$21:C22) -> 0.115 | E22: =+Summary!H37 -> 5 | F22: =+C22*E22 -> 0.15
B23: 3 | C23: 0.011 | D23: =+SUM($C$21:C23) -> 0.126 | E23: =+Summary!H38 -> 10 | F23: =+C23*E23 -> 0.11
B24: 4 | C24: 0.001 | D24: =+SUM($C$21:C24) -> 0.127 | E24: =+Summary!H39 -> 20 | F24: =+C24*E24 -> 0.02
B25: 5 | C25: 8e-05 | D25: =+SUM($C$21:C25) -> 0.12708 | E25: =+Summary!H40 -> 50 | F25: =+C25*E25 -> 0.004
B26: 6 | C26: 1e-05 | D26: =+SUM($C$21:C26) -> 0.12709 | E26: =+Summary!H41 -> 100 | F26: =+C26*E26 -> 0.001
B27: 7 | C27: 0.001 | D27: =+SUM($C$21:C27) -> 0.12809 | E27: =+Summary!H42 -> 500 | F27: =+C27*E27 -> 0.5 | G27: (*) Enemy killed
B28: Total (*) | C28: =+SUM(C21:C27) -> 0.12809 | F28: =+SUM(F21:F27) -> 0.955
B29: (*) Total probability is hit rate
A32: Table 3 | B32: Prize # | C32: Probability | D32: Cumulative prob. | E32: Award | F32: RTP
B33: 1 | C33: 0.085 | D33: =+SUM($C$33:C33) -> 0.085 | E33: =+Summary!H36 -> 2 | F33: =+C33*E33 -> 0.17
B34: 2 | C34: 0.03 | D34: =+SUM($C$33:C34) -> 0.115 | E34: =+Summary!H37 -> 5 | F34: =+C34*E34 -> 0.15
B35: 3 | C35: 0.006 | D35: =+SUM($C$33:C35) -> 0.121 | E35: =+Summary!H38 -> 10 | F35: =+C35*E35 -> 0.06
B36: 4 | C36: 0.001 | D36: =+SUM($C$33:C36) -> 0.122 | E36: =+Summary!H39 -> 20 | F36: =+C36*E36 -> 0.02
B37: 5 | C37: 8e-05 | D37: =+SUM($C$33:C37) -> 0.12208 | E37: =+Summary!H40 -> 50 | F37: =+C37*E37 -> 0.004
B38: 6 | C38: 1e-05 | D38: =+SUM($C$33:C38) -> 0.12209 | E38: =+Summary!H41 -> 100 | F38: =+C38*E38 -> 0.001
B39: 7 | C39: 0.0011 | D39: =+SUM($C$33:C39) -> 0.12319 | E39: =+Summary!H42 -> 500 | F39: =+C39*E39 -> 0.55 | G39: (*) Enemy killed
B40: Total (*) | C40: =+SUM(C33:C39) -> 0.12319 | F40: =+SUM(F33:F39) -> 0.955
B41: (*) Total probability is hit rate
A44: Table 4 | B44: Prize # | C44: Probability | D44: Cumulative prob. | E44: Award | F44: RTP
B45: 1 | C45: 0.105 | D45: =+SUM($C$45:C45) -> 0.105 | E45: =+Summary!H36 -> 2 | F45: =+C45*E45 -> 0.21
B46: 2 | C46: 0.02 | D46: =+SUM($C$45:C46) -> 0.125 | E46: =+Summary!H37 -> 5 | F46: =+C46*E46 -> 0.1
B47: 3 | C47: 0.002 | D47: =+SUM($C$45:C47) -> 0.127 | E47: =+Summary!H38 -> 10 | F47: =+C47*E47 -> 0.02
B48: 4 | C48: 0.001 | D48: =+SUM($C$45:C48) -> 0.128 | E48: =+Summary!H39 -> 20 | F48: =+C48*E48 -> 0.02
B49: 5 | C49: 8e-05 | D49: =+SUM($C$45:C49) -> 0.12808 | E49: =+Summary!H40 -> 50 | F49: =+C49*E49 -> 0.004
...

Sheet Special weapon 1 (HV enemy)
A1: SPECIAL WEAPON 1 - High Volatility Enemy
A2: For each shot with a regular weapon, draw the damage caused using the tables below.
A3: Start using table 1 and every 100 shots received change to the following table.
A4: Note: The probability of defeating the enemy increases from one table to next table (the enemy gets weaker every 100 shots received)
A8: Table 1 | B8: Prize # | C8: Probability | D8: Cumulative prob. | E8: Award | F8: Avg payout
B9: 1 | C9: 0.21 | D9: =+SUM($C$9:C9) -> 0.21 | E9: =+Summary!H36 -> 2 | F9: =+C9*E9 -> 0.42
B10: 2 | C10: 0.03 | D10: =+SUM($C$9:C10) -> 0.24 | E10: =+Summary!H37 -> 5 | F10: =+C10*E10 -> 0.15
B11: 3 | C11: 0.002 | D11: =+SUM($C$9:C11) -> 0.242 | E11: =+Summary!H38 -> 10 | F11: =+C11*E11 -> 0.02
B12: 4 | C12: 0.002 | D12: =+SUM($C$9:C12) -> 0.244 | E12: =+Summary!H39 -> 20 | F12: =+C12*E12 -> 0.04
B13: 5 | C13: 0.001 | D13: =+SUM($C$9:C13) -> 0.245 | E13: =+Summary!H40 -> 50 | F13: =+C13*E13 -> 0.05
B14: 6 | C14: 0.0002 | D14: =+SUM($C$9:C14) -> 0.2452 | E14: =+Summary!H41 -> 100 | F14: =+C14*E14 -> 0.02
B15: 7 | C15: 0.001 | D15: =+SUM($C$9:C15) -> 0.2462 | E15: =+Summary!H42 -> 500 | F15: =+C15*E15 -> 0.5 | G15: (*) Enemy killed
B16: Total (*) | C16: =+SUM(C9:C15) -> 0.2462 | F16: =+SUM(F9:F15) -> 1.2
B17: (*) Total probability is hit rate
A20: Table 2 | B20: Prize # | C20: Probability | D20: Cumulative prob. | E20: Award | F20: Avg payout
B21: 1 | C21: 0.225 | D21: =+SUM($C$21:C21) -> 0.225 | E21: =+Summary!H36 -> 2 | F21: =+C21*E21 -> 0.45
B22: 2 | C22: 0.02 | D22: =+SUM($C$21:C22) -> 0.245 | E22: =+Summary!H37 -> 5 | F22: =+C22*E22 -> 0.1
B23: 3 | C23: 0.002 | D23: =+SUM($C$21:C23) -> 0.247 | E23: =+Summary!H38 -> 10 | F23: =+C23*E23 -> 0.02
B24: 4 | C24: 0.0015 | D24: =+SUM($C$21:C24) -> 0.2485 | E24: =+Summary!H39 -> 20 | F24: =+C24*E24 -> 0.03
B25: 5 | C25: 0 | D25: =+SUM($C$21:C25) -> 0.2485 | E25: =+Summary!H40 -> 50 | F25: =+C25*E25 -> 0
B26: 6 | C26: 0 | D26: =+SUM($C$21:C26) -> 0.2485 | E26: =+Summary!H41 -> 100 | F26: =+C26*E26 -> 0
B27: 7 | C27: 0.0012 | D27: =+SUM($C$21:C27) -> 0.2497 | E27: =+Summary!H42 -> 500 | F27: =+C27*E27 -> 0.6 | G27: (*) Enemy killed
B28: Total (*) | C28: =+SUM(C21:C27) -> 0.2497 | F28: =+SUM(F21:F27) -> 1.2
B29: (*) Total probability is hit rate
A32: Table 3 | B32: Prize # | C32: Probability | D32: Cumulative prob. | E32: Award | F32: Avg payout
B33: 1 | C33: 0.23 | D33: =+SUM($C$33:C33) -> 0.23 | E33: =+Summary!H36 -> 2 | F33: =+C33*E33 -> 0.46
B34: 2 | C34: 0.01 | D34: =+SUM($C$33:C34) -> 0.24 | E34: =+Summary!H37 -> 5 | F34: =+C34*E34 -> 0.05
B35: 3 | C35: 0.002 | D35: =+SUM($C$33:C35) -> 0.242 | E35: =+Summary!H38 -> 10 | F35: =+C35*E35 -> 0.02
B36: 4 | C36: 0.001 | D36: =+SUM($C$33:C36) -> 0.243 | E36: =+Summary!H39 -> 20 | F36: =+C36*E36 -> 0.02
B37: 5 | C37: 0 | D37: =+SUM($C$33:C37) -> 0.243 | E37: =+Summary!H40 -> 50 | F37: =+C37*E37 -> 0
B38: 6 | C38: 0 | D38: =+SUM($C$33:C38) -> 0.243 | E38: =+Summary!H41 -> 100 | F38: =+C38*E38 -> 0
B39: 7 | C39: 0.0013 | D39: =+SUM($C$33:C39) -> 0.2443 | E39: =+Summary!H42 -> 500 | F39: =+C39*E39 -> 0.65 | G39: (*) Enemy killed
B40: Total (*) | C40: =+SUM(C33:C39) -> 0.2443 | F40: =+SUM(F33:F39) -> 1.2
B41: (*) Total probability is hit rate
A44: Table 4 | B44: Prize # | C44: Probability | D44: Cumulative prob. | E44: Award | F44: Avg payout
B45: 1 | C45: 0.1 | D45: =+SUM($C$45:C45) -> 0.1 | E45: =+Summary!H36 -> 2 | F45: =+C45*E45 -> 0.2
B46: 2 | C46: 0.01 | D46: =+SUM($C$45:C46) -> 0.11 | E46: =+Summary!H37 -> 5 | F46: =+C46*E46 -> 0.05
B47: 3 | C47: 0.001 | D47: =+SUM($C$45:C47) -> 0.111 | E47: =+Summary!H38 -> 10 | F47: =+C47*E47 -> 0.01
B48: 4 | C48: 0.001 | D48: =+SUM($C$45:C48) -> 0.112 | E48: =+Summary!H39 -> 20 | F48: =+C48*E48 -> 0.02
B49: 5 | C49: 0.0002 | D49: =+SUM($C$45:C49) -> 0.1122 | E49: =+Summary!H40 -> 50 | F49: =+C49*E49 -> 0.01
...

Sheet Special weapon 2 (HV enemy)
A1: SPECIAL WEAPON 2 - High Volatility Enemy
A2: For each shot with a regular weapon, draw the damage caused using the tables below.
A3: Start using table 1 and every 100 shots received change to the following table.
A4: Note: The probability of defeating the enemy increases from one table to next table (the enemy gets weaker every 100 shots received)
A8: Table 1 | B8: Prize # | C8: Probability | D8: Cumulative prob. | E8: Award | F8: Avg payout
B9: 1 | C9: 0.15 | D9: =+SUM($C$9:C9) -> 0.15 | E9: =+Summary!H36 -> 2 | F9: =+C9*E9 -> 0.3
B10: 2 | C10: 0.01 | D10: =+SUM($C$9:C10) -> 0.16 | E10: =+Summary!H37 -> 5 | F10: =+C10*E10 -> 0.05
B11: 3 | C11: 0.001 | D11: =+SUM($C$9:C11) -> 0.161 | E11: =+Summary!H38 -> 10 | F11: =+C11*E11 -> 0.01
B12: 4 | C12: 0.002 | D12: =+SUM($C$9:C12) -> 0.163 | E12: =+Summary!H39 -> 20 | F12: =+C12*E12 -> 0.04
B13: 5 | C13: 0.001 | D13: =+SUM($C$9:C13) -> 0.164 | E13: =+Summary!H40 -> 50 | F13: =+C13*E13 -> 0.05
B14: 6 | C14: 0.001 | D14: =+SUM($C$9:C14) -> 0.165 | E14: =+Summary!H41 -> 100 | F14: =+C14*E14 -> 0.1
B15: 7 | C15: 0.001 | D15: =+SUM($C$9:C15) -> 0.166 | E15: =+Summary!H42 -> 500 | F15: =+C15*E15 -> 0.5 | G15: (*) Enemy killed
B16: Total (*) | C16: =+SUM(C9:C15) -> 0.166 | F16: =+SUM(F9:F15) -> 1.05
B17: (*) Total probability is hit rate
A20: Table 2 | B20: Prize # | C20: Probability | D20: Cumulative prob. | E20: Award | F20: Avg payout
B21: 1 | C21: 0.185 | D21: =+SUM($C$21:C21) -> 0.185 | E21: =+Summary!H36 -> 2 | F21: =+C21*E21 -> 0.37
B22: 2 | C22: 0.01 | D22: =+SUM($C$21:C22) -> 0.195 | E22: =+Summary!H37 -> 5 | F22: =+C22*E22 -> 0.05
B23: 3 | C23: 0.001 | D23: =+SUM($C$21:C23) -> 0.196 | E23: =+Summary!H38 -> 10 | F23: =+C23*E23 -> 0.01
B24: 4 | C24: 0.001 | D24: =+SUM($C$21:C24) -> 0.197 | E24: =+Summary!H39 -> 20 | F24: =+C24*E24 -> 0.02
B25: 5 | C25: 0.001 | D25: =+SUM($C$21:C25) -> 0.198 | E25: =+Summary!H40 -> 50 | F25: =+C25*E25 -> 0.05
B26: 6 | C26: 0 | D26: =+SUM($C$21:C26) -> 0.198 | E26: =+Summary!H41 -> 100 | F26: =+C26*E26 -> 0
B27: 7 | C27: 0.0011 | D27: =+SUM($C$21:C27) -> 0.1991 | E27: =+Summary!H42 -> 500 | F27: =+C27*E27 -> 0.55 | G27: (*) Enemy killed
B28: Total (*) | C28: =+SUM(C21:C27) -> 0.1991 | F28: =+SUM(F21:F27) -> 1.05
B29: (*) Total probability is hit rate
A32: Table 3 | B32: Prize # | C32: Probability | D32: Cumulative prob. | E32: Award | F32: Avg payout
B33: 1 | C33: 0.2 | D33: =+SUM($C$33:C33) -> 0.2 | E33: =+Summary!H36 -> 2 | F33: =+C33*E33 -> 0.4
B34: 2 | C34: 0.006 | D34: =+SUM($C$33:C34) -> 0.206 | E34: =+Summary!H37 -> 5 | F34: =+C34*E34 -> 0.03
B35: 3 | C35: 0.001 | D35: =+SUM($C$33:C35) -> 0.207 | E35: =+Summary!H38 -> 10 | F35: =+C35*E35 -> 0.01
B36: 4 | C36: 0.0005 | D36: =+SUM($C$33:C36) -> 0.2075 | E36: =+Summary!H39 -> 20 | F36: =+C36*E36 -> 0.01
B37: 5 | C37: 0 | D37: =+SUM($C$33:C37) -> 0.2075 | E37: =+Summary!H40 -> 50 | F37: =+C37*E37 -> 0
B38: 6 | C38: 0 | D38: =+SUM($C$33:C38) -> 0.2075 | E38: =+Summary!H41 -> 100 | F38: =+C38*E38 -> 0
B39: 7 | C39: 0.0012 | D39: =+SUM($C$33:C39) -> 0.2087 | E39: =+Summary!H42 -> 500 | F39: =+C39*E39 -> 0.6 | G39: (*) Enemy killed
B40: Total (*) | C40: =+SUM(C33:C39) -> 0.2087 | F40: =+SUM(F33:F39) -> 1.05
B41: (*) Total probability is hit rate
A44: Table 4 | B44: Prize # | C44: Probability | D44: Cumulative prob. | E44: Award | F44: Avg payout
B45: 1 | C45: 0.145 | D45: =+SUM($C$45:C45) -> 0.145 | E45: =+Summary!H36 -> 2 | F45: =+C45*E45 -> 0.29
B46: 2 | C46: 0.004 | D46: =+SUM($C$45:C46) -> 0.149 | E46: =+Summary!H37 -> 5 | F46: =+C46*E46 -> 0.02
B47: 3 | C47: 0.001 | D47: =+SUM($C$45:C47) -> 0.15 | E47: =+Summary!H38 -> 10 | F47: =+C47*E47 -> 0.01
B48: 4 | C48: 0.0005 | D48: =+SUM($C$45:C48) -> 0.1505 | E48: =+Summary!H39 -> 20 | F48: =+C48*E48 -> 0.01
B49: 5 | C49: 0.0002 | D49: =+SUM($C$45:C49) -> 0.1507 | E49: =+Summary!H40 -> 50 | F49: =+C49*E49 -> 0.01
...

Sheet Special weapon 3 (HV enemy)
A1: SPECIAL WEAPON 3 - High Volatility Enemy
A2: For each shot with a regular weapon, draw the damage caused using the tables below.
A3: Start using table 1 and every 100 shots received change to the following table.
A4: Note: The probability of defeating the enemy increases from one table to next table (the enemy gets weaker every 100 shots received)
A8: Table 1 | B8: Prize # | C8: Probability | D8: Cumulative prob. | E8: Award | F8: Avg payout
B9: 1 | C9: 0.15 | D9: =+SUM($C$9:C9) -> 0.15 | E9: =+Summary!H36 -> 2 | F9: =+C9*E9 -> 0.3
B10: 2 | C10: 0.012 | D10: =+SUM($C$9:C10) -> 0.162 | E10: =+Summary!H37 -> 5 | F10: =+C10*E10 -> 0.06
B11: 3 | C11: 0.002 | D11: =+SUM($C$9:C11) -> 0.164 | E11: =+Summary!H38 -> 10 | F11: =+C11*E11 -> 0.02
B12: 4 | C12: 0.001 | D12: =+SUM($C$9:C12) -> 0.165 | E12: =+Summary!H39 -> 20 | F12: =+C12*E12 -> 0.02
B13: 5 | C13: 0 | D13: =+SUM($C$9:C13) -> 0.165 | E13: =+Summary!H40 -> 50 | F13: =+C13*E13 -> 0
B14: 6 | C14: 0 | D14: =+SUM($C$9:C14) -> 0.165 | E14: =+Summary!H41 -> 100 | F14: =+C14*E14 -> 0
B15: 7 | C15: 0.001 | D15: =+SUM($C$9:C15) -> 0.166 | E15: =+Summary!H42 -> 500 | F15: =+C15*E15 -> 0.5 | G15: (*) Enemy killed
B16: Total (*) | C16: =+SUM(C9:C15) -> 0.166 | F16: =+SUM(F9:F15) -> 0.9
B17: (*) Total probability is hit rate
A20: Table 2 | B20: Prize # | C20: Probability | D20: Cumulative prob. | E20: Award | F20: Avg payout
B21: 1 | C21: 0.08 | D21: =+SUM($C$21:C21) -> 0.08 | E21: =+Summary!H36 -> 2 | F21: =+C21*E21 -> 0.16
B22: 2 | C22: 0.024 | D22: =+SUM($C$21:C22) -> 0.104 | E22: =+Summary!H37 -> 5 | F22: =+C22*E22 -> 0.12
B23: 3 | C23: 0 | D23: =+SUM($C$21:C23) -> 0.104 | E23: =+Summary!H38 -> 10 | F23: =+C23*E23 -> 0
B24: 4 | C24: 0.001 | D24: =+SUM($C$21:C24) -> 0.105 | E24: =+Summary!H39 -> 20 | F24: =+C24*E24 -> 0.02
B25: 5 | C25: 0.001 | D25: =+SUM($C$21:C25) -> 0.106 | E25: =+Summary!H40 -> 50 | F25: =+C25*E25 -> 0.05
B26: 6 | C26: 0.0005 | D26: =+SUM($C$21:C26) -> 0.1065 | E26: =+Summary!H41 -> 100 | F26: =+C26*E26 -> 0.05
B27: 7 | C27: 0.001 | D27: =+SUM($C$21:C27) -> 0.1075 | E27: =+Summary!H42 -> 500 | F27: =+C27*E27 -> 0.5 | G27: (*) Enemy killed
B28: Total (*) | C28: =+SUM(C21:C27) -> 0.1075 | F28: =+SUM(F21:F27) -> 0.9
B29: (*) Total probability is hit rate
A32: Table 3 | B32: Prize # | C32: Probability | D32: Cumulative prob. | E32: Award | F32: Avg payout
B33: 1 | C33: 0.09 | D33: =+SUM($C$33:C33) -> 0.09 | E33: =+Summary!H36 -> 2 | F33: =+C33*E33 -> 0.18
B34: 2 | C34: 0.016 | D34: =+SUM($C$33:C34) -> 0.106 | E34: =+Summary!H37 -> 5 | F34: =+C34*E34 -> 0.08
B35: 3 | C35: 0.002 | D35: =+SUM($C$33:C35) -> 0.108 | E35: =+Summary!H38 -> 10 | F35: =+C35*E35 -> 0.02
B36: 4 | C36: 0.001 | D36: =+SUM($C$33:C36) -> 0.109 | E36: =+Summary!H39 -> 20 | F36: =+C36*E36 -> 0.02
B37: 5 | C37: 0.001 | D37: =+SUM($C$33:C37) -> 0.11 | E37: =+Summary!H40 -> 50 | F37: =+C37*E37 -> 0.05
B38: 6 | C38: 0 | D38: =+SUM($C$33:C38) -> 0.11 | E38: =+Summary!H41 -> 100 | F38: =+C38*E38 -> 0
B39: 7 | C39: 0.0011 | D39: =+SUM($C$33:C39) -> 0.1111 | E39: =+Summary!H42 -> 500 | F39: =+C39*E39 -> 0.55 | G39: (*) Enemy killed
B40: Total (*) | C40: =+SUM(C33:C39) -> 0.1111 | F40: =+SUM(F33:F39) -> 0.9
B41: (*) Total probability is hit rate
A44: Table 4 | B44: Prize # | C44: Probability | D44: Cumulative prob. | E44: Award | F44: Avg payout
B45: 1 | C45: 0.1 | D45: =+SUM($C$45:C45) -> 0.1 | E45: =+Summary!H36 -> 2 | F45: =+C45*E45 -> 0.2
B46: 2 | C46: 0.01 | D46: =+SUM($C$45:C46) -> 0.11 | E46: =+Summary!H37 -> 5 | F46: =+C46*E46 -> 0.05
B47: 3 | C47: 0.005 | D47: =+SUM($C$45:C47) -> 0.115 | E47: =+Summary!H38 -> 10 | F47: =+C47*E47 -> 0.05
B48: 4 | C48: 0 | D48: =+SUM($C$45:C48) -> 0.115 | E48: =+Summary!H39 -> 20 | F48: =+C48*E48 -> 0
B49: 5 | C49: 0 | D49: =+SUM($C$45:C49) -> 0.115 | E49: =+Summary!H40 -> 50 | F49: =+C49*E49 -> 0
...

Sheet Plasma Gun (HV enemy)
A1: SPECIAL WEAPON 3 - High Volatility Enemy
A2: For each shot with a regular weapon, draw the damage caused using the tables below.
A3: Start using table 1 and every 100 shots received change to the following table.
A4: Note: The probability of defeating the enemy increases from one table to next table (the enemy gets weaker every 100 shots received)
A8: Table 1 | B8: Prize # | C8: Probability | D8: Cumulative prob. | E8: Award | F8: Avg payout
B9: 1 | C9: 0.1 | D9: =+SUM($C$9:C9) -> 0.1 | E9: =+Summary!H36 -> 2 | F9: =+C9*E9 -> 0.2
B10: 2 | C10: 0.26 | D10: =+SUM($C$9:C10) -> 0.36 | E10: =+Summary!H37 -> 5 | F10: =+C10*E10 -> 1.3
B11: 3 | C11: 0.25 | D11: =+SUM($C$9:C11) -> 0.61 | E11: =+Summary!H38 -> 10 | F11: =+C11*E11 -> 2.5
B12: 4 | C12: 0.2 | D12: =+SUM($C$9:C12) -> 0.81 | E12: =+Summary!H39 -> 20 | F12: =+C12*E12 -> 4
B13: 5 | C13: 0.02 | D13: =+SUM($C$9:C13) -> 0.83 | E13: =+Summary!H40 -> 50 | F13: =+C13*E13 -> 1
B14: 6 | C14: 0.01 | D14: =+SUM($C$9:C14) -> 0.84 | E14: =+Summary!H41 -> 100 | F14: =+C14*E14 -> 1
B15: 7 | C15: 0.01 | D15: =+SUM($C$9:C15) -> 0.85 | E15: =+Summary!H42 -> 500 | F15: =+C15*E15 -> 5 | G15: (*) Enemy killed
B16: Total (*) | C16: =+SUM(C9:C15) -> 0.85 | F16: =+SUM(F9:F15) -> 15
B17: (*) Total probability is hit rate
A20: Table 2 | B20: Prize # | C20: Probability | D20: Cumulative prob. | E20: Award | F20: Avg payout
B21: 1 | C21: 0 | D21: =+SUM($C$21:C21) -> 0 | E21: =+Summary!H36 -> 2 | F21: =+C21*E21 -> 0
B22: 2 | C22: 0.4 | D22: =+SUM($C$21:C22) -> 0.4 | E22: =+Summary!H37 -> 5 | F22: =+C22*E22 -> 2
B23: 3 | C23: 0.19 | D23: =+SUM($C$21:C23) -> 0.59 | E23: =+Summary!H38 -> 10 | F23: =+C23*E23 -> 1.9
B24: 4 | C24: 0.2 | D24: =+SUM($C$21:C24) -> 0.79 | E24: =+Summary!H39 -> 20 | F24: =+C24*E24 -> 4
B25: 5 | C25: 0.02 | D25: =+SUM($C$21:C25) -> 0.81 | E25: =+Summary!H40 -> 50 | F25: =+C25*E25 -> 1
B26: 6 | C26: 0.001 | D26: =+SUM($C$21:C26) -> 0.811 | E26: =+Summary!H41 -> 100 | F26: =+C26*E26 -> 0.1
B27: 7 | C27: 0.012 | D27: =+SUM($C$21:C27) -> 0.823 | E27: =+Summary!H42 -> 500 | F27: =+C27*E27 -> 6 | G27: (*) Enemy killed
B28: Total (*) | C28: =+SUM(C21:C27) -> 0.823 | F28: =+SUM(F21:F27) -> 15
B29: (*) Total probability is hit rate
A32: Table 3 | B32: Prize # | C32: Probability | D32: Cumulative prob. | E32: Award | F32: Avg payout
B33: 1 | C33: 0 | D33: =+SUM($C$33:C33) -> 0 | E33: =+Summary!H36 -> 2 | F33: =+C33*E33 -> 0
B34: 2 | C34: 0.4 | D34: =+SUM($C$33:C34) -> 0.4 | E34: =+Summary!H37 -> 5 | F34: =+C34*E34 -> 2
B35: 3 | C35: 0.25 | D35: =+SUM($C$33:C35) -> 0.65 | E35: =+Summary!H38 -> 10 | F35: =+C35*E35 -> 2.5
B36: 4 | C36: 0.05 | D36: =+SUM($C$33:C36) -> 0.7 | E36: =+Summary!H39 -> 20 | F36: =+C36*E36 -> 1
B37: 5 | C37: 0.02 | D37: =+SUM($C$33:C37) -> 0.72 | E37: =+Summary!H40 -> 50 | F37: =+C37*E37 -> 1
B38: 6 | C38: 0.01 | D38: =+SUM($C$33:C38) -> 0.73 | E38: =+Summary!H41 -> 100 | F38: =+C38*E38 -> 1
B39: 7 | C39: 0.015 | D39: =+SUM($C$33:C39) -> 0.745 | E39: =+Summary!H42 -> 500 | F39: =+C39*E39 -> 7.5 | G39: (*) Enemy killed
B40: Total (*) | C40: =+SUM(C33:C39) -> 0.745 | F40: =+SUM(F33:F39) -> 15
B41: (*) Total probability is hit rate
A44: Table 4 | B44: Prize # | C44: Probability | D44: Cumulative prob. | E44: Award | F44: Avg payout
B45: 1 | C45: 0 | D45: =+SUM($C$45:C45) -> 0 | E45: =+Summary!H36 -> 2 | F45: =+C45*E45 -> 0
B46: 2 | C46: 0.4 | D46: =+SUM($C$45:C46) -> 0.4 | E46: =+Summary!H37 -> 5 | F46: =+C46*E46 -> 2
B47: 3 | C47: 0.14 | D47: =+SUM($C$45:C47) -> 0.54 | E47: =+Summary!H38 -> 10 | F47: =+C47*E47 -> 1.4
B48: 4 | C48: 0.05 | D48: =+SUM($C$45:C48) -> 0.59 | E48: =+Summary!H39 -> 20 | F48: =+C48*E48 -> 1
B49: 5 | C49: 0.01 | D49: =+SUM($C$45:C49) -> 0.6 | E49: =+Summary!H40 -> 50 | F49: =+C49*E49 -> 0.5
...

Sheet Base game (Mummy A)
A1: Medium Mummy A (golden wrist bands)
A2: For each shot with a regular weapon, draw the damage caused using the table according to prizes already granted by enemy that is being shot.
A4: Table 1 | B4: Prize # | C4: Probability | D4: Cumulative prob. | E4: Award | F4: RTP | G4: Prob. Boss round
A5: (Initial state) | B5: 1 | C5: 0.075 | D5: =+SUM($C$5:C5) -> 0.075 | E5: =+Summary!E27 -> 5 | F5: =+C5*E5 -> 0.375
B6: 2 | C6: 0.0205 | D6: =+SUM($C$5:C6) -> 0.0955 | E6: =+Summary!E28 -> 10 | F6: =+C6*E6 -> 0.205
B7: 1 and 2 | C7: 0.005 | D7: =+SUM($C$5:C7) -> 0.1005 | E7: =+E5+E6 -> 15 | F7: =+C7*E7 -> 0.075 | G7: =1/C7/Summary!$C$7 -> 0.4 | H7: (*) Enemy killed
B8: Total (*) | C8: =+SUM(C5:C7) -> 0.1005 | F8: =+SUM(F5:F7) -> 0.655
B9: (*) Total probability is hit rate
A12: Table 6 | B12: Prize # | C12: Probability | D12: Cumulative prob. | E12: Award | F12: RTP | G12: Prob. Boss round
A13: Awards granted: | B13: 1 | C13: 0.131 | D13: =+SUM(C13:$C$13) -> 0.131 | E13: =+E5 -> 5 | F13: =+E13*C13 -> 0.655 | G13: =1/C13/Summary!$C$7 -> 0.015267176 | H13: (*) Enemy killed
A14: Prize #2 | B14: Total | C14: =+SUM(C13:C13) -> 0.131 | F14: =+SUM(F13:F13) -> 0.655
A17: Table 7 | B17: Prize # | C17: Probability | D17: Cumulative prob. | E17: Award | F17: RTP | G17: Prob. Boss round
A18: Awards granted: | B18: 2 | C18: 0.0655 | D18: =+SUM(C$18:$C18) -> 0.0655 | E18: =+E6 -> 10 | F18: =+E18*C18 -> 0.655 | G18: =1/C18/Summary!$C$7 -> 0.030534351 | H18: (*) Enemy killed
A19: Prize #1 | B19: Total | C19: =+SUM(C18:C18) -> 0.0655 | F19: =+SUM(F18:F18) -> 0.655

Sheet Base game (Mummy B)
A1: Medium Mummy B (golden wrist bands and necklace)
A2: For each shot with a regular weapon, draw the damage caused using the table according to prizes already granted by enemy that is being shot.
A4: Table 1 | B4: Prize # | C4: Probability | D4: Cumulative prob. | E4: Award | F4: RTP | G4: Prob. Boss round
A5: (Initial state) | B5: 1 | C5: 0.08 | D5: =+SUM($C$5:C5) -> 0.08 | E5: =+Summary!H27 -> 5 | F5: =+C5*E5 -> 0.4
B6: 2 | C6: 0.0015 | D6: =+SUM($C$5:C6) -> 0.0815 | E6: =+Summary!H28 -> 10 | F6: =+C6*E6 -> 0.015
B7: 3 | C7: 0 | D7: =+SUM($C$5:C7) -> 0.0815 | E7: =+Summary!H29 -> 15 | F7: =+C7*E7 -> 0
B8: 1 and 2 | C8: 0 | D8: =+SUM($C$5:C8) -> 0.0815 | E8: =+E5+E6 -> 15 | F8: =+C8*E8 -> 0
B9: 1 and 3 | C9: 0 | D9: =+SUM($C$5:C9) -> 0.0815 | E9: =+E5+E7 -> 20 | F9: =+C9*E9 -> 0
B10: 2 and 3 | C10: 0 | D10: =+SUM($C$5:C10) -> 0.0815 | E10: =+E6+E7 -> 25 | F10: =+C10*E10 -> 0
B11: 1, 2 and 3 (*) | C11: 0.008 | D11: =+SUM($C$5:C11) -> 0.0895 | E11: =+E5+E6+E7 -> 30 | F11: =+C11*E11 -> 0.24 | G11: =1/C11/200 -> 0.625 | H11: (*) Enemy killed
B12: Total (*) | C12: =+SUM(C5:C11) -> 0.0895 | F12: =+SUM(F5:F11) -> 0.655
B13: (*) Total probability is hit rate
A15: Table 2 | B15: Prize # | C15: Probability | D15: Cumulative prob. | E15: Award | F15: RTP | G15: Prob. Boss round
A16: Awards granted: | B16: 2 | C16: 0.0405 | D16: =+SUM(C16:$C$16) -> 0.0405 | E16: =+E6 -> 10 | F16: =+C16*E16 -> 0.405
A17: Prize #1 | B17: 3 | C17: 0 | D17: =+SUM(C$16:$C17) -> 0.0405 | E17: =+E7 -> 15 | F17: =+C17*E17 -> 0
B18: 2 and 3 | C18: 0.01 | D18: =+SUM(C$16:$C18) -> 0.0505 | E18: =+E16+E17 -> 25 | F18: =+C18*E18 -> 0.25 | G18: =1/C18/200 -> 0.5 | H18: (*) Enemy killed
B19: Total | C19: =+SUM(C16:C18) -> 0.0505 | F19: =+SUM(F16:F18) -> 0.655
A22: Table 3 | B22: Prize # | C22: Probability | D22: Cumulative prob. | E22: Award | F22: RTP | G22: Prob. Boss round
A23: Awards granted: | B23: 1 | C23: 0.091 | D23: =+SUM(C23:$C$23) -> 0.091 | E23: =+E5 -> 5 | F23: =+C23*E23 -> 0.455
A24: Prize #2 | B24: 3 | C24: 0 | D24: =+SUM(C$23:$C24) -> 0.091 | E24: =+E7 -> 15 | F24: =+C24*E24 -> 0
B25: 1 and 3 | C25: 0.01 | D25: =+SUM(C$23:$C25) -> 0.101 | E25: =+E23+E24 -> 20 | F25: =+C25*E25 -> 0.2 | G25: =1/C25/Summary!$C$7 -> 0.2 | H25: (*) Enemy killed
B26: Total | C26: =+SUM(C23:C25) -> 0.101 | F26: =+SUM(F23:F25) -> 0.655
A29: Table 4 | B29: Prize # | C29: Probability | D29: Cumulative prob. | E29: Award | F29: RTP | G29: Prob. Boss round
A30: Awards granted: | B30: 3 | C30: 0.043666667 | D30: =+SUM(C30:$C$30) -> 0.043666667 | E30: =+E7 -> 15 | F30: =+C30*E30 -> 0.655 | G30: =1/C30/Summary!$C$7 -> 0.045801527 | H30: (*) Enemy killed
A31: Prize #1 | B31: Total | C31: =+SUM(C30:C30) -> 0.043666667 | F31: =+SUM(F30:F30) -> 0.655
A32: Prize #2
