Workbook

Sheet Summary
A1: Notes: the number of enemies of each type in each location is irrelevant from the mathematical point of view.
A2: If locations act as "levels", it may be interesting to have weak enemies in the first location and add other species in the following locations.
A5: Feature | B5: RTP | C5: Freq | D5: Probability | E5: Avg pay
A6: Base game | B6: 0.5
A7: Boss round | B7: 0.25 | C7: 200 | D7: =1/C7 -> 0.005 | E7: =+C7*B7 -> 50 | F7: Prize: 50x to be distributed between players according to damage done to boss
A8: Special weapon (*) | B8: 0.1 | C8: 60 | D8: =1/C8 -> 0.016666667 | E8: =+C8*B8 -> 6
A9: Hoard | B9: 0.1 | C9: 800 | D9: =1/C9 -> 0.00125 | E9: =+C9*B9 -> 80 | F9: Prize: 30x credits to be distributed between players according to contribution to completion + 50x to be distributed between players according to damage done to boss.
A10: Leaderboard | B10: 0
A11: Total | B11: 0.95
A12: (*) To use in MAIN only. Shots using special weapons are not paid. Each special weapon has a limited number of shots and could be used any time in base game.
A13: When a player gets a GUARANTEE KNOCKOUT he/she can use it only in base game and optimal strategy is to kill a Powerful Pharaoh Mummy with no damage. The prize is x15 (see table below)
A14: If player uses the special weapon in other case (imperfect play) then he/she will get a prize lower than x15. The difference is added to leaderboard prize.
A16: There are different kind of enemies. Each enemy has its own prizes. Stronger enemies grant bigger prizes but are more difficult to kill.
A19: Scarab black | D19: Scarab gold | G19: Scarab gem covered
A20: Prize # | B20: Pays | D20: Prize # | E20: Pays | G20: Prize # | H20: Pays
A21: 1 | B21: 2 | D21: 1 | E21: 3 | G21: 1 | H21: 4
A25: Standard Mummy | D25: Medium Mummy A | G25: Medium Mummy B | J25: Medium Mummy C
A26: Prize | B26: Pays | D26: Prize # | E26: Pays | G26: Prize # | H26: Pays | J26: Prize # | K26: Pays
A27: 1 | B27: 2 | D27: 1 | E27: 0 | G27: 1 | H27: 2 | J27: 1 | K27: 3
A28: 2 | B28: 3 | D28: 2 | E28: 2 | G28: 2 | H28: 2 | J28: 2 | K28: 3
A29: Total | B29: =+SUM(B27:B28) -> 5 | D29: 3 | E29: 3 | G29: 3 | H29: 4 | J29: 3 | K29: 6
D30: Total | E30: =+SUM(E27:E29) -> 5 | G30: Total | H30: =+SUM(H27:H29) -> 8 | J30: Total | K30: =+SUM(K27:K29) -> 12
A34: Powerful Pharaoh Mummy A | D34: Powerful Pharaoh Mummy B
A35: Prize # | B35: Pays | D35: Prize # | E35: Pays
A36: 1 | B36: 2 | D36: 1 | E36: 2
A37: 2 | B37: 5 | D37: 2 | E37: 5
A38: 3 | B38: 8 | D38: 3 | E38: 8
A39: Total | B39: =+SUM(B36:B38) -> 15 | D39: Total | E39: =+SUM(E36:E38) -> 15

Sheet Special weapon
A1: For each shot in base game with a regular weapon draw if player gets a special weapon or not.
A2: Probability of getting a special weapon = 1/60
A3: If player gets a special weapon then draw which one he gets using the weights in the table below.
A6: Special weapons: | B6: Shots | C6: Avg pay by shot | D6: Total avg pay | E6: Weights
A7: Special weapon 1 | B7: 3 | C7: 1.2 | D7: =+B7*C7 -> 3.6 | E7: 330
A8: Special weapon 2 | B8: 5 | C8: 1.05 | D8: =+B8*C8 -> 5.25 | E8: 180
A9: Special weapon 3 | B9: 10 | C9: 0.9 | D9: =+B9*C9 -> 9 | E9: 309
A10: Guarantee knockout (*) | B10: 0 | C10: 12 | D10: =+B10*C10 -> 0 | E10: 0 | F10: (*) if there is not any Powerful Pharaoh Mummy in location we can discard this one to make it simpler.
F11: Otherwise, the best strategy would be to keep this weapon and use it in another location to kill a Powerful Pharaoh Mummy.
C12: Avg win | D12: =+SUMPRODUCT(D7:D9,E7:E9)/SUM(E7:E9) -> 6
A15: Special weapons can be use anytime in base game only.
A17: Special weapons: | B17: Shots | C17: Avg pay by shot | D17: Total avg pay | E17: Weights
A18: Special weapon 1 | B18: 3 | C18: 1.2 | D18: =+B18*C18 -> 3.6 | E18: 10
A19: Special weapon 2 | B19: 5 | C19: 1.05 | D19: =+B19*C19 -> 5.25 | E19: 8
A20: Special weapon 3 | B20: 10 | C20: 0.9 | D20: =+B20*C20 -> 9 | E20: 7
A21: Guarantee knockout (*) | B21: 1 | C21: 15 | D21: =+B21*C21 -> 15 | E21: 1 | F21: Skill: best strategy is to use it with a Powerful Pharaoh Mummy with no damage
A22: (*) avg pay using best strategy
C23: Avg win | D23: =+SUMPRODUCT(D18:D21,E18:E21)/SUM(E18:E21) -> 6
A26: Each special weapon has its own probabilities of damage for each kind of enemy. Prizes must be multiplied by the stake that triggered the feature.
A27: For instance, if player gets a special weapon betting 100 credits, at the moment he decides to use it the prizes must be multiplied by 100. It doesn’t matter if after getting the special weapon he changed the stake.

Sheet Base game (Mummy A)
A1: Medium Mummy A (golden wrist bands)
A2: For each shot with a regular weapon, draw the damage caused using the table according to prizes already granted by enemy that is being shot.
A3: For example, if player is shooting to an enemy that has granted prize #1 and prize #2, the only possible prize is #3. In that case use probabilities in Table 4.
A4: But if player is shooting to an enemy with no damage at all, the damage caused by this shot must be drawn using Table 1.
A5: How to use tables: example using Table 1
A6: Draw a real number between 0 and 1 (uniform distribution).
A7: If the number drawn is greater than Total (*) probability (Cell C21) that will be a miss.
A8: If the number drawn is less than 0.13 (first cumulative probability) then the player receives a prize of 1x (1st row, 4th column)
A9: If the number drawn is between 0.13 and 0.26 (first and second cumulative probabilities) then the player receives a prize of 2x (2nd row, 4th column)
A10: If the number drawn is 0.28, that is between 0.2766666666 and 0.2816666666 (5th and 6th cumulative probabilities) then the player receives a prize of 5x (2 by prize #2 + 3 by prize #3).
A12: Boss round:
A13: The Boss round can be triggered only when an enemy is defeated.
... A19: There are several special weapons that can be granted (tab "Special weapon")
A21: Table 1 | B21: Prize # | C21: Probability | D21: Cumulative prob. | E21: Award | F21: RTP | G21: Prob. Boss round
A22: (Initial state) | B22: 1 | C22: 0.13 | D22: =+SUM($C$22:C22) -> 0.13 | E22: =+Summary!E27 -> 0 | F22: =+C22*E22 -> 0
B23: 2 | C23: 0.196 | D23: =+SUM($C$22:C23) -> 0.326 | E23: =+Summary!E28 -> 2 | F23: =+C23*E23 -> 0.392
B24: 3 | C24: 0.001 | D24: =+SUM($C$22:C24) -> 0.327 | E24: =+Summary!E29 -> 3 | F24: =+C24*E24 -> 0.003
B25: 1 and 2 | C25: 0.02 | D25: =+SUM($C$22:C25) -> 0.347 | E25: =+E22+E23 -> 2 | F25: =+C25*E25 -> 0.04
B26: 1 and 3 | C26: 0.005 | D26: =+SUM($C$22:C26) -> 0.352 | E26: =+E22+E24 -> 3 | F26: =+C26*E26 -> 0.015
B27: 2 and 3 | C27: 0.005 | D27: =+SUM($C$22:C27) -> 0.357 | E27: =+E23+E24 -> 5 | F27: =+C27*E27 -> 0.025
B28: 1, 2 and 3 (*) | C28: 0.005 | D28: =+SUM($C$22:C28) -> 0.362 | E28: =+E22+E23+E24 -> 5 | F28: =+C28*E28 -> 0.025 | G28: 1 | H28: (*) Enemy killed
B29: Total (*) | C29: =+SUM(C22:C28) -> 0.362 | F29: =+SUM(F22:F28) -> 0.5
B30: (*) Total probability is hit rate
A32: Table 2 | B32: Prize # | C32: Probability | D32: Cumulative prob. | E32: Award | F32: RTP
A33: Awards granted: | B33: 2 | C33: 0.125 | D33: =+SUM(C33:$C$33) -> 0.125 | E33: =+E23 -> 2 | F33: =+C33*E33 -> 0.25
A34: Prize #1 | B34: 3 | C34: 0.05 | D34: =+SUM(C$33:$C34) -> 0.175 | E34: =+E24 -> 3 | F34: =+C34*E34 -> 0.15
B35: 2 and 3 | C35: 0.02 | D35: =+SUM(C$33:$C35) -> 0.195 | E35: =+E33+E34 -> 5 | F35: =+C35*E35 -> 0.1 | G35: 0.25 | H35: (*) Enemy killed
B36: Total | C36: =+SUM(C33:C35) -> 0.195 | F36: =+SUM(F33:F35) -> 0.5
A39: Table 3 | B39: Prize # | C39: Probability | D39: Cumulative prob. | E39: Award | F39: RTP
A40: Awards granted: | B40: 1 | C40: 0.3 | D40: =+SUM(C40:$C$40) -> 0.3 | E40: =+E22 -> 0 | F40: =+C40*E40 -> 0
A41: Prize #2 | B41: 3 | C41: 0.14666667 | D41: =+SUM(C$40:$C41) -> 0.44666667 | E41: =+E24 -> 3 | F41: =+C41*E41 -> 0.44
B42: 1 and 3 | C42: 0.02 | D42: =+SUM(C$40:$C42) -> 0.46666667 | E42: =+E40+E41 -> 3 | F42: =+C42*E42 -> 0.06 | G42: 0.25 | H42: (*) Enemy killed
B43: Total | C43: =+SUM(C40:C42) -> 0.46666667 | F43: =+SUM(F40:F42) -> 0.5
A46: Table 4 | B46: Prize # | C46: Probability | D46: Cumulative prob. | E46: Award | F46: RTP
A47: Awards granted: | B47: 3 | C47: 0.16666667 | D47: =+SUM(C47:$C$47) -> 0.16666667 | E47: =+E24 -> 3 | F47: =+C47*E47 -> 0.5 | G47: 0.03 | H47: (*) Enemy killed
A48: Prize #1 | B48: Total | C48: =+SUM(C47:C47) -> 0.16666667 | F48: =+SUM(F47:F47) -> 0.5
A49: Prize #2
A51: Table 5 | B51: Prize # | C51: Probability | D51: Cumulative prob. | E51: Award | F51: RTP
A52: Awards granted: | B52: 1 | C52: 0.14 | D52: =+SUM(C52:$C$52) -> 0.14 | E52: =+E22 -> 0 | F52: =+C52*E52 -> 0
A53: Prize #3 | B53: 2 | C53: 0.22333333 | D53: =+SUM(C$52:$C53) -> 0.36333333 | E53: =+E23 -> 2 | F53: =+C53*E53 -> 0.44666667
...

Sheet Base game (Mummy B)
A1: Medium Mummy B (golden wrist bands and necklace)
A2: For each shot with a regular weapon, draw the damage caused using the table according to prizes already granted by enemy that is being shot.
A4: Table 1 | B4: Prize # | C4: Probability | D4: Cumulative prob. | E4: Award | F4: RTP | G4: Prob. Boss round
A5: (Initial state) | B5: 1 | C5: 0.09 | D5: =+SUM($C$5:C5) -> 0.09 | E5: =+Summary!H27 -> 2 | F5: =+C5*E5 -> 0.18
B6: 2 | C6: 0.09 | D6: =+SUM($C$5:C6) -> 0.18 | E6: =+Summary!H28 -> 2 | F6: =+C6*E6 -> 0.18
B7: 3 | C7: 0.005 | D7: =+SUM($C$5:C7) -> 0.185 | E7: =+Summary!H29 -> 4 | F7: =+C7*E7 -> 0.02
B8: 1 and 2 | C8: 0.008 | D8: =+SUM($C$5:C8) -> 0.193 | E8: =+E5+E6 -> 4 | F8: =+C8*E8 -> 0.032
B9: 1 and 3 | C9: 0.004 | D9: =+SUM($C$5:C9) -> 0.197 | E9: =+E5+E7 -> 6 | F9: =+C9*E9 -> 0.024
B10: 2 and 3 | C10: 0.004 | D10: =+SUM($C$5:C10) -> 0.201 | E10: =+E6+E7 -> 6 | F10: =+C10*E10 -> 0.024
B11: 1, 2 and 3 (*) | C11: 0.005 | D11: =+SUM($C$5:C11) -> 0.206 | E11: =+E5+E6+E7 -> 8 | F11: =+C11*E11 -> 0.04 | G11: 1 | H11: (*) Enemy killed
B12: Total (*) | C12: =+SUM(C5:C11) -> 0.206 | F12: =+SUM(F5:F11) -> 0.5
B13: (*) Total probability is hit rate
A15: Table 2 | B15: Prize # | C15: Probability | D15: Cumulative prob. | E15: Award | F15: RTP | G15: Prob. Boss round
A16: Awards granted: | B16: 2 | C16: 0.2 | D16: =+SUM(C16:$C$16) -> 0.2 | E16: =+E6 -> 2 | F16: =+C16*E16 -> 0.4
A17: Prize #1 | B17: 3 | C17: 0.013 | D17: =+SUM(C$16:$C17) -> 0.213 | E17: =+E7 -> 4 | F17: =+C17*E17 -> 0.052
B18: 2 and 3 | C18: 0.008 | D18: =+SUM(C$16:$C18) -> 0.221 | E18: =+E16+E17 -> 6 | F18: =+C18*E18 -> 0.048 | G18: 0.625 | H18: (*) Enemy killed
B19: Total | C19: =+SUM(C16:C18) -> 0.221 | F19: =+SUM(F16:F18) -> 0.5
A22: Table 3 | B22: Prize # | C22: Probability | D22: Cumulative prob. | E22: Award | F22: RTP | G22: Prob. Boss round
A23: Awards granted: | B23: 1 | C23: 0.2 | D23: =+SUM(C23:$C$23) -> 0.2 | E23: =+E5 -> 2 | F23: =+C23*E23 -> 0.4
A24: Prize #2 | B24: 3 | C24: 0.013 | D24: =+SUM(C$23:$C24) -> 0.213 | E24: =+E7 -> 4 | F24: =+C24*E24 -> 0.052
B25: 1 and 3 | C25: 0.008 | D25: =+SUM(C$23:$C25) -> 0.221 | E25: =+E23+E24 -> 6 | F25: =+C25*E25 -> 0.048 | G25: 0.625 | H25: (*) Enemy killed
B26: Total | C26: =+SUM(C23:C25) -> 0.221 | F26: =+SUM(F23:F25) -> 0.5
A29: Table 4 | B29: Prize # | C29: Probability | D29: Cumulative prob. | E29: Award | F29: RTP | G29: Prob. Boss round
A30: Awards granted: | B30: 3 | C30: 0.125 | D30: =+SUM(C30:$C$30) -> 0.125 | E30: =+E7 -> 4 | F30: =+C30*E30 -> 0.5 | G30: 0.04 | H30: (*) Enemy killed
A31: Prize #1 | B31: Total | C31: =+SUM(C30:C30) -> 0.125 | F31: =+SUM(F30:F30) -> 0.5
A32: Prize #2
A34: Table 5 | B34: Prize # | C34: Probability | D34: Cumulative prob. | E34: Award | F34: RTP | G34: Prob. Boss round
A35: Awards granted: | B35: 1 | C35: 0.115 | D35: =+SUM(C35:$C$35) -> 0.115 | E35: =+E5 -> 2 | F35: =+C35*E35 -> 0.23
A36: Prize #3 | B36: 2 | C36: 0.115 | D36: =+SUM(C$35:$C36) -> 0.23 | E36: =+E6 -> 2 | F36: =+C36*E36 -> 0.23
B37: 1 and 2 | C37: 0.01 | D37: =+SUM(C$35:$C37) -> 0.24 | E37: =+E35+E36 -> 4 | F37: =+C37*E37 -> 0.04 | G37: 0.5 | H37: (*) Enemy killed
B38: Total | C38: =+SUM(C35:C37) -> 0.24 | F38: =+SUM(F35:F37) -> 0.5
A41: Table 6 | B41: Prize # | C41: Probability | D41: Cumulative prob. | E41: Award | F41: RTP
A42: Awards granted: | B42: 1 | C42: 0.25 | D42: =+SUM(C42:$C$42) -> 0.25 | E42: =+E5 -> 2 | F42: =+E42*C42 -> 0.5 | G42: 0.02 | H42: (*) Enemy killed
A43: Prize #2 | B43: Total | C43: =+SUM(C42:C42) -> 0.25 | F43: =+SUM(F42:F42) -> 0.5
A44: Prize #3
A46: Table 7 | B46: Prize # | C46: Probability | D46: Cumulative prob. | E46: Award | F46: RTP
A47: Awards granted: | B47: 2 | C47: 0.25 | D47: =+SUM(C$47:$C47) -> 0.25 | E47: =+E6 -> 2 | F47: =+E47*C47 -> 0.5 | G47: 0.02 | H47: (*) Enemy killed
A48: Prize #1 | B48: Total | C48: =+SUM(C47:C47) -> 0.25 | F48: =+SUM(F47:F47) -> 0.5
A49: Prize #3

Sheet Base game (Mummy C)
A1: Medium Mummy C (golden boots and wrist bands)
A2: For each shot with a regular weapon, draw the damage caused using the table according to prizes already granted by enemy that is being shot.
A4: Table 1 | B4: Prize # | C4: Probability | D4: Cumulative prob. | E4: Award | F4: RTP | G4: Prob. Boss round
A5: (Initial state) | B5: 1 | C5: 0.06 | D5: =+SUM($C$5:C5) -> 0.06 | E5: =+Summary!K27 -> 3 | F5: =+C5*E5 -> 0.18
B6: 2 | C6: 0.06 | D6: =+SUM($C$5:C6) -> 0.12 | E6: =+Summary!K28 -> 3 | F6: =+C6*E6 -> 0.18
B7: 3 | C7: 0.005 | D7: =+SUM($C$5:C7) -> 0.125 | E7: =+Summary!K29 -> 6 | F7: =+C7*E7 -> 0.03
B8: 1 and 2 | C8: 0.0038333333 | D8: =+SUM($C$5:C8) -> 0.12883333 | E8: =+E5+E6 -> 6 | F8: =+C8*E8 -> 0.023
B9: 1 and 3 | C9: 0.0015 | D9: =+SUM($C$5:C9) -> 0.13033333 | E9: =+E5+E7 -> 9 | F9: =+C9*E9 -> 0.0135
B10: 2 and 3 | C10: 0.0015 | D10: =+SUM($C$5:C10) -> 0.13183333 | E10: =+E6+E7 -> 9 | F10: =+C10*E10 -> 0.0135
B11: 1, 2 and 3 (*) | C11: 0.005 | D11: =+SUM($C$5:C11) -> 0.13683333 | E11: =+E5+E6+E7 -> 12 | F11: =+C11*E11 -> 0.06 | G11: 1 | H11: (*) Enemy killed
B12: Total (*) | C12: =+SUM(C5:C11) -> 0.13683333 | F12: =+SUM(F5:F11) -> 0.5
B13: (*) Total probability is hit rate
A15: Table 2 | B15: Prize # | C15: Probability | D15: Cumulative prob. | E15: Award | F15: RTP | G15: Prob. Boss round
A16: Awards granted: | B16: 2 | C16: 0.096666667 | D16: =+SUM(C16:$C$16) -> 0.096666667 | E16: =+E6 -> 3 | F16: =+C16*E16 -> 0.29
A17: Prize #1 | B17: 3 | C17: 0.02 | D17: =+SUM(C$16:$C17) -> 0.11666667 | E17: =+E7 -> 6 | F17: =+C17*E17 -> 0.12
B18: 2 and 3 | C18: 0.01 | D18: =+SUM(C$16:$C18) -> 0.12666667 | E18: =+E16+E17 -> 9 | F18: =+C18*E18 -> 0.09 | G18: 0.5 | H18: (*) Enemy killed
B19: Total | C19: =+SUM(C16:C18) -> 0.12666667 | F19: =+SUM(F16:F18) -> 0.5
A22: Table 3 | B22: Prize # | C22: Probability | D22: Cumulative prob. | E22: Award | F22: RTP | G22: Prob. Boss round
A23: Awards granted: | B23: 1 | C23: 0.096666667 | D23: =+SUM(C23:$C$23) -> 0.096666667 | E23: =+E5 -> 3 | F23: =+C23*E23 -> 0.29
A24: Prize #2 | B24: 3 | C24: 0.02 | D24: =+SUM(C$23:$C24) -> 0.11666667 | E24: =+E7 -> 6 | F24: =+C24*E24 -> 0.12
B25: 1 and 3 | C25: 0.01 | D25: =+SUM(C$23:$C25) -> 0.12666667 | E25: =+E23+E24 -> 9 | F25: =+C25*E25 -> 0.09 | G25: 0.5 | H25: (*) Enemy killed
B26: Total | C26: =+SUM(C23:C25) -> 0.12666667 | F26: =+SUM(F23:F25) -> 0.5
A29: Table 4 | B29: Prize # | C29: Probability | D29: Cumulative prob. | E29: Award | F29: RTP | G29: Prob. Boss round
A30: Awards granted: | B30: 3 | C30: 0.083333333 | D30: =+SUM(C30:$C$30) -> 0.083333333 | E30: =+E7 -> 6 | F30: =+C30*E30 -> 0.5 | G30: 0.06 | H30: (*) Enemy killed
A31: Prize #1 | B31: Total | C31: =+SUM(C30:C30) -> 0.083333333 | F31: =+SUM(F30:F30) -> 0.5
A32: Prize #2
A34: Table 5 | B34: Prize # | C34: Probability | D34: Cumulative prob. | E34: Award | F34: RTP | G34: Prob. Boss round
A35: Awards granted: | B35: 1 | C35: 0.07 | D35: =+SUM(C35:$C$35) -> 0.07 | E35: =+E5 -> 3 | F35: =+C35*E35 -> 0.21
A36: Prize #3 | B36: 2 | C36: 0.07 | D36: =+SUM(C$35:$C36) -> 0.14 | E36: =+E6 -> 3 | F36: =+C36*E36 -> 0.21
B37: 1 and 2 | C37: 0.013333333 | D37: =+SUM(C$35:$C37) -> 0.15333333 | E37: =+E35+E36 -> 6 | F37: =+C37*E37 -> 0.08 | G37: 0.375 | H37: (*) Enemy killed
B38: Total | C38: =+SUM(C35:C37) -> 0.15333333 | F38: =+SUM(F35:F37) -> 0.5
A41: Table 6 | B41: Prize # | C41: Probability | D41: Cumulative prob. | E41: Award | F41: RTP | G41: Prob. Boss round
A42: Awards granted: | B42: 1 | C42: 0.16666667 | D42: =+SUM(C42:$C$42) -> 0.16666667 | E42: =+E5 -> 3 | F42: =+E42*C42 -> 0.5 | G42: 0.03 | H42: (*) Enemy killed
A43: Prize #2 | B43: Total | C43: =+SUM(C42:C42) -> 0.16666667 | F43: =+SUM(F42:F42) -> 0.5
A44: Prize #3
A46: Table 7 | B46: Prize # | C46: Probability | D46: Cumulative prob. | E46: Award | F46: RTP | G46: Prob. Boss round
A47: Awards granted: | B47: 2 | C47: 0.16666667 | D47: =+SUM(C$47:$C47) -> 0.16666667 | E47: =+E6 -> 3 | F47: =+E47*C47 -> 0.5 | G47: 0.03 | H47: (*) Enemy killed
A48: Prize #1 | B48: Total | C48: =+SUM(C47:C47) -> 0.16666667 | F48: =+SUM(F47:F47) -> 0.5
A49: Prize #3

Sheet Base game (Standard Mummy)
A1: Standard Mummy
A2: For each shot with a regular weapon, draw the damage caused using the table according to prizes already granted by enemy that is being shot.
A4: Table 1 | B4: Prize # | C4: Probability | D4: Cumulative prob. | E4: Award | F4: RTP | G4: Prob. Boss round
A5: (Initial state) | B5: 1 | C5: 0.105 | D5: =+SUM($C$5:C5) -> 0.105 | E5: =+Summary!B27 -> 2 | F5: =+C5*E5 -> 0.21
B6: 2 | C6: 0.08 | D6: =+SUM($C$5:C6) -> 0.185 | E6: =+Summary!B28 -> 3 | F6: =+C6*E6 -> 0.24
B7: 1 and 2 | C7: 0.01 | D7: =+SUM($C$5:C7) -> 0.195 | E7: =+E5+E6 -> 5 | F7: =+C7*E7 -> 0.05 | G7: 0.5 | H7: (*) Enemy killed
B8: Total (*) | C8: =+SUM(C5:C7) -> 0.195 | F8: =+SUM(F5:F7) -> 0.5
B9: (*) Total probability is hit rate
A12: Table 6 | B12: Prize # | C12: Probability | D12: Cumulative prob. | E12: Award | F12: RTP | G12: Prob. Boss round
A13: Awards granted: | B13: 1 | C13: 0.25 | D13: =+SUM(C13:$C$13) -> 0.25 | E13: =+E5 -> 2 | F13: =+E13*C13 -> 0.5 | G13: 0.02 | H13: (*) Enemy killed
A14: Prize #2 | B14: Total | C14: =+SUM(C13:C13) -> 0.25 | F14: =+SUM(F13:F13) -> 0.5
A17: Table 7 | B17: Prize # | C17: Probability | D17: Cumulative prob. | E17: Award | F17: RTP | G17: Prob. Boss round
A18: Awards granted: | B18: 2 | C18: =1/6 -> 0.16666667 | D18: =+SUM(C$18:$C18) -> 0.16666667 | E18: =+E6 -> 3 | F18: =+E18*C18 -> 0.5 | G18: 0.03 | H18: (*) Enemy killed
A19: Prize #1 | B19: Total | C19: =+SUM(C18:C18) -> 0.16666667 | F19: =+SUM(F18:F18) -> 0.5

Sheet Base game (Scarabs)
A1: Scarabs
A4: Scarab black | B4: Prize # | C4: Probability | D4: Cumulative prob. | E4: Award | F4: RTP | G4: Prob. Boss round
B5: 1 | C5: 0.25 | D5: =+SUM(C5:$C$5) -> 0.25 | E5: =+Summary!B21 -> 2 | F5: =+E5*C5 -> 0.5 | G5: 0.02 | H5: (*) Enemy killed
B6: Total | C6: =+SUM(C5:C5) -> 0.25 | F6: =+SUM(F5:F5) -> 0.5
A9: Scarab gold | B9: Prize # | C9: Probability | D9: Cumulative prob. | E9: Award | F9: RTP | G9: Prob. Boss round
B10: 1 | C10: 0.16666667 | D10: =1/6 -> 0.16666667 | E10: =+Summary!E21 -> 3 | F10: =+E10*C10 -> 0.5 | G10: 0.03 | H10: (*) Enemy killed
B11: Total | C11: =+SUM(C10:C10) -> 0.16666667 | F11: =+SUM(F10:F10) -> 0.5
A14: Scarab gem covered | B14: Prize # | C14: Probability | D14: Cumulative prob. | E14: Award | F14: RTP | G14: Prob. Boss round
B15: 1 | C15: 0.125 | D15: =+SUM(C$15:$C15) -> 0.125 | E15: =+Summary!H21 -> 4 | F15: =+E15*C15 -> 0.5 | G15: 0.04 | H15: (*) Enemy killed
B16: Total | C16: =+SUM(C15:C15) -> 0.125 | F16: =+SUM(F15:F15) -> 0.5

Sheet Base game (Pharaoh A & B)
A1: Powerful Pharaoh Mummy A & B
A2: For each shot with a regular weapon, draw the damage caused using the table according to prizes already granted by enemy that is being shot.
A4: Table 1 | B4: Prize # | C4: Probability | D4: Cumulative prob. | E4: Award | F4: RTP | G4: Prob. Boss round
A5: (Initial state) | B5: 1 | C5: 0.07 | D5: =+SUM($C$5:C5) -> 0.07 | E5: =+Summary!B36 -> 2 | F5: =+C5*E5 -> 0.14
B6: 2 | C6: 0.009 | D6: =+SUM($C$5:C6) -> 0.079 | E6: =+Summary!B37 -> 5 | F6: =+C6*E6 -> 0.045
B7: 3 | C7: 0.01 | D7: =+SUM($C$5:C7) -> 0.089 | E7: =+Summary!B38 -> 8 | F7: =+C7*E7 -> 0.08
B8: 1 and 2 | C8: 0.005 | D8: =+SUM($C$5:C8) -> 0.094 | E8: =+E5+E6 -> 7 | F8: =+C8*E8 -> 0.035
B9: 1 and 3 | C9: 0.006 | D9: =+SUM($C$5:C9) -> 0.1 | E9: =+E5+E7 -> 10 | F9: =+C9*E9 -> 0.06
B10: 2 and 3 | C10: 0.005 | D10: =+SUM($C$5:C10) -> 0.105 | E10: =+E6+E7 -> 13 | F10: =+C10*E10 -> 0.065
B11: 1, 2 and 3 (*) | C11: 0.005 | D11: =+SUM($C$5:C11) -> 0.11 | E11: =+E5+E6+E7 -> 15 | F11: =+C11*E11 -> 0.075 | G11: 1 | H11: (*) Enemy killed
B12: Total (*) | C12: =+SUM(C5:C11) -> 0.11 | F12: =+SUM(F5:F11) -> 0.5
B13: (*) Total probability is hit rate
A15: Table 2 | B15: Prize # | C15: Probability | D15: Cumulative prob. | E15: Award | F15: RTP | G15: Prob. Boss round
A16: Awards granted: | B16: 2 | C16: 0.08 | D16: =+SUM(C16:$C$16) -> 0.08 | E16: =+E6 -> 5 | F16: =+C16*E16 -> 0.4
A17: Prize #1 | B17: 3 | C17: 0.004375 | D17: =+SUM(C$16:$C17) -> 0.084375 | E17: =+E7 -> 8 | F17: =+C17*E17 -> 0.035
B18: 2 and 3 | C18: 0.005 | D18: =+SUM(C$16:$C18) -> 0.089375 | E18: =+E16+E17 -> 13 | F18: =+C18*E18 -> 0.065 | G18: 1 | H18: (*) Enemy killed
B19: Total | C19: =+SUM(C16:C18) -> 0.089375 | F19: =+SUM(F16:F18) -> 0.5
A22: Table 3 | B22: Prize # | C22: Probability | D22: Cumulative prob. | E22: Award | F22: RTP | G22: Prob. Boss round
A23: Awards granted: | B23: 1 | C23: 0.12 | D23: =+SUM(C23:$C$23) -> 0.12 | E23: =+E5 -> 2 | F23: =+C23*E23 -> 0.24
A24: Prize #2 | B24: 3 | C24: 0.02 | D24: =+SUM(C$23:$C24) -> 0.14 | E24: =+E7 -> 8 | F24: =+C24*E24 -> 0.16
B25: 1 and 3 | C25: 0.01 | D25: =+SUM(C$23:$C25) -> 0.15 | E25: =+E23+E24 -> 10 | F25: =+C25*E25 -> 0.1 | G25: 0.5 | H25: (*) Enemy killed
B26: Total | C26: =+SUM(C23:C25) -> 0.15 | F26: =+SUM(F23:F25) -> 0.5
A29: Table 4 | B29: Prize # | C29: Probability | D29: Cumulative prob. | E29: Award | F29: RTP | G29: Prob. Boss round
A30: Awards granted: | B30: 3 | C30: 0.0625 | D30: =+SUM(C30:$C$30) -> 0.0625 | E30: =+E7 -> 8 | F30: =+C30*E30 -> 0.5 | G30: 0.08 | H30: (*) Enemy killed
A31: Prize #1 | B31: Total | C31: =+SUM(C30:C30) -> 0.0625 | F31: =+SUM(F30:F30) -> 0.5
A32: Prize #2
A34: Table 5 | B34: Prize # | C34: Probability | D34: Cumulative prob. | E34: Award | F34: RTP | G34: Prob. Boss round
A35: Awards granted: | B35: 1 | C35: 0.115 | D35: =+SUM(C35:$C$35) -> 0.115 | E35: =+E5 -> 2 | F35: =+C35*E35 -> 0.23
A36: Prize #3 | B36: 2 | C36: 0.04 | D36: =+SUM(C$35:$C36) -> 0.155 | E36: =+E6 -> 5 | F36: =+C36*E36 -> 0.2
B37: 1 and 2 | C37: 0.01 | D37: =+SUM(C$35:$C37) -> 0.165 | E37: =+E35+E36 -> 7 | F37: =+C37*E37 -> 0.07 | G37: 0.5 | H37: (*) Enemy killed
B38: Total | C38: =+SUM(C35:C37) -> 0.165 | F38: =+SUM(F35:F37) -> 0.5
A41: Table 6 | B41: Prize # | C41: Probability | D41: Cumulative prob. | E41: Award | F41: RTP | G41: Prob. Boss round
A42: Awards granted: | B42: 1 | C42: 0.25 | D42: =+SUM(C42:$C$42) -> 0.25 | E42: =+E5 -> 2 | F42: =+E42*C42 -> 0.5 | G42: 0.02 | H42: (*) Enemy killed
A43: Prize #2 | B43: Total | C43: =+SUM(C42:C42) -> 0.25 | F43: =+SUM(F42:F42) -> 0.5
A44: Prize #3
A46: Table 7 | B46: Prize # | C46: Probability | D46: Cumulative prob. | E46: Award | F46: RTP | G46: Prob. Boss round
A47: Awards granted: | B47: 2 | C47: 0.1 | D47: =+SUM(C$47:$C47) -> 0.1 | E47: =+E6 -> 5 | F47: =+E47*C47 -> 0.5 | G47: 0.05 | H47: (*) Enemy killed
A48: Prize #1 | B48: Total | C48: =+SUM(C47:C47) -> 0.1 | F48: =+SUM(F47:F47) -> 0.5
A49: Prize #3

Sheet Special weapon 1 (Mummy A) 
A1: SPECIAL WEAPON 1 - Medium Mummy A (golden wrist bands)
A2: For each shot with a special weapon, draw the damage caused using the table according to prizes already granted by enemy that is being shot.
A4: Table 1 | B4: Prize # | C4: Probability | D4: Cumulative prob. | E4: Award | F4: RTP | G4: Prob. Boss round
A5: (Initial state) | B5: 1 | C5: 0.25 | D5: =+SUM($C$5:C5) -> 0.25 | E5: =Summary!E27 -> 0 | F5: =+C5*E5 -> 0
B6: 2 | C6: 0.3 | D6: =+SUM($C$5:C6) -> 0.55 | E6: =Summary!E28 -> 2 | F6: =+C6*E6 -> 0.6
B7: 3 | C7: 0.05 | D7: =+SUM($C$5:C7) -> 0.6 | E7: =Summary!E29 -> 3 | F7: =+C7*E7 -> 0.15
B8: 1 and 2 | C8: 0.075 | D8: =+SUM($C$5:C8) -> 0.675 | E8: =+E5+E6 -> 2 | F8: =+C8*E8 -> 0.15
B9: 1 and 3 | C9: 0.025 | D9: =+SUM($C$5:C9) -> 0.7 | E9: =+E5+E7 -> 3 | F9: =+C9*E9 -> 0.075
B10: 2 and 3 | C10: 0.04 | D10: =+SUM($C$5:C10) -> 0.74 | E10: =+E6+E7 -> 5 | F10: =+C10*E10 -> 0.2
B11: 1, 2 and 3 (*) | C11: 0.005 | D11: =+SUM($C$5:C11) -> 0.745 | E11: =+E5+E6+E7 -> 5 | F11: =+C11*E11 -> 0.025 | G11: 0 | H11: (*) Enemy killed
B12: Total (*) | C12: =+SUM(C5:C11) -> 0.745 | F12: =+SUM(F5:F11) -> 1.2
B13: (*) Total probability is hit rate
A15: Table 2 | B15: Prize # | C15: Probability | D15: Cumulative prob. | E15: Award | F15: RTP | G15: Prob. Boss round
A16: Awards granted: | B16: 2 | C16: 0.45 | D16: =+SUM(C16:$C$16) -> 0.45 | E16: =+E6 -> 2 | F16: =+C16*E16 -> 0.9
A17: Prize #1 | B17: 3 | C17: 0.05 | D17: =+SUM(C$16:$C17) -> 0.5 | E17: =+E7 -> 3 | F17: =+C17*E17 -> 0.15
B18: 2 and 3 | C18: 0.03 | D18: =+SUM(C$16:$C18) -> 0.53 | E18: =+E16+E17 -> 5 | F18: =+C18*E18 -> 0.15 | G18: 0 | H18: (*) Enemy killed
B19: Total | C19: =+SUM(C16:C18) -> 0.53 | F19: =+SUM(F16:F18) -> 1.2
A22: Table 3 | B22: Prize # | C22: Probability | D22: Cumulative prob. | E22: Award | F22: RTP | G22: Prob. Boss round
A23: Awards granted: | B23: 1 | C23: 0.6 | D23: =+SUM(C23:$C$23) -> 0.6 | E23: =+E5 -> 0 | F23: =+C23*E23 -> 0
A24: Prize #2 | B24: 3 | C24: 0.37 | D24: =+SUM(C$23:$C24) -> 0.97 | E24: =+E7 -> 3 | F24: =+C24*E24 -> 1.11
B25: 1 and 3 | C25: 0.03 | D25: =+SUM(C$23:$C25) -> 1 | E25: =+E23+E24 -> 3 | F25: =+C25*E25 -> 0.09 | G25: 0 | H25: (*) Enemy killed
B26: Total | C26: =+SUM(C23:C25) -> 1 | F26: =+SUM(F23:F25) -> 1.2
A29: Table 4 | B29: Prize # | C29: Probability | D29: Cumulative prob. | E29: Award | F29: RTP | G29: Prob. Boss round
A30: Awards granted: | B30: 3 | C30: 0.4 | D30: =+SUM(C30:$C$30) -> 0.4 | E30: =+E7 -> 3 | F30: =+C30*E30 -> 1.2 | G30: 0 | H30: (*) Enemy killed
A31: Prize #1 | B31: Total | C31: =+SUM(C30:C30) -> 0.4 | F31: =+SUM(F30:F30) -> 1.2
A32: Prize #2
A34: Table 5 | B34: Prize # | C34: Probability | D34: Cumulative prob. | E34: Award | F34: RTP | G34: Prob. Boss round
A35: Awards granted: | B35: 1 | C35: 0.35 | D35: =+SUM(C35:$C$35) -> 0.35 | E35: =+E5 -> 0 | F35: =+C35*E35 -> 0
A36: Prize #3 | B36: 2 | C36: 0.55 | D36: =+SUM(C$35:$C36) -> 0.9 | E36: =+E6 -> 2 | F36: =+C36*E36 -> 1.1
B37: 1 and 2 | C37: 0.05 | D37: =+SUM(C$35:$C37) -> 0.95 | E37: =+E35+E36 -> 2 | F37: =+C37*E37 -> 0.1 | G37: 0 | H37: (*) Enemy killed
B38: Total | C38: =+SUM(C35:C37) -> 0.95 | F38: =+SUM(F35:F37) -> 1.2
A41: Table 6 | B41: Prize # | C41: Probability | D41: Cumulative prob. | E41: Award | F41: RTP
A42: Awards granted: | B42: 1 | C42: 0.8 | D42: =+SUM(C42:$C$42) -> 0.8 | E42: =+E5 -> 0 | F42: =+E42*C42 -> 0 | G42: 0 | H42: (*) Enemy killed
A43: Prize #2 | B43: Total | C43: =+SUM(C42:C42) -> 0.8 | F43: =+SUM(F42:F42) -> 0
A44: Prize #3
A46: Table 7 | B46: Prize # | C46: Probability | D46: Cumulative prob. | E46: Award | F46: RTP
A47: Awards granted: | B47: 2 | C47: 0.6 | D47: =+SUM(C$47:$C47) -> 0.6 | E47: =+E6 -> 2 | F47: =+E47*C47 -> 1.2 | G47: 0 | H47: (*) Enemy killed
A48: Prize #1 | B48: Total | C48: =+SUM(C47:C47) -> 0.6 | F48: =+SUM(F47:F47) -> 1.2
A49: Prize #3

Sheet Special weapon 1 (Mummy B)
A1: SPECIAL WEAPON 1 - Medium Mummy B (golden wrist bands and necklace)
A2: For each shot with a special weapon, draw the damage caused using the table according to prizes already granted by enemy that is being shot.
A4: Table 1 | B4: Prize # | C4: Probability | D4: Cumulative prob. | E4: Award | F4: RTP | G4: Prob. Boss round
A5: (Initial state) | B5: 1 | C5: 0.2 | D5: =+SUM($C$5:C5) -> 0.2 | E5: =+Summary!H27 -> 2 | F5: =+C5*E5 -> 0.4
B6: 2 | C6: 0.2 | D6: =+SUM($C$5:C6) -> 0.4 | E6: =+Summary!H28 -> 2 | F6: =+C6*E6 -> 0.4
B7: 3 | C7: 0.01 | D7: =+SUM($C$5:C7) -> 0.41 | E7: =+Summary!H29 -> 4 | F7: =+C7*E7 -> 0.04
B8: 1 and 2 | C8: 0.05 | D8: =+SUM($C$5:C8) -> 0.46 | E8: =+E5+E6 -> 4 | F8: =+C8*E8 -> 0.2
B9: 1 and 3 | C9: 0.01 | D9: =+SUM($C$5:C9) -> 0.47 | E9: =+E5+E7 -> 6 | F9: =+C9*E9 -> 0.06
B10: 2 and 3 | C10: 0.01 | D10: =+SUM($C$5:C10) -> 0.48 | E10: =+E6+E7 -> 6 | F10: =+C10*E10 -> 0.06
B11: 1, 2 and 3 (*) | C11: 0.005 | D11: =+SUM($C$5:C11) -> 0.485 | E11: =+E5+E6+E7 -> 8 | F11: =+C11*E11 -> 0.04 | G11: 0 | H11: (*) Enemy killed
B12: Total (*) | C12: =+SUM(C5:C11) -> 0.485 | F12: =+SUM(F5:F11) -> 1.2
B13: (*) Total probability is hit rate
A15: Table 2 | B15: Prize # | C15: Probability | D15: Cumulative prob. | E15: Award | F15: RTP | G15: Prob. Boss round
A16: Awards granted: | B16: 2 | C16: 0.5 | D16: =+SUM(C16:$C$16) -> 0.5 | E16: =+E6 -> 2 | F16: =+C16*E16 -> 1
A17: Prize #1 | B17: 3 | C17: 0.02 | D17: =+SUM(C$16:$C17) -> 0.52 | E17: =+E7 -> 4 | F17: =+C17*E17 -> 0.08
B18: 2 and 3 | C18: 0.02 | D18: =+SUM(C$16:$C18) -> 0.54 | E18: =+E16+E17 -> 6 | F18: =+C18*E18 -> 0.12 | G18: 0 | H18: (*) Enemy killed
B19: Total | C19: =+SUM(C16:C18) -> 0.54 | F19: =+SUM(F16:F18) -> 1.2
A22: Table 3 | B22: Prize # | C22: Probability | D22: Cumulative prob. | E22: Award | F22: RTP | G22: Prob. Boss round
A23: Awards granted: | B23: 1 | C23: 0.5 | D23: =+SUM(C23:$C$23) -> 0.5 | E23: =+E5 -> 2 | F23: =+C23*E23 -> 1
A24: Prize #2 | B24: 3 | C24: 0.02 | D24: =+SUM(C$23:$C24) -> 0.52 | E24: =+E7 -> 4 | F24: =+C24*E24 -> 0.08
B25: 1 and 3 | C25: 0.02 | D25: =+SUM(C$23:$C25) -> 0.54 | E25: =+E23+E24 -> 6 | F25: =+C25*E25 -> 0.12 | G25: 0 | H25: (*) Enemy killed
B26: Total | C26: =+SUM(C23:C25) -> 0.54 | F26: =+SUM(F23:F25) -> 1.2
A29: Table 4 | B29: Prize # | C29: Probability | D29: Cumulative prob. | E29: Award | F29: RTP | G29: Prob. Boss round
A30: Awards granted: | B30: 3 | C30: 0.3 | D30: =+SUM(C30:$C$30) -> 0.3 | E30: =+E7 -> 4 | F30: =+C30*E30 -> 1.2 | G30: 0 | H30: (*) Enemy killed
A31: Prize #1 | B31: Total | C31: =+SUM(C30:C30) -> 0.3 | F31: =+SUM(F30:F30) -> 1.2
A32: Prize #2
A34: Table 5 | B34: Prize # | C34: Probability | D34: Cumulative prob. | E34: Award | F34: RTP | G34: Prob. Boss round
A35: Awards granted: | B35: 1 | C35: 0.28 | D35: =+SUM(C35:$C$35) -> 0.28 | E35: =+E5 -> 2 | F35: =+C35*E35 -> 0.56
A36: Prize #3 | B36: 2 | C36: 0.28 | D36: =+SUM(C$35:$C36) -> 0.56 | E36: =+E6 -> 2 | F36: =+C36*E36 -> 0.56
B37: 1 and 2 | C37: 0.02 | D37: =+SUM(C$35:$C37) -> 0.58 | E37: =+E35+E36 -> 4 | F37: =+C37*E37 -> 0.08 | G37: 0 | H37: (*) Enemy killed
B38: Total | C38: =+SUM(C35:C37) -> 0.58 | F38: =+SUM(F35:F37) -> 1.2
A41: Table 6 | B41: Prize # | C41: Probability | D41: Cumulative prob. | E41: Award | F41: RTP
A42: Awards granted: | B42: 1 | C42: 0.6 | D42: =+SUM(C42:$C$42) -> 0.6 | E42: =+E5 -> 2 | F42: =+E42*C42 -> 1.2 | G42: 0 | H42: (*) Enemy killed
A43: Prize #2 | B43: Total | C43: =+SUM(C42:C42) -> 0.6 | F43: =+SUM(F42:F42) -> 1.2
A44: Prize #3
A46: Table 7 | B46: Prize # | C46: Probability | D46: Cumulative prob. | E46: Award | F46: RTP
A47: Awards granted: | B47: 2 | C47: 0.6 | D47: =+SUM(C$47:$C47) -> 0.6 | E47: =+E6 -> 2 | F47: =+E47*C47 -> 1.2 | G47: 0 | H47: (*) Enemy killed
A48: Prize #1 | B48: Total | C48: =+SUM(C47:C47) -> 0.6 | F48: =+SUM(F47:F47) -> 1.2
A49: Prize #3

Sheet Special weapon 1 (Mummy C)
A1: SPECIAL WEAPON 1 - Medium Mummy C (golden boots and wrist bands)
A2: For each shot with a special weapon, draw the damage caused using the table according to prizes already granted by enemy that is being shot.
A4: Table 1 | B4: Prize # | C4: Probability | D4: Cumulative prob. | E4: Award | F4: RTP | G4: Prob. Boss round
A5: (Initial state) | B5: 1 | C5: 0.12 | D5: =+SUM($C$5:C5) -> 0.12 | E5: =Summary!K27 -> 3 | F5: =+C5*E5 -> 0.36
B6: 2 | C6: 0.12 | D6: =+SUM($C$5:C6) -> 0.24 | E6: =Summary!K28 -> 3 | F6: =+C6*E6 -> 0.36
B7: 3 | C7: 0.02 | D7: =+SUM($C$5:C7) -> 0.26 | E7: =Summary!K29 -> 6 | F7: =+C7*E7 -> 0.12
B8: 1 and 2 | C8: 0.02 | D8: =+SUM($C$5:C8) -> 0.28 | E8: =+E5+E6 -> 6 | F8: =+C8*E8 -> 0.12
B9: 1 and 3 | C9: 0.01 | D9: =+SUM($C$5:C9) -> 0.29 | E9: =+E5+E7 -> 9 | F9: =+C9*E9 -> 0.09
B10: 2 and 3 | C10: 0.01 | D10: =+SUM($C$5:C10) -> 0.3 | E10: =+E6+E7 -> 9 | F10: =+C10*E10 -> 0.09
B11: 1, 2 and 3 (*) | C11: 0.005 | D11: =+SUM($C$5:C11) -> 0.305 | E11: =+E5+E6+E7 -> 12 | F11: =+C11*E11 -> 0.06 | G11: 0 | H11: (*) Enemy killed
B12: Total (*) | C12: =+SUM(C5:C11) -> 0.305 | F12: =+SUM(F5:F11) -> 1.2
B13: (*) Total probability is hit rate
A15: Table 2 | B15: Prize # | C15: Probability | D15: Cumulative prob. | E15: Award | F15: RTP | G15: Prob. Boss round
A16: Awards granted: | B16: 2 | C16: 0.3 | D16: =+SUM(C16:$C$16) -> 0.3 | E16: =+E6 -> 3 | F16: =+C16*E16 -> 0.9
A17: Prize #1 | B17: 3 | C17: 0.02 | D17: =+SUM(C$16:$C17) -> 0.32 | E17: =+E7 -> 6 | F17: =+C17*E17 -> 0.12
B18: 2 and 3 | C18: 0.02 | D18: =+SUM(C$16:$C18) -> 0.34 | E18: =+E16+E17 -> 9 | F18: =+C18*E18 -> 0.18 | G18: 0 | H18: (*) Enemy killed
B19: Total | C19: =+SUM(C16:C18) -> 0.34 | F19: =+SUM(F16:F18) -> 1.2
A22: Table 3 | B22: Prize # | C22: Probability | D22: Cumulative prob. | E22: Award | F22: RTP | G22: Prob. Boss round
A23: Awards granted: | B23: 1 | C23: 0.3 | D23: =+SUM(C23:$C$23) -> 0.3 | E23: =+E5 -> 3 | F23: =+C23*E23 -> 0.9
A24: Prize #2 | B24: 3 | C24: 0.02 | D24: =+SUM(C$23:$C24) -> 0.32 | E24: =+E7 -> 6 | F24: =+C24*E24 -> 0.12
B25: 1 and 3 | C25: 0.02 | D25: =+SUM(C$23:$C25) -> 0.34 | E25: =+E23+E24 -> 9 | F25: =+C25*E25 -> 0.18 | G25: 0 | H25: (*) Enemy killed
B26: Total | C26: =+SUM(C23:C25) -> 0.34 | F26: =+SUM(F23:F25) -> 1.2
A29: Table 4 | B29: Prize # | C29: Probability | D29: Cumulative prob. | E29: Award | F29: RTP | G29: Prob. Boss round
A30: Awards granted: | B30: 3 | C30: 0.2 | D30: =+SUM(C30:$C$30) -> 0.2 | E30: =+E7 -> 6 | F30: =+C30*E30 -> 1.2 | G30: 0 | H30: (*) Enemy killed
A31: Prize #1 | B31: Total | C31: =+SUM(C30:C30) -> 0.2 | F31: =+SUM(F30:F30) -> 1.2
A32: Prize #2
A34: Table 5 | B34: Prize # | C34: Probability | D34: Cumulative prob. | E34: Award | F34: RTP | G34: Prob. Boss round
A35: Awards granted: | B35: 1 | C35: 0.16 | D35: =+SUM(C35:$C$35) -> 0.16 | E35: =+E5 -> 3 | F35: =+C35*E35 -> 0.48
A36: Prize #3 | B36: 2 | C36: 0.16 | D36: =+SUM(C$35:$C36) -> 0.32 | E36: =+E6 -> 3 | F36: =+C36*E36 -> 0.48
B37: 1 and 2 | C37: 0.04 | D37: =+SUM(C$35:$C37) -> 0.36 | E37: =+E35+E36 -> 6 | F37: =+C37*E37 -> 0.24 | G37: 0 | H37: (*) Enemy killed
B38: Total | C38: =+SUM(C35:C37) -> 0.36 | F38: =+SUM(F35:F37) -> 1.2
A41: Table 6 | B41: Prize # | C41: Probability | D41: Cumulative prob. | E41: Award | F41: RTP
A42: Awards granted: | B42: 1 | C42: 0.4 | D42: =+SUM(C42:$C$42) -> 0.4 | E42: =+E5 -> 3 | F42: =+E42*C42 -> 1.2 | G42: 0 | H42: (*) Enemy killed
A43: Prize #2 | B43: Total | C43: =+SUM(C42:C42) -> 0.4 | F43: =+SUM(F42:F42) -> 1.2
A44: Prize #3
A46: Table 7 | B46: Prize # | C46: Probability | D46: Cumulative prob. | E46: Award | F46: RTP
A47: Awards granted: | B47: 2 | C47: 0.4 | D47: =+SUM(C$47:$C47) -> 0.4 | E47: =+E6 -> 3 | F47: =+E47*C47 -> 1.2 | G47: 0 | H47: (*) Enemy killed
A48: Prize #1 | B48: Total | C48: =+SUM(C47:C47) -> 0.4 | F48: =+SUM(F47:F47) -> 1.2
A49: Prize #3

Sheet Special weapon 1 (Std Mummy)
A1: SPECIAL WEAPON 1 - Standard Mummy
A2: For each shot with a special weapon, draw the damage caused using the table according to prizes already granted by enemy that is being shot.
A4: Table 1 | B4: Prize # | C4: Probability | D4: Cumulative prob. | E4: Award | F4: RTP | G4: Prob. Boss round
A5: (Initial state) | B5: 1 | C5: 0.26 | D5: =+SUM($C$5:C5) -> 0.26 | E5: =+Summary!B27 -> 2 | F5: =+C5*E5 -> 0.52
B6: 2 | C6: 0.16 | D6: =+SUM($C$5:C6) -> 0.42 | E6: =+Summary!B28 -> 3 | F6: =+C6*E6 -> 0.48
B7: 1 and 2 | C7: 0.04 | D7: =+SUM($C$5:C7) -> 0.46 | E7: =+E5+E6 -> 5 | F7: =+C7*E7 -> 0.2 | G7: 0 | H7: (*) Enemy killed
B8: Total (*) | C8: =+SUM(C5:C7) -> 0.46 | F8: =+SUM(F5:F7) -> 1.2
B9: (*) Total probability is hit rate
A12: Table 6 | B12: Prize # | C12: Probability | D12: Cumulative prob. | E12: Award | F12: RTP | G12: Prob. Boss round
A13: Awards granted: | B13: 1 | C13: 0.6 | D13: =+SUM(C13:$C$13) -> 0.6 | E13: =+E5 -> 2 | F13: =+E13*C13 -> 1.2 | G13: 0 | H13: (*) Enemy killed
A14: Prize #2 | B14: Total | C14: =+SUM(C13:C13) -> 0.6 | F14: =+SUM(F13:F13) -> 1.2
A17: Table 7 | B17: Prize # | C17: Probability | D17: Cumulative prob. | E17: Award | F17: RTP | G17: Prob. Boss round
A18: Awards granted: | B18: 2 | C18: 0.4 | D18: =+SUM(C$18:$C18) -> 0.4 | E18: =+E6 -> 3 | F18: =+E18*C18 -> 1.2 | G18: 0 | H18: (*) Enemy killed
A19: Prize #1 | B19: Total | C19: =+SUM(C18:C18) -> 0.4 | F19: =+SUM(F18:F18) -> 1.2

Sheet Special weapon 1 (Scarabs)
A1: SPECIAL WEAPON 1 - Scarabs
A2: For each shot with a special weapon, draw the damage caused using the table according to prizes already granted by enemy that is being shot.
A4: Scarab black | B4: Prize # | C4: Probability | D4: Cumulative prob. | E4: Award | F4: RTP | G4: Prob. Boss round
B5: 1 | C5: 0.6 | D5: =+SUM(C5:$C$5) -> 0.6 | E5: =+Summary!B21 -> 2 | F5: =+E5*C5 -> 1.2 | G5: 0 | H5: (*) Enemy killed
B6: Total | C6: =+SUM(C5:C5) -> 0.6 | F6: =+SUM(F5:F5) -> 1.2
A9: Scarab gold | B9: Prize # | C9: Probability | D9: Cumulative prob. | E9: Award | F9: RTP | G9: Prob. Boss round
B10: 1 | C10: 0.4 | D10: =1/6 -> 0.16666667 | E10: =+Summary!E21 -> 3 | F10: =+E10*C10 -> 1.2 | G10: 0 | H10: (*) Enemy killed
B11: Total | C11: =+SUM(C10:C10) -> 0.4 | F11: =+SUM(F10:F10) -> 1.2
A14: Scarab gem covered | B14: Prize # | C14: Probability | D14: Cumulative prob. | E14: Award | F14: RTP | G14: Prob. Boss round
B15: 1 | C15: 0.3 | D15: =+SUM(C$15:$C15) -> 0.3 | E15: =+Summary!H21 -> 4 | F15: =+E15*C15 -> 1.2 | G15: 0 | H15: (*) Enemy killed
B16: Total | C16: =+SUM(C15:C15) -> 0.3 | F16: =+SUM(F15:F15) -> 1.2

Sheet Special weapon 1 (Pharaoh A&B)
A1: SPECIAL WEAPON 1 - Powerful Pharaoh Mummy A & B
A2: For each shot with a special weapon, draw the damage caused using the table according to prizes already granted by enemy that is being shot.
A4: Table 1 | B4: Prize # | C4: Probability | D4: Cumulative prob. | E4: Award | F4: RTP | G4: Prob. Boss round
A5: (Initial state) | B5: 1 | C5: 0.12 | D5: =+SUM($C$5:C5) -> 0.12 | E5: =+Summary!B36 -> 2 | F5: =+C5*E5 -> 0.24
B6: 2 | C6: 0.01 | D6: =+SUM($C$5:C6) -> 0.13 | E6: =+Summary!B37 -> 5 | F6: =+C6*E6 -> 0.05
B7: 3 | C7: 0.01 | D7: =+SUM($C$5:C7) -> 0.14 | E7: =+Summary!B38 -> 8 | F7: =+C7*E7 -> 0.08
B8: 1 and 2 | C8: 0.01 | D8: =+SUM($C$5:C8) -> 0.15 | E8: =+E5+E6 -> 7 | F8: =+C8*E8 -> 0.07
B9: 1 and 3 | C9: 0.02 | D9: =+SUM($C$5:C9) -> 0.17 | E9: =+E5+E7 -> 10 | F9: =+C9*E9 -> 0.2
B10: 2 and 3 | C10: 0.02 | D10: =+SUM($C$5:C10) -> 0.19 | E10: =+E6+E7 -> 13 | F10: =+C10*E10 -> 0.26
B11: 1, 2 and 3 (*) | C11: 0.02 | D11: =+SUM($C$5:C11) -> 0.21 | E11: =+E5+E6+E7 -> 15 | F11: =+C11*E11 -> 0.3 | G11: 0 | H11: (*) Enemy killed
B12: Total (*) | C12: =+SUM(C5:C11) -> 0.21 | F12: =+SUM(F5:F11) -> 1.2
B13: (*) Total probability is hit rate
A15: Table 2 | B15: Prize # | C15: Probability | D15: Cumulative prob. | E15: Award | F15: RTP | G15: Prob. Boss round
A16: Awards granted: | B16: 2 | C16: 0.12 | D16: =+SUM(C16:$C$16) -> 0.12 | E16: =+E6 -> 5 | F16: =+C16*E16 -> 0.6
A17: Prize #1 | B17: 3 | C17: 0.01 | D17: =+SUM(C$16:$C17) -> 0.13 | E17: =+E7 -> 8 | F17: =+C17*E17 -> 0.08
B18: 2 and 3 | C18: 0.04 | D18: =+SUM(C$16:$C18) -> 0.17 | E18: =+E16+E17 -> 13 | F18: =+C18*E18 -> 0.52 | G18: 0 | H18: (*) Enemy killed
B19: Total | C19: =+SUM(C16:C18) -> 0.17 | F19: =+SUM(F16:F18) -> 1.2
A22: Table 3 | B22: Prize # | C22: Probability | D22: Cumulative prob. | E22: Award | F22: RTP | G22: Prob. Boss round
A23: Awards granted: | B23: 1 | C23: 0.15 | D23: =+SUM(C23:$C$23) -> 0.15 | E23: =+E5 -> 2 | F23: =+C23*E23 -> 0.3
A24: Prize #2 | B24: 3 | C24: 0.05 | D24: =+SUM(C$23:$C24) -> 0.2 | E24: =+E7 -> 8 | F24: =+C24*E24 -> 0.4
B25: 1 and 3 | C25: 0.05 | D25: =+SUM(C$23:$C25) -> 0.25 | E25: =+E23+E24 -> 10 | F25: =+C25*E25 -> 0.5 | G25: 0 | H25: (*) Enemy killed
B26: Total | C26: =+SUM(C23:C25) -> 0.25 | F26: =+SUM(F23:F25) -> 1.2
A29: Table 4 | B29: Prize # | C29: Probability | D29: Cumulative prob. | E29: Award | F29: RTP | G29: Prob. Boss round
A30: Awards granted: | B30: 3 | C30: 0.15 | D30: =+SUM(C30:$C$30) -> 0.15 | E30: =+E7 -> 8 | F30: =+C30*E30 -> 1.2 | G30: 0 | H30: (*) Enemy killed
A31: Prize #1 | B31: Total | C31: =+SUM(C30:C30) -> 0.15 | F31: =+SUM(F30:F30) -> 1.2
A32: Prize #2
A34: Table 5 | B34: Prize # | C34: Probability | D34: Cumulative prob. | E34: Award | F34: RTP | G34: Prob. Boss round
A35: Awards granted: | B35: 1 | C35: 0.14 | D35: =+SUM(C35:$C$35) -> 0.14 | E35: =+E5 -> 2 | F35: =+C35*E35 -> 0.28
A36: Prize #3 | B36: 2 | C36: 0.1 | D36: =+SUM(C$35:$C36) -> 0.24 | E36: =+E6 -> 5 | F36: =+C36*E36 -> 0.5
B37: 1 and 2 | C37: 0.06 | D37: =+SUM(C$35:$C37) -> 0.3 | E37: =+E35+E36 -> 7 | F37: =+C37*E37 -> 0.42 | G37: 0 | H37: (*) Enemy killed
B38: Total | C38: =+SUM(C35:C37) -> 0.3 | F38: =+SUM(F35:F37) -> 1.2
A41: Table 6 | B41: Prize # | C41: Probability | D41: Cumulative prob. | E41: Award | F41: RTP | G41: Prob. Boss round
A42: Awards granted: | B42: 1 | C42: 0.6 | D42: =+SUM(C42:$C$42) -> 0.6 | E42: =+E5 -> 2 | F42: =+E42*C42 -> 1.2 | G42: 0 | H42: (*) Enemy killed
A43: Prize #2 | B43: Total | C43: =+SUM(C42:C42) -> 0.6 | F43: =+SUM(F42:F42) -> 1.2
A44: Prize #3
A46: Table 7 | B46: Prize # | C46: Probability | D46: Cumulative prob. | E46: Award | F46: RTP | G46: Prob. Boss round
A47: Awards granted: | B47: 2 | C47: 0.24 | D47: =+SUM(C$47:$C47) -> 0.24 | E47: =+E6 -> 5 | F47: =+E47*C47 -> 1.2 | G47: 0 | H47: (*) Enemy killed
A48: Prize #1 | B48: Total | C48: =+SUM(C47:C47) -> 0.24 | F48: =+SUM(F47:F47) -> 1.2
A49: Prize #3

Sheet Special weapon 2 (Mummy A)
A1: SPECIAL WEAPON 2 - Medium Mummy A (golden wrist bands)
A2: For each shot with a special weapon, draw the damage caused using the table according to prizes already granted by enemy that is being shot.
A4: Table 1 | B4: Prize # | C4: Probability | D4: Cumulative prob. | E4: Award | F4: RTP | G4: Prob. Boss round
A5: (Initial state) | B5: 1 | C5: 0.2 | D5: =+SUM($C$5:C5) -> 0.2 | E5: =Summary!E27 -> 0 | F5: =+C5*E5 -> 0
B6: 2 | C6: 0.305 | D6: =+SUM($C$5:C6) -> 0.505 | E6: =Summary!E28 -> 2 | F6: =+C6*E6 -> 0.61
B7: 3 | C7: 0.045 | D7: =+SUM($C$5:C7) -> 0.55 | E7: =Summary!E29 -> 3 | F7: =+C7*E7 -> 0.135
B8: 1 and 2 | C8: 0.1 | D8: =+SUM($C$5:C8) -> 0.65 | E8: =+E5+E6 -> 2 | F8: =+C8*E8 -> 0.2
B9: 1 and 3 | C9: 0.01 | D9: =+SUM($C$5:C9) -> 0.66 | E9: =+E5+E7 -> 3 | F9: =+C9*E9 -> 0.03
B10: 2 and 3 | C10: 0.01 | D10: =+SUM($C$5:C10) -> 0.67 | E10: =+E6+E7 -> 5 | F10: =+C10*E10 -> 0.05
B11: 1, 2 and 3 (*) | C11: 0.005 | D11: =+SUM($C$5:C11) -> 0.675 | E11: =+E5+E6+E7 -> 5 | F11: =+C11*E11 -> 0.025 | G11: 0 | H11: (*) Enemy killed
B12: Total (*) | C12: =+SUM(C5:C11) -> 0.675 | F12: =+SUM(F5:F11) -> 1.05
B13: (*) Total probability is hit rate
A15: Table 2 | B15: Prize # | C15: Probability | D15: Cumulative prob. | E15: Award | F15: RTP | G15: Prob. Boss round
A16: Awards granted: | B16: 2 | C16: 0.375 | D16: =+SUM(C16:$C$16) -> 0.375 | E16: =+E6 -> 2 | F16: =+C16*E16 -> 0.75
A17: Prize #1 | B17: 3 | C17: 0.05 | D17: =+SUM(C$16:$C17) -> 0.425 | E17: =+E7 -> 3 | F17: =+C17*E17 -> 0.15
B18: 2 and 3 | C18: 0.03 | D18: =+SUM(C$16:$C18) -> 0.455 | E18: =+E16+E17 -> 5 | F18: =+C18*E18 -> 0.15 | G18: 0 | H18: (*) Enemy killed
B19: Total | C19: =+SUM(C16:C18) -> 0.455 | F19: =+SUM(F16:F18) -> 1.05
A22: Table 3 | B22: Prize # | C22: Probability | D22: Cumulative prob. | E22: Award | F22: RTP | G22: Prob. Boss round
A23: Awards granted: | B23: 1 | C23: 0.5 | D23: =+SUM(C23:$C$23) -> 0.5 | E23: =+E5 -> 0 | F23: =+C23*E23 -> 0
A24: Prize #2 | B24: 3 | C24: 0.32 | D24: =+SUM(C$23:$C24) -> 0.82 | E24: =+E7 -> 3 | F24: =+C24*E24 -> 0.96
B25: 1 and 3 | C25: 0.03 | D25: =+SUM(C$23:$C25) -> 0.85 | E25: =+E23+E24 -> 3 | F25: =+C25*E25 -> 0.09 | G25: 0 | H25: (*) Enemy killed
B26: Total | C26: =+SUM(C23:C25) -> 0.85 | F26: =+SUM(F23:F25) -> 1.05
A29: Table 4 | B29: Prize # | C29: Probability | D29: Cumulative prob. | E29: Award | F29: RTP | G29: Prob. Boss round
A30: Awards granted: | B30: 3 | C30: 0.35 | D30: =+SUM(C30:$C$30) -> 0.35 | E30: =+E7 -> 3 | F30: =+C30*E30 -> 1.05 | G30: 0 | H30: (*) Enemy killed
A31: Prize #1 | B31: Total | C31: =+SUM(C30:C30) -> 0.35 | F31: =+SUM(F30:F30) -> 1.05
A32: Prize #2
A34: Table 5 | B34: Prize # | C34: Probability | D34: Cumulative prob. | E34: Award | F34: RTP | G34: Prob. Boss round
A35: Awards granted: | B35: 1 | C35: 0.3 | D35: =+SUM(C35:$C$35) -> 0.3 | E35: =+E5 -> 0 | F35: =+C35*E35 -> 0
A36: Prize #3 | B36: 2 | C36: 0.475 | D36: =+SUM(C$35:$C36) -> 0.775 | E36: =+E6 -> 2 | F36: =+C36*E36 -> 0.95
B37: 1 and 2 | C37: 0.05 | D37: =+SUM(C$35:$C37) -> 0.825 | E37: =+E35+E36 -> 2 | F37: =+C37*E37 -> 0.1 | G37: 0 | H37: (*) Enemy killed
B38: Total | C38: =+SUM(C35:C37) -> 0.825 | F38: =+SUM(F35:F37) -> 1.05
A41: Table 6 | B41: Prize # | C41: Probability | D41: Cumulative prob. | E41: Award | F41: RTP
A42: Awards granted: | B42: 1 | C42: 0.7 | D42: =+SUM(C42:$C$42) -> 0.7 | E42: =+E5 -> 0 | F42: =+E42*C42 -> 0 | G42: 0 | H42: (*) Enemy killed
A43: Prize #2 | B43: Total | C43: =+SUM(C42:C42) -> 0.7 | F43: =+SUM(F42:F42) -> 0
A44: Prize #3
A46: Table 7 | B46: Prize # | C46: Probability | D46: Cumulative prob. | E46: Award | F46: RTP
A47: Awards granted: | B47: 2 | C47: 0.525 | D47: =+SUM(C$47:$C47) -> 0.525 | E47: =+E6 -> 2 | F47: =+E47*C47 -> 1.05 | G47: 0 | H47: (*) Enemy killed
A48: Prize #1 | B48: Total | C48: =+SUM(C47:C47) -> 0.525 | F48: =+SUM(F47:F47) -> 1.05
A49: Prize #3

Sheet Special weapon 2 (Mummy B)
A1: SPECIAL WEAPON 2 -Medium Mummy B (golden wrist bands and necklace)
A2: For each shot with a special weapon, draw the damage caused using the table according to prizes already granted by enemy that is being shot.
A4: Table 1 | B4: Prize # | C4: Probability | D4: Cumulative prob. | E4: Award | F4: RTP | G4: Prob. Boss round
A5: (Initial state) | B5: 1 | C5: 0.15 | D5: =+SUM($C$5:C5) -> 0.15 | E5: =+Summary!H27 -> 2 | F5: =+C5*E5 -> 0.3
B6: 2 | C6: 0.15 | D6: =+SUM($C$5:C6) -> 0.3 | E6: =+Summary!H28 -> 2 | F6: =+C6*E6 -> 0.3
B7: 3 | C7: 0.0225 | D7: =+SUM($C$5:C7) -> 0.3225 | E7: =+Summary!H29 -> 4 | F7: =+C7*E7 -> 0.09
B8: 1 and 2 | C8: 0.05 | D8: =+SUM($C$5:C8) -> 0.3725 | E8: =+E5+E6 -> 4 | F8: =+C8*E8 -> 0.2
B9: 1 and 3 | C9: 0.01 | D9: =+SUM($C$5:C9) -> 0.3825 | E9: =+E5+E7 -> 6 | F9: =+C9*E9 -> 0.06
B10: 2 and 3 | C10: 0.01 | D10: =+SUM($C$5:C10) -> 0.3925 | E10: =+E6+E7 -> 6 | F10: =+C10*E10 -> 0.06
B11: 1, 2 and 3 (*) | C11: 0.005 | D11: =+SUM($C$5:C11) -> 0.3975 | E11: =+E5+E6+E7 -> 8 | F11: =+C11*E11 -> 0.04 | G11: 0 | H11: (*) Enemy killed
B12: Total (*) | C12: =+SUM(C5:C11) -> 0.3975 | F12: =+SUM(F5:F11) -> 1.05
B13: (*) Total probability is hit rate
A15: Table 2 | B15: Prize # | C15: Probability | D15: Cumulative prob. | E15: Award | F15: RTP | G15: Prob. Boss round
A16: Awards granted: | B16: 2 | C16: 0.4 | D16: =+SUM(C16:$C$16) -> 0.4 | E16: =+E6 -> 2 | F16: =+C16*E16 -> 0.8
A17: Prize #1 | B17: 3 | C17: 0.0325 | D17: =+SUM(C$16:$C17) -> 0.4325 | E17: =+E7 -> 4 | F17: =+C17*E17 -> 0.13
B18: 2 and 3 | C18: 0.02 | D18: =+SUM(C$16:$C18) -> 0.4525 | E18: =+E16+E17 -> 6 | F18: =+C18*E18 -> 0.12 | G18: 0 | H18: (*) Enemy killed
B19: Total | C19: =+SUM(C16:C18) -> 0.4525 | F19: =+SUM(F16:F18) -> 1.05
A22: Table 3 | B22: Prize # | C22: Probability | D22: Cumulative prob. | E22: Award | F22: RTP | G22: Prob. Boss round
A23: Awards granted: | B23: 1 | C23: 0.4 | D23: =+SUM(C23:$C$23) -> 0.4 | E23: =+E5 -> 2 | F23: =+C23*E23 -> 0.8
A24: Prize #2 | B24: 3 | C24: 0.0325 | D24: =+SUM(C$23:$C24) -> 0.4325 | E24: =+E7 -> 4 | F24: =+C24*E24 -> 0.13
B25: 1 and 3 | C25: 0.02 | D25: =+SUM(C$23:$C25) -> 0.4525 | E25: =+E23+E24 -> 6 | F25: =+C25*E25 -> 0.12 | G25: 0 | H25: (*) Enemy killed
B26: Total | C26: =+SUM(C23:C25) -> 0.4525 | F26: =+SUM(F23:F25) -> 1.05
A29: Table 4 | B29: Prize # | C29: Probability | D29: Cumulative prob. | E29: Award | F29: RTP | G29: Prob. Boss round
A30: Awards granted: | B30: 3 | C30: 0.2625 | D30: =+SUM(C30:$C$30) -> 0.2625 | E30: =+E7 -> 4 | F30: =+C30*E30 -> 1.05 | G30: 0 | H30: (*) Enemy killed
A31: Prize #1 | B31: Total | C31: =+SUM(C30:C30) -> 0.2625 | F31: =+SUM(F30:F30) -> 1.05
A32: Prize #2
A34: Table 5 | B34: Prize # | C34: Probability | D34: Cumulative prob. | E34: Award | F34: RTP | G34: Prob. Boss round
A35: Awards granted: | B35: 1 | C35: 0.24 | D35: =+SUM(C35:$C$35) -> 0.24 | E35: =+E5 -> 2 | F35: =+C35*E35 -> 0.48
A36: Prize #3 | B36: 2 | C36: 0.24 | D36: =+SUM(C$35:$C36) -> 0.48 | E36: =+E6 -> 2 | F36: =+C36*E36 -> 0.48
B37: 1 and 2 | C37: 0.0225 | D37: =+SUM(C$35:$C37) -> 0.5025 | E37: =+E35+E36 -> 4 | F37: =+C37*E37 -> 0.09 | G37: 0 | H37: (*) Enemy killed
B38: Total | C38: =+SUM(C35:C37) -> 0.5025 | F38: =+SUM(F35:F37) -> 1.05
A41: Table 6 | B41: Prize # | C41: Probability | D41: Cumulative prob. | E41: Award | F41: RTP
A42: Awards granted: | B42: 1 | C42: 0.525 | D42: =+SUM(C42:$C$42) -> 0.525 | E42: =+E5 -> 2 | F42: =+E42*C42 -> 1.05 | G42: 0 | H42: (*) Enemy killed
A43: Prize #2 | B43: Total | C43: =+SUM(C42:C42) -> 0.525 | F43: =+SUM(F42:F42) -> 1.05
A44: Prize #3
A46: Table 7 | B46: Prize # | C46: Probability | D46: Cumulative prob. | E46: Award | F46: RTP
A47: Awards granted: | B47: 2 | C47: 0.525 | D47: =+SUM(C$47:$C47) -> 0.525 | E47: =+E6 -> 2 | F47: =+E47*C47 -> 1.05 | G47: 0 | H47: (*) Enemy killed
A48: Prize #1 | B48: Total | C48: =+SUM(C47:C47) -> 0.525 | F48: =+SUM(F47:F47) -> 1.05
A49: Prize #3

Sheet Special weapon 2 (Mummy C)
A1: SPECIAL WEAPON 2 - Medium Mummy C (golden boots and wrist bands)
A2: For each shot with a special weapon, draw the damage caused using the table according to prizes already granted by enemy that is being shot.
A4: Table 1 | B4: Prize # | C4: Probability | D4: Cumulative prob. | E4: Award | F4: RTP | G4: Prob. Boss round
A5: (Initial state) | B5: 1 | C5: 0.1 | D5: =+SUM($C$5:C5) -> 0.1 | E5: =Summary!K27 -> 3 | F5: =+C5*E5 -> 0.3
B6: 2 | C6: 0.1 | D6: =+SUM($C$5:C6) -> 0.2 | E6: =Summary!K28 -> 3 | F6: =+C6*E6 -> 0.3
B7: 3 | C7: 0.015 | D7: =+SUM($C$5:C7) -> 0.215 | E7: =Summary!K29 -> 6 | F7: =+C7*E7 -> 0.09
B8: 1 and 2 | C8: 0.02 | D8: =+SUM($C$5:C8) -> 0.235 | E8: =+E5+E6 -> 6 | F8: =+C8*E8 -> 0.12
B9: 1 and 3 | C9: 0.01 | D9: =+SUM($C$5:C9) -> 0.245 | E9: =+E5+E7 -> 9 | F9: =+C9*E9 -> 0.09
B10: 2 and 3 | C10: 0.01 | D10: =+SUM($C$5:C10) -> 0.255 | E10: =+E6+E7 -> 9 | F10: =+C10*E10 -> 0.09
B11: 1, 2 and 3 (*) | C11: 0.005 | D11: =+SUM($C$5:C11) -> 0.26 | E11: =+E5+E6+E7 -> 12 | F11: =+C11*E11 -> 0.06 | G11: 0 | H11: (*) Enemy killed
B12: Total (*) | C12: =+SUM(C5:C11) -> 0.26 | F12: =+SUM(F5:F11) -> 1.05
B13: (*) Total probability is hit rate
A15: Table 2 | B15: Prize # | C15: Probability | D15: Cumulative prob. | E15: Award | F15: RTP | G15: Prob. Boss round
A16: Awards granted: | B16: 2 | C16: 0.25 | D16: =+SUM(C16:$C$16) -> 0.25 | E16: =+E6 -> 3 | F16: =+C16*E16 -> 0.75
A17: Prize #1 | B17: 3 | C17: 0.02 | D17: =+SUM(C$16:$C17) -> 0.27 | E17: =+E7 -> 6 | F17: =+C17*E17 -> 0.12
B18: 2 and 3 | C18: 0.02 | D18: =+SUM(C$16:$C18) -> 0.29 | E18: =+E16+E17 -> 9 | F18: =+C18*E18 -> 0.18 | G18: 0 | H18: (*) Enemy killed
B19: Total | C19: =+SUM(C16:C18) -> 0.29 | F19: =+SUM(F16:F18) -> 1.05
A22: Table 3 | B22: Prize # | C22: Probability | D22: Cumulative prob. | E22: Award | F22: RTP | G22: Prob. Boss round
A23: Awards granted: | B23: 1 | C23: 0.25 | D23: =+SUM(C23:$C$23) -> 0.25 | E23: =+E5 -> 3 | F23: =+C23*E23 -> 0.75
A24: Prize #2 | B24: 3 | C24: 0.02 | D24: =+SUM(C$23:$C24) -> 0.27 | E24: =+E7 -> 6 | F24: =+C24*E24 -> 0.12
B25: 1 and 3 | C25: 0.02 | D25: =+SUM(C$23:$C25) -> 0.29 | E25: =+E23+E24 -> 9 | F25: =+C25*E25 -> 0.18 | G25: 0 | H25: (*) Enemy killed
B26: Total | C26: =+SUM(C23:C25) -> 0.29 | F26: =+SUM(F23:F25) -> 1.05
A29: Table 4 | B29: Prize # | C29: Probability | D29: Cumulative prob. | E29: Award | F29: RTP | G29: Prob. Boss round
A30: Awards granted: | B30: 3 | C30: 0.175 | D30: =+SUM(C30:$C$30) -> 0.175 | E30: =+E7 -> 6 | F30: =+C30*E30 -> 1.05 | G30: 0 | H30: (*) Enemy killed
A31: Prize #1 | B31: Total | C31: =+SUM(C30:C30) -> 0.175 | F31: =+SUM(F30:F30) -> 1.05
A32: Prize #2
A34: Table 5 | B34: Prize # | C34: Probability | D34: Cumulative prob. | E34: Award | F34: RTP | G34: Prob. Boss round
A35: Awards granted: | B35: 1 | C35: 0.15 | D35: =+SUM(C35:$C$35) -> 0.15 | E35: =+E5 -> 3 | F35: =+C35*E35 -> 0.45
A36: Prize #3 | B36: 2 | C36: 0.15 | D36: =+SUM(C$35:$C36) -> 0.3 | E36: =+E6 -> 3 | F36: =+C36*E36 -> 0.45
B37: 1 and 2 | C37: 0.025 | D37: =+SUM(C$35:$C37) -> 0.325 | E37: =+E35+E36 -> 6 | F37: =+C37*E37 -> 0.15 | G37: 0 | H37: (*) Enemy killed
B38: Total | C38: =+SUM(C35:C37) -> 0.325 | F38: =+SUM(F35:F37) -> 1.05
A41: Table 6 | B41: Prize # | C41: Probability | D41: Cumulative prob. | E41: Award | F41: RTP
A42: Awards granted: | B42: 1 | C42: 0.35 | D42: =+SUM(C42:$C$42) -> 0.35 | E42: =+E5 -> 3 | F42: =+E42*C42 -> 1.05 | G42: 0 | H42: (*) Enemy killed
A43: Prize #2 | B43: Total | C43: =+SUM(C42:C42) -> 0.35 | F43: =+SUM(F42:F42) -> 1.05
A44: Prize #3
A46: Table 7 | B46: Prize # | C46: Probability | D46: Cumulative prob. | E46: Award | F46: RTP
A47: Awards granted: | B47: 2 | C47: 0.35 | D47: =+SUM(C$47:$C47) -> 0.35 | E47: =+E6 -> 3 | F47: =+E47*C47 -> 1.05 | G47: 0 | H47: (*) Enemy killed
A48: Prize #1 | B48: Total | C48: =+SUM(C47:C47) -> 0.35 | F48: =+SUM(F47:F47) -> 1.05
A49: Prize #3

Sheet Special weapon 2 (Std Mummy)
A1: SPECIAL WEAPON 2 - Standard Mummy
A2: For each shot with a special weapon, draw the damage caused using the table according to prizes already granted by enemy that is being shot.
A4: Table 1 | B4: Prize # | C4: Probability | D4: Cumulative prob. | E4: Award | F4: RTP | G4: Prob. Boss round
A5: (Initial state) | B5: 1 | C5: 0.25 | D5: =+SUM($C$5:C5) -> 0.25 | E5: =+Summary!B27 -> 2 | F5: =+C5*E5 -> 0.5
B6: 2 | C6: 0.1 | D6: =+SUM($C$5:C6) -> 0.35 | E6: =+Summary!B28 -> 3 | F6: =+C6*E6 -> 0.3
B7: 1 and 2 | C7: 0.05 | D7: =+SUM($C$5:C7) -> 0.4 | E7: =+E5+E6 -> 5 | F7: =+C7*E7 -> 0.25 | G7: 0 | H7: (*) Enemy killed
B8: Total (*) | C8: =+SUM(C5:C7) -> 0.4 | F8: =+SUM(F5:F7) -> 1.05
B9: (*) Total probability is hit rate
A12: Table 6 | B12: Prize # | C12: Probability | D12: Cumulative prob. | E12: Award | F12: RTP | G12: Prob. Boss round
A13: Awards granted: | B13: 1 | C13: 0.525 | D13: =+SUM(C13:$C$13) -> 0.525 | E13: =+E5 -> 2 | F13: =+E13*C13 -> 1.05 | G13: 0 | H13: (*) Enemy killed
A14: Prize #2 | B14: Total | C14: =+SUM(C13:C13) -> 0.525 | F14: =+SUM(F13:F13) -> 1.05
A17: Table 7 | B17: Prize # | C17: Probability | D17: Cumulative prob. | E17: Award | F17: RTP | G17: Prob. Boss round
A18: Awards granted: | B18: 2 | C18: 0.35 | D18: =+SUM(C$18:$C18) -> 0.35 | E18: =+E6 -> 3 | F18: =+E18*C18 -> 1.05 | G18: 0 | H18: (*) Enemy killed
A19: Prize #1 | B19: Total | C19: =+SUM(C18:C18) -> 0.35 | F19: =+SUM(F18:F18) -> 1.05

Sheet Special weapon 2 (Scarabs)
A1: SPECIAL WEAPON 2 - Scarabs
A2: For each shot with a special weapon, draw the damage caused using the table according to prizes already granted by enemy that is being shot.
A4: Scarab black | B4: Prize # | C4: Probability | D4: Cumulative prob. | E4: Award | F4: RTP | G4: Prob. Boss round
B5: 1 | C5: 0.525 | D5: =+SUM(C5:$C$5) -> 0.525 | E5: =+Summary!B21 -> 2 | F5: =+E5*C5 -> 1.05 | G5: 0 | H5: (*) Enemy killed
B6: Total | C6: =+SUM(C5:C5) -> 0.525 | F6: =+SUM(F5:F5) -> 1.05
A9: Scarab gold | B9: Prize # | C9: Probability | D9: Cumulative prob. | E9: Award | F9: RTP | G9: Prob. Boss round
B10: 1 | C10: 0.35 | D10: =1/6 -> 0.16666667 | E10: =+Summary!E21 -> 3 | F10: =+E10*C10 -> 1.05 | G10: 0 | H10: (*) Enemy killed
B11: Total | C11: =+SUM(C10:C10) -> 0.35 | F11: =+SUM(F10:F10) -> 1.05
A14: Scarab gem covered | B14: Prize # | C14: Probability | D14: Cumulative prob. | E14: Award | F14: RTP | G14: Prob. Boss round
B15: 1 | C15: 0.2625 | D15: =+SUM(C$15:$C15) -> 0.2625 | E15: =+Summary!H21 -> 4 | F15: =+E15*C15 -> 1.05 | G15: 0 | H15: (*) Enemy killed
B16: Total | C16: =+SUM(C15:C15) -> 0.2625 | F16: =+SUM(F15:F15) -> 1.05

Sheet Special weapon 2 (Pharaoh A&B)
A1: SPECIAL WEAPON 2 - Powerful Pharaoh Mummy A & B
A2: For each shot with a special weapon, draw the damage caused using the table according to prizes already granted by enemy that is being shot.
A4: Table 1 | B4: Prize # | C4: Probability | D4: Cumulative prob. | E4: Award | F4: RTP | G4: Prob. Boss round
A5: (Initial state) | B5: 1 | C5: 0.12 | D5: =+SUM($C$5:C5) -> 0.12 | E5: =+Summary!B36 -> 2 | F5: =+C5*E5 -> 0.24
B6: 2 | C6: 0.01 | D6: =+SUM($C$5:C6) -> 0.13 | E6: =+Summary!B37 -> 5 | F6: =+C6*E6 -> 0.05
B7: 3 | C7: 0.01 | D7: =+SUM($C$5:C7) -> 0.14 | E7: =+Summary!B38 -> 8 | F7: =+C7*E7 -> 0.08
B8: 1 and 2 | C8: 0.01 | D8: =+SUM($C$5:C8) -> 0.15 | E8: =+E5+E6 -> 7 | F8: =+C8*E8 -> 0.07
B9: 1 and 3 | C9: 0.02 | D9: =+SUM($C$5:C9) -> 0.17 | E9: =+E5+E7 -> 10 | F9: =+C9*E9 -> 0.2
B10: 2 and 3 | C10: 0.02 | D10: =+SUM($C$5:C10) -> 0.19 | E10: =+E6+E7 -> 13 | F10: =+C10*E10 -> 0.26
B11: 1, 2 and 3 (*) | C11: 0.01 | D11: =+SUM($C$5:C11) -> 0.2 | E11: =+E5+E6+E7 -> 15 | F11: =+C11*E11 -> 0.15 | G11: 0 | H11: (*) Enemy killed
B12: Total (*) | C12: =+SUM(C5:C11) -> 0.2 | F12: =+SUM(F5:F11) -> 1.05
B13: (*) Total probability is hit rate
A15: Table 2 | B15: Prize # | C15: Probability | D15: Cumulative prob. | E15: Award | F15: RTP | G15: Prob. Boss round
A16: Awards granted: | B16: 2 | C16: 0.09 | D16: =+SUM(C16:$C$16) -> 0.09 | E16: =+E6 -> 5 | F16: =+C16*E16 -> 0.45
A17: Prize #1 | B17: 3 | C17: 0.01 | D17: =+SUM(C$16:$C17) -> 0.1 | E17: =+E7 -> 8 | F17: =+C17*E17 -> 0.08
B18: 2 and 3 | C18: 0.04 | D18: =+SUM(C$16:$C18) -> 0.14 | E18: =+E16+E17 -> 13 | F18: =+C18*E18 -> 0.52 | G18: 0 | H18: (*) Enemy killed
B19: Total | C19: =+SUM(C16:C18) -> 0.14 | F19: =+SUM(F16:F18) -> 1.05
A22: Table 3 | B22: Prize # | C22: Probability | D22: Cumulative prob. | E22: Award | F22: RTP | G22: Prob. Boss round
A23: Awards granted: | B23: 1 | C23: 0.12 | D23: =+SUM(C23:$C$23) -> 0.12 | E23: =+E5 -> 2 | F23: =+C23*E23 -> 0.24
A24: Prize #2 | B24: 3 | C24: 0.04 | D24: =+SUM(C$23:$C24) -> 0.16 | E24: =+E7 -> 8 | F24: =+C24*E24 -> 0.32
B25: 1 and 3 | C25: 0.049 | D25: =+SUM(C$23:$C25) -> 0.209 | E25: =+E23+E24 -> 10 | F25: =+C25*E25 -> 0.49 | G25: 0 | H25: (*) Enemy killed
B26: Total | C26: =+SUM(C23:C25) -> 0.209 | F26: =+SUM(F23:F25) -> 1.05
A29: Table 4 | B29: Prize # | C29: Probability | D29: Cumulative prob. | E29: Award | F29: RTP | G29: Prob. Boss round
A30: Awards granted: | B30: 3 | C30: 0.13125 | D30: =+SUM(C30:$C$30) -> 0.13125 | E30: =+E7 -> 8 | F30: =+C30*E30 -> 1.05 | G30: 0 | H30: (*) Enemy killed
A31: Prize #1 | B31: Total | C31: =+SUM(C30:C30) -> 0.13125 | F31: =+SUM(F30:F30) -> 1.05
A32: Prize #2
A34: Table 5 | B34: Prize # | C34: Probability | D34: Cumulative prob. | E34: Award | F34: RTP | G34: Prob. Boss round
A35: Awards granted: | B35: 1 | C35: 0.12 | D35: =+SUM(C35:$C$35) -> 0.12 | E35: =+E5 -> 2 | F35: =+C35*E35 -> 0.24
A36: Prize #3 | B36: 2 | C36: 0.078 | D36: =+SUM(C$35:$C36) -> 0.198 | E36: =+E6 -> 5 | F36: =+C36*E36 -> 0.39
B37: 1 and 2 | C37: 0.06 | D37: =+SUM(C$35:$C37) -> 0.258 | E37: =+E35+E36 -> 7 | F37: =+C37*E37 -> 0.42 | G37: 0 | H37: (*) Enemy killed
B38: Total | C38: =+SUM(C35:C37) -> 0.258 | F38: =+SUM(F35:F37) -> 1.05
A41: Table 6 | B41: Prize # | C41: Probability | D41: Cumulative prob. | E41: Award | F41: RTP | G41: Prob. Boss round
A42: Awards granted: | B42: 1 | C42: 0.525 | D42: =+SUM(C42:$C$42) -> 0.525 | E42: =+E5 -> 2 | F42: =+E42*C42 -> 1.05 | G42: 0 | H42: (*) Enemy killed
A43: Prize #2 | B43: Total | C43: =+SUM(C42:C42) -> 0.525 | F43: =+SUM(F42:F42) -> 1.05
A44: Prize #3
A46: Table 7 | B46: Prize # | C46: Probability | D46: Cumulative prob. | E46: Award | F46: RTP | G46: Prob. Boss round
A47: Awards granted: | B47: 2 | C47: 0.21 | D47: =+SUM(C$47:$C47) -> 0.21 | E47: =+E6 -> 5 | F47: =+E47*C47 -> 1.05 | G47: 0 | H47: (*) Enemy killed
A48: Prize #1 | B48: Total | C48: =+SUM(C47:C47) -> 0.21 | F48: =+SUM(F47:F47) -> 1.05
A49: Prize #3

Sheet Special weapon 3 (Mummy A)
